Workbook

Sheet Master Roles
A1: APPSCODE | B1: ROLE_ID | C1: STATUS | D1: DESC | E1: SQL
A2: CK | B2: ADMIN | C2: A | D2: ACCOUNT ADMIN | E2: =CONCATENATE("INSERT INTO T_CORE_ROLE(ROLE_APPSCODE, ROLE_ID, ROLE_STATUS, ROLE_DESC, ROLE_DT_CREATE, ROLE_UID_CREATE, ROLE_DT_LUPD, ROLE_UID_LUPD) VALUES ('",A2,"','",B2,"','",C2,"','",D2,"',NOW(),'SYS',NOW(),'SYS');") -> INSERT INTO T_CORE_ROLE(ROLE_APPSCODE, ROLE_ID, ROLE_STATUS, ROLE_DESC, ROLE_DT_CREATE, ROLE_UID_CREATE, ROLE_DT_LUPD, ROLE_UID_LUPD) VALUES ('CK','ADMIN','A','ACCOUNT ADMIN',NOW(),'SYS',NOW(),'SYS');
A3: CK | B3: OFFICER | C3: A | D3: OFFICER | E3: =CONCATENATE("INSERT INTO T_CORE_ROLE(ROLE_APPSCODE, ROLE_ID, ROLE_STATUS, ROLE_DESC, ROLE_DT_CREATE, ROLE_UID_CREATE, ROLE_DT_LUPD, ROLE_UID_LUPD) VALUES ('",A3,"','",B3,"','",C3,"','",D3,"',NOW(),'SYS',NOW(),'SYS');") -> INSERT INTO T_CORE_ROLE(ROLE_APPSCODE, ROLE_ID, ROLE_STATUS, ROLE_DESC, ROLE_DT_CREATE, ROLE_UID_CREATE, ROLE_DT_LUPD, ROLE_UID_LUPD) VALUES ('CK','OFFICER','A','OFFICER',NOW(),'SYS',NOW(),'SYS');
A4: CK | B4: OPERATIONS | C4: A | D4: OPERATIONS | E4: =CONCATENATE("INSERT INTO T_CORE_ROLE(ROLE_APPSCODE, ROLE_ID, ROLE_STATUS, ROLE_DESC, ROLE_DT_CREATE, ROLE_UID_CREATE, ROLE_DT_LUPD, ROLE_UID_LUPD) VALUES ('",A4,"','",B4,"','",C4,"','",D4,"',NOW(),'SYS',NOW(),'SYS');") -> INSERT INTO T_CORE_ROLE(ROLE_APPSCODE, ROLE_ID, ROLE_STATUS, ROLE_DESC, ROLE_DT_CREATE, ROLE_UID_CREATE, ROLE_DT_LUPD, ROLE_UID_LUPD) VALUES ('CK','OPERATIONS','A','OPERATIONS',NOW(),'SYS',NOW(),'SYS');
A5: CK | B5: FINANCE | C5: A | D5: FINANCE | E5: =CONCATENATE("INSERT INTO T_CORE_ROLE(ROLE_APPSCODE, ROLE_ID, ROLE_STATUS, ROLE_DESC, ROLE_DT_CREATE, ROLE_UID_CREATE, ROLE_DT_LUPD, ROLE_UID_LUPD) VALUES ('",A5,"','",B5,"','",C5,"','",D5,"',NOW(),'SYS',NOW(),'SYS');") -> INSERT INTO T_CORE_ROLE(ROLE_APPSCODE, ROLE_ID, ROLE_STATUS, ROLE_DESC, ROLE_DT_CREATE, ROLE_UID_CREATE, ROLE_DT_LUPD, ROLE_UID_LUPD) VALUES ('CK','FINANCE','A','FINANCE',NOW(),'SYS',NOW(),'SYS');
A6: CK | B6: SYS_SUPER_ADMIN | C6: A | D6: SYSTEM SUPER ADMIN | E6: =CONCATENATE("INSERT INTO T_CORE_ROLE(ROLE_APPSCODE, ROLE_ID, ROLE_STATUS, ROLE_DESC, ROLE_DT_CREATE, ROLE_UID_CREATE, ROLE_DT_LUPD, ROLE_UID_LUPD) VALUES ('",A6,"','",B6,"','",C6,"','",D6,"',NOW(),'SYS',NOW(),'SYS');") -> INSERT INTO T_CORE_ROLE(ROLE_APPSCODE, ROLE_ID, ROLE_STATUS, ROLE_DESC, ROLE_DT_CREATE, ROLE_UID_CREATE, ROLE_DT_LUPD, ROLE_UID_LUPD) VALUES ('CK','SYS_SUPER_ADMIN','A','SYSTEM SUPER ADMIN',NOW(),'SYS',NOW(),'SYS');
A8: CKT | B8: ADMIN | C8: A | D8: ACCOUNT ADMIN | E8: =CONCATENATE("INSERT INTO T_CORE_ROLE(ROLE_APPSCODE, ROLE_ID, ROLE_STATUS, ROLE_DESC, ROLE_DT_CREATE, ROLE_UID_CREATE, ROLE_DT_LUPD, ROLE_UID_LUPD) VALUES ('",A8,"','",B8,"','",C8,"','",D8,"',NOW(),'SYS',NOW(),'SYS');") -> INSERT INTO T_CORE_ROLE(ROLE_APPSCODE, ROLE_ID, ROLE_STATUS, ROLE_DESC, ROLE_DT_CREATE, ROLE_UID_CREATE, ROLE_DT_LUPD, ROLE_UID_LUPD) VALUES ('CKT','ADMIN','A','ACCOUNT ADMIN',NOW(),'SYS',NOW(),'SYS');
A9: CKT | B9: OFFICER | C9: A | D9: OFFICER | E9: =CONCATENATE("INSERT INTO T_CORE_ROLE(ROLE_APPSCODE, ROLE_ID, ROLE_STATUS, ROLE_DESC, ROLE_DT_CREATE, ROLE_UID_CREATE, ROLE_DT_LUPD, ROLE_UID_LUPD) VALUES ('",A9,"','",B9,"','",C9,"','",D9,"',NOW(),'SYS',NOW(),'SYS');") -> INSERT INTO T_CORE_ROLE(ROLE_APPSCODE, ROLE_ID, ROLE_STATUS, ROLE_DESC, ROLE_DT_CREATE, ROLE_UID_CREATE, ROLE_DT_LUPD, ROLE_UID_LUPD) VALUES ('CKT','OFFICER','A','OFFICER',NOW(),'SYS',NOW(),'SYS');
A10: CKT | B10: FF_FINANCE | C10: A | D10: FINANCE | E10: =CONCATENATE("INSERT INTO T_CORE_ROLE(ROLE_APPSCODE, ROLE_ID, ROLE_STATUS, ROLE_DESC, ROLE_DT_CREATE, ROLE_UID_CREATE, ROLE_DT_LUPD, ROLE_UID_LUPD) VALUES ('",A10,"','",B10,"','",C10,"','",D10,"',NOW(),'SYS',NOW(),'SYS');") -> INSERT INTO T_CORE_ROLE(ROLE_APPSCODE, ROLE_ID, ROLE_STATUS, ROLE_DESC, ROLE_DT_CREATE, ROLE_UID_CREATE, ROLE_DT_LUPD, ROLE_UID_LUPD) VALUES ('CKT','FF_FINANCE','A','FINANCE',NOW(),'SYS',NOW(),'SYS');
A11: CKT | B11: OP_ADMIN | C11: A | D11: OPERATIONS ADMIN | E11: =CONCATENATE("INSERT INTO T_CORE_ROLE(ROLE_APPSCODE, ROLE_ID, ROLE_STATUS, ROLE_DESC, ROLE_DT_CREATE, ROLE_UID_CREATE, ROLE_DT_LUPD, ROLE_UID_LUPD) VALUES ('",A11,"','",B11,"','",C11,"','",D11,"',NOW(),'SYS',NOW(),'SYS');") -> INSERT INTO T_CORE_ROLE(ROLE_APPSCODE, ROLE_ID, ROLE_STATUS, ROLE_DESC, ROLE_DT_CREATE, ROLE_UID_CREATE, ROLE_DT_LUPD, ROLE_UID_LUPD) VALUES ('CKT','OP_ADMIN','A','OPERATIONS ADMIN',NOW(),'SYS',NOW(),'SYS');
A12: CKT | B12: SP_OP_ADMIN | C12: A | D12: OPERATIONS ADMIN | E12: =CONCATENATE("INSERT INTO T_CORE_ROLE(ROLE_APPSCODE, ROLE_ID, ROLE_STATUS, ROLE_DESC, ROLE_DT_CREATE, ROLE_UID_CREATE, ROLE_DT_LUPD, ROLE_UID_LUPD) VALUES ('",A12,"','",B12,"','",C12,"','",D12,"',NOW(),'SYS',NOW(),'SYS');") -> INSERT INTO T_CORE_ROLE(ROLE_APPSCODE, ROLE_ID, ROLE_STATUS, ROLE_DESC, ROLE_DT_CREATE, ROLE_UID_CREATE, ROLE_DT_LUPD, ROLE_UID_LUPD) VALUES ('CKT','SP_OP_ADMIN','A','OPERATIONS ADMIN',NOW(),'SYS',NOW(),'SYS');
A13: CKT | B13: SP_L1 | C13: A | D13: LEVEL 1 SUPPORT | E13: =CONCATENATE("INSERT INTO T_CORE_ROLE(ROLE_APPSCODE, ROLE_ID, ROLE_STATUS, ROLE_DESC, ROLE_DT_CREATE, ROLE_UID_CREATE, ROLE_DT_LUPD, ROLE_UID_LUPD) VALUES ('",A13,"','",B13,"','",C13,"','",D13,"',NOW(),'SYS',NOW(),'SYS');") -> INSERT INTO T_CORE_ROLE(ROLE_APPSCODE, ROLE_ID, ROLE_STATUS, ROLE_DESC, ROLE_DT_CREATE, ROLE_UID_CREATE, ROLE_DT_LUPD, ROLE_UID_LUPD) VALUES ('CKT','SP_L1','A','LEVEL 1 SUPPORT',NOW(),'SYS',NOW(),'SYS');
A14: CKT | B14: SP_COM | C14: A | D14: COMMERCIAL | E14: =CONCATENATE("INSERT INTO T_CORE_ROLE(ROLE_APPSCODE, ROLE_ID, ROLE_STATUS, ROLE_DESC, ROLE_DT_CREATE, ROLE_UID_CREATE, ROLE_DT_LUPD, ROLE_UID_LUPD) VALUES ('",A14,"','",B14,"','",C14,"','",D14,"',NOW(),'SYS',NOW(),'SYS');") -> INSERT INTO T_CORE_ROLE(ROLE_APPSCODE, ROLE_ID, ROLE_STATUS, ROLE_DESC, ROLE_DT_CREATE, ROLE_UID_CREATE, ROLE_DT_LUPD, ROLE_UID_LUPD) VALUES ('CKT','SP_COM','A','COMMERCIAL',NOW(),'SYS',NOW(),'SYS');
... A29: CKDO | B29: SP_FIN_ADMIN | C29: A | D29: FINANCE ADMIN | E29: =CONCATENATE("INSERT INTO T_CORE_ROLE(ROLE_APPSCODE, ROLE_ID, ROLE_STATUS, ROLE_DESC, ROLE_DT_CREATE, ROLE_UID_CREATE, ROLE_DT_LUPD, ROLE_UID_LUPD) VALUES ('",A29,"','",B29,"','",C29,"','",D29,"',NOW(),'SYS',NOW(),'SYS');") -> INSERT INTO T_CORE_ROLE(ROLE_APPSCODE, ROLE_ID, ROLE_STATUS, ROLE_DESC, ROLE_DT_CREATE, ROLE_UID_CREATE, ROLE_DT_LUPD, ROLE_UID_LUPD) VALUES ('CKDO','SP_FIN_ADMIN','A','FINANCE ADMIN',NOW(),'SYS',NOW(),'SYS');
A32: NOTE:
B33: SP_FIN_ADMIN WILL REPLACE FINANCE_VERIFIER AND FINANCE_ADMIN
B34: SP_FIN_HD WILL REPLACE FINANCE_APPROVER

Sheet User Roles
A1: User ID | B1: USR_ACCNID | C1: ACCOUNT TYPE | D1: APPSCODE | E1: ROLE ID | F1: IS ADMIN | G1: TEMP ROLE | H1: STATUS
A2: ALKNAR_U001 | B2: ALKNAR | C2: ACC_TYPE_CO | D2: CK | E2: OFFICER | F2: N | G2: N | H2: A | I2: =CONCATENATE("INSERT INTO T_CORE_USR_ROLE(UROL_UID, UROL_APPSCODE, UROL_ROLEID, UROL_ADMIN_OPT, UROL_STATUS, UROL_DT_CREATE, UROL_UID_CREATE, UROL_DT_LUPD, UROL_UID_LUPD, UROL_TEMP_ROLE) VALUES('",A2,"','",D2,"','",E2,"','",F2,"','",H2,"',NOW(),'SYS', NOW(),'SYS','",G2,"');") -> INSERT INTO T_CORE_USR_ROLE(UROL_UID, UROL_APPSCODE, UROL_ROLEID, UROL_ADMIN_OPT, UROL_STATUS, UROL_DT_CREATE, UROL_UID_CREATE, UROL_DT_LUPD, UROL_UID_LUPD, UROL_TEMP_ROLE) VALUES('ALKNAR_U001','CK','OFFICER','N','A',NOW(),'SYS', NOW(),'SYS','N');
A3: ALKNAR_U002 | B3: ALKNAR | C3: ACC_TYPE_CO | D3: CK | E3: OFFICER | F3: N | G3: N | H3: A | I3: =CONCATENATE("INSERT INTO T_CORE_USR_ROLE(UROL_UID, UROL_APPSCODE, UROL_ROLEID, UROL_ADMIN_OPT, UROL_STATUS, UROL_DT_CREATE, UROL_UID_CREATE, UROL_DT_LUPD, UROL_UID_LUPD, UROL_TEMP_ROLE) VALUES('",A3,"','",D3,"','",E3,"','",F3,"','",H3,"',NOW(),'SYS', NOW(),'SYS','",G3,"');") -> INSERT INTO T_CORE_USR_ROLE(UROL_UID, UROL_APPSCODE, UROL_ROLEID, UROL_ADMIN_OPT, UROL_STATUS, UROL_DT_CREATE, UROL_UID_CREATE, UROL_DT_LUPD, UROL_UID_LUPD, UROL_TEMP_ROLE) VALUES('ALKNAR_U002','CK','OFFICER','N','A',NOW(),'SYS', NOW(),'SYS','N');
A4: ALKNAR_U003 | B4: ALKNAR | C4: ACC_TYPE_CO | D4: CK | E4: OFFICER | F4: N | G4: N | H4: A | I4: =CONCATENATE("INSERT INTO T_CORE_USR_ROLE(UROL_UID, UROL_APPSCODE, UROL_ROLEID, UROL_ADMIN_OPT, UROL_STATUS, UROL_DT_CREATE, UROL_UID_CREATE, UROL_DT_LUPD, UROL_UID_LUPD, UROL_TEMP_ROLE) VALUES('",A4,"','",D4,"','",E4,"','",F4,"','",H4,"',NOW(),'SYS', NOW(),'SYS','",G4,"');") -> INSERT INTO T_CORE_USR_ROLE(UROL_UID, UROL_APPSCODE, UROL_ROLEID, UROL_ADMIN_OPT, UROL_STATUS, UROL_DT_CREATE, UROL_UID_CREATE, UROL_DT_LUPD, UROL_UID_LUPD, UROL_TEMP_ROLE) VALUES('ALKNAR_U003','CK','OFFICER','N','A',NOW(),'SYS', NOW(),'SYS','N');
A5: ALMGA_U001 | B5: ALMGA | C5: ACC_TYPE_CO | D5: CK | E5: OFFICER | F5: N | G5: N | H5: A | I5: =CONCATENATE("INSERT INTO T_CORE_USR_ROLE(UROL_UID, UROL_APPSCODE, UROL_ROLEID, UROL_ADMIN_OPT, UROL_STATUS, UROL_DT_CREATE, UROL_UID_CREATE, UROL_DT_LUPD, UROL_UID_LUPD, UROL_TEMP_ROLE) VALUES('",A5,"','",D5,"','",E5,"','",F5,"','",H5,"',NOW(),'SYS', NOW(),'SYS','",G5,"');") -> INSERT INTO T_CORE_USR_ROLE(UROL_UID, UROL_APPSCODE, UROL_ROLEID, UROL_ADMIN_OPT, UROL_STATUS, UROL_DT_CREATE, UROL_UID_CREATE, UROL_DT_LUPD, UROL_UID_LUPD, UROL_TEMP_ROLE) VALUES('ALMGA_U001','CK','OFFICER','N','A',NOW(),'SYS', NOW(),'SYS','N');
A6: ALMGA_U002 | B6: ALMGA | C6: ACC_TYPE_CO | D6: CK | E6: OFFICER | F6: N | G6: N | H6: A | I6: =CONCATENATE("INSERT INTO T_CORE_USR_ROLE(UROL_UID, UROL_APPSCODE, UROL_ROLEID, UROL_ADMIN_OPT, UROL_STATUS, UROL_DT_CREATE, UROL_UID_CREATE, UROL_DT_LUPD, UROL_UID_LUPD, UROL_TEMP_ROLE) VALUES('",A6,"','",D6,"','",E6,"','",F6,"','",H6,"',NOW(),'SYS', NOW(),'SYS','",G6,"');") -> INSERT INTO T_CORE_USR_ROLE(UROL_UID, UROL_APPSCODE, UROL_ROLEID, UROL_ADMIN_OPT, UROL_STATUS, UROL_DT_CREATE, UROL_UID_CREATE, UROL_DT_LUPD, UROL_UID_LUPD, UROL_TEMP_ROLE) VALUES('ALMGA_U002','CK','OFFICER','N','A',NOW(),'SYS', NOW(),'SYS','N');
A7: ALMGA_U003 | B7: ALMGA | C7: ACC_TYPE_CO | D7: CK | E7: OFFICER | F7: N | G7: N | H7: A | I7: =CONCATENATE("INSERT INTO T_CORE_USR_ROLE(UROL_UID, UROL_APPSCODE, UROL_ROLEID, UROL_ADMIN_OPT, UROL_STATUS, UROL_DT_CREATE, UROL_UID_CREATE, UROL_DT_LUPD, UROL_UID_LUPD, UROL_TEMP_ROLE) VALUES('",A7,"','",D7,"','",E7,"','",F7,"','",H7,"',NOW(),'SYS', NOW(),'SYS','",G7,"');") -> INSERT INTO T_CORE_USR_ROLE(UROL_UID, UROL_APPSCODE, UROL_ROLEID, UROL_ADMIN_OPT, UROL_STATUS, UROL_DT_CREATE, UROL_UID_CREATE, UROL_DT_LUPD, UROL_UID_LUPD, UROL_TEMP_ROLE) VALUES('ALMGA_U003','CK','OFFICER','N','A',NOW(),'SYS', NOW(),'SYS','N');
A8: ASPIND_U001 | B8: ASPIND | C8: ACC_TYPE_CO | D8: CK | E8: OFFICER | F8: N | G8: N | H8: A | I8: =CONCATENATE("INSERT INTO T_CORE_USR_ROLE(UROL_UID, UROL_APPSCODE, UROL_ROLEID, UROL_ADMIN_OPT, UROL_STATUS, UROL_DT_CREATE, UROL_UID_CREATE, UROL_DT_LUPD, UROL_UID_LUPD, UROL_TEMP_ROLE) VALUES('",A8,"','",D8,"','",E8,"','",F8,"','",H8,"',NOW(),'SYS', NOW(),'SYS','",G8,"');") -> INSERT INTO T_CORE_USR_ROLE(UROL_UID, UROL_APPSCODE, UROL_ROLEID, UROL_ADMIN_OPT, UROL_STATUS, UROL_DT_CREATE, UROL_UID_CREATE, UROL_DT_LUPD, UROL_UID_LUPD, UROL_TEMP_ROLE) VALUES('ASPIND_U001','CK','OFFICER','N','A',NOW(),'SYS', NOW(),'SYS','N');
A9: ASPIND_U002 | B9: ASPIND | C9: ACC_TYPE_CO | D9: CK | E9: OFFICER | F9: N | G9: N | H9: A | I9: =CONCATENATE("INSERT INTO T_CORE_USR_ROLE(UROL_UID, UROL_APPSCODE, UROL_ROLEID, UROL_ADMIN_OPT, UROL_STATUS, UROL_DT_CREATE, UROL_UID_CREATE, UROL_DT_LUPD, UROL_UID_LUPD, UROL_TEMP_ROLE) VALUES('",A9,"','",D9,"','",E9,"','",F9,"','",H9,"',NOW(),'SYS', NOW(),'SYS','",G9,"');") -> INSERT INTO T_CORE_USR_ROLE(UROL_UID, UROL_APPSCODE, UROL_ROLEID, UROL_ADMIN_OPT, UROL_STATUS, UROL_DT_CREATE, UROL_UID_CREATE, UROL_DT_LUPD, UROL_UID_LUPD, UROL_TEMP_ROLE) VALUES('ASPIND_U002','CK','OFFICER','N','A',NOW(),'SYS', NOW(),'SYS','N');
A10: ASPIND_U003 | B10: ASPIND | C10: ACC_TYPE_CO | D10: CK | E10: OFFICER | F10: N | G10: N | H10: A | I10: =CONCATENATE("INSERT INTO T_CORE_USR_ROLE(UROL_UID, UROL_APPSCODE, UROL_ROLEID, UROL_ADMIN_OPT, UROL_STATUS, UROL_DT_CREATE, UROL_UID_CREATE, UROL_DT_LUPD, UROL_UID_LUPD, UROL_TEMP_ROLE) VALUES('",A10,"','",D10,"','",E10,"','",F10,"','",H10,"',NOW(),'SYS', NOW(),'SYS','",G10,"');") -> INSERT INTO T_CORE_USR_ROLE(UROL_UID, UROL_APPSCODE, UROL_ROLEID, UROL_ADMIN_OPT, UROL_STATUS, UROL_DT_CREATE, UROL_UID_CREATE, UROL_DT_LUPD, UROL_UID_LUPD, UROL_TEMP_ROLE) VALUES('ASPIND_U003','CK','OFFICER','N','A',NOW(),'SYS', NOW(),'SYS','N');
A11: COMLG_U001 | B11: COMLG | C11: ACC_TYPE_FF | D11: CK | E11: OFFICER | F11: N | G11: N | H11: A | I11: =CONCATENATE("INSERT INTO T_CORE_USR_ROLE(UROL_UID, UROL_APPSCODE, UROL_ROLEID, UROL_ADMIN_OPT, UROL_STATUS, UROL_DT_CREATE, UROL_UID_CREATE, UROL_DT_LUPD, UROL_UID_LUPD, UROL_TEMP_ROLE) VALUES('",A11,"','",D11,"','",E11,"','",F11,"','",H11,"',NOW(),'SYS', NOW(),'SYS','",G11,"');") -> INSERT INTO T_CORE_USR_ROLE(UROL_UID, UROL_APPSCODE, UROL_ROLEID, UROL_ADMIN_OPT, UROL_STATUS, UROL_DT_CREATE, UROL_UID_CREATE, UROL_DT_LUPD, UROL_UID_LUPD, UROL_TEMP_ROLE) VALUES('COMLG_U001','CK','OFFICER','N','A',NOW(),'SYS', NOW(),'SYS','N');
A12: COMLG_U002 | B12: COMLG | C12: ACC_TYPE_FF | D12: CK | E12: OFFICER | F12: N | G12: N | H12: A | I12: =CONCATENATE("INSERT INTO T_CORE_USR_ROLE(UROL_UID, UROL_APPSCODE, UROL_ROLEID, UROL_ADMIN_OPT, UROL_STATUS, UROL_DT_CREATE, UROL_UID_CREATE, UROL_DT_LUPD, UROL_UID_LUPD, UROL_TEMP_ROLE) VALUES('",A12,"','",D12,"','",E12,"','",F12,"','",H12,"',NOW(),'SYS', NOW(),'SYS','",G12,"');") -> INSERT INTO T_CORE_USR_ROLE(UROL_UID, UROL_APPSCODE, UROL_ROLEID, UROL_ADMIN_OPT, UROL_STATUS, UROL_DT_CREATE, UROL_UID_CREATE, UROL_DT_LUPD, UROL_UID_LUPD, UROL_TEMP_ROLE) VALUES('COMLG_U002','CK','OFFICER','N','A',NOW(),'SYS', NOW(),'SYS','N');
A13: COMLG_U003 | B13: COMLG | C13: ACC_TYPE_FF | D13: CK | E13: OFFICER | F13: N | G13: N | H13: A | I13: =CONCATENATE("INSERT INTO T_CORE_USR_ROLE(UROL_UID, UROL_APPSCODE, UROL_ROLEID, UROL_ADMIN_OPT, UROL_STATUS, UROL_DT_CREATE, UROL_UID_CREATE, UROL_DT_LUPD, UROL_UID_LUPD, UROL_TEMP_ROLE) VALUES('",A13,"','",D13,"','",E13,"','",F13,"','",H13,"',NOW(),'SYS', NOW(),'SYS','",G13,"');") -> INSERT INTO T_CORE_USR_ROLE(UROL_UID, UROL_APPSCODE, UROL_ROLEID, UROL_ADMIN_OPT, UROL_STATUS, UROL_DT_CREATE, UROL_UID_CREATE, UROL_DT_LUPD, UROL_UID_LUPD, UROL_TEMP_ROLE) VALUES('COMLG_U003','CK','OFFICER','N','A',NOW(),'SYS', NOW(),'SYS','N');
... A38: GLI_U001 | B38: GLI | C38: ACC_TYPE_SP | D38: CKT | E38: SP_OP_ADMIN | F38: N | G38: N | H38: A | I38: =CONCATENATE("INSERT INTO T_CORE_USR_ROLE(UROL_UID, UROL_APPSCODE, UROL_ROLEID, UROL_ADMIN_OPT, UROL_STATUS, UROL_DT_CREATE, UROL_UID_CREATE, UROL_DT_LUPD, UROL_UID_LUPD, UROL_TEMP_ROLE) VALUES('",A38,"','",D38,"','",E38,"','",F38,"','",H38,"',NOW(),'SYS', NOW(),'SYS','",G38,"');") -> INSERT INTO T_CORE_USR_ROLE(UROL_UID, UROL_APPSCODE, UROL_ROLEID, UROL_ADMIN_OPT, UROL_STATUS, UROL_DT_CREATE, UROL_UID_CREATE, UROL_DT_LUPD, UROL_UID_LUPD, UROL_TEMP_ROLE) VALUES('GLI_U001','CKT','SP_OP_ADMIN','N','A',NOW(),'SYS', NOW(),'SYS','N');
A39: GLI_L1 | B39: GLI | C39: ACC_TYPE_SP | D39: CKT | E39: SP_L1 | F39: N | G39: N | H39: A
A40: GLI_SYS_ADMIN | B40: GLI | C40: ACC_TYPE_SP | D40: CKT | E40: SYS_SUPER_ADMIN | F40: N | G40: N | H40: A | I40: =CONCATENATE("INSERT INTO T_CORE_USR_ROLE(UROL_UID, UROL_APPSCODE, UROL_ROLEID, UROL_ADMIN_OPT, UROL_STATUS, UROL_DT_CREATE, UROL_UID_CREATE, UROL_DT_LUPD, UROL_UID_LUPD, UROL_TEMP_ROLE) VALUES('",A40,"','",D40,"','",E40,"','",F40,"','",H40,"',NOW(),'SYS', NOW(),'SYS','",G40,"');") -> INSERT INTO T_CORE_USR_ROLE(UROL_UID, UROL_APPSCODE, UROL_ROLEID, UROL_ADMIN_OPT, UROL_STATUS, UROL_DT_CREATE, UROL_UID_CREATE, UROL_DT_LUPD, UROL_UID_LUPD, UROL_TEMP_ROLE) VALUES('GLI_SYS_ADMIN','CKT','SYS_SUPER_ADMIN','N','A',NOW(),'SYS', NOW(),'SYS','N');
A41: GLI_U001 | B41: GLI | C41: ACC_TYPE_SP | D41: CKDO | E41: FINANCE_ADMIN | F41: N | G41: N | H41: A | I41: =CONCATENATE("INSERT INTO T_CORE_USR_ROLE(UROL_UID, UROL_APPSCODE, UROL_ROLEID, UROL_ADMIN_OPT, UROL_STATUS, UROL_DT_CREATE, UROL_UID_CREATE, UROL_DT_LUPD, UROL_UID_LUPD, UROL_TEMP_ROLE) VALUES('",A41,"','",D41,"','",E41,"','",F41,"','",H41,"',NOW(),'SYS', NOW(),'SYS','",G41,"');") -> INSERT INTO T_CORE_USR_ROLE(UROL_UID, UROL_APPSCODE, UROL_ROLEID, UROL_ADMIN_OPT, UROL_STATUS, UROL_DT_CREATE, UROL_UID_CREATE, UROL_DT_LUPD, UROL_UID_LUPD, UROL_TEMP_ROLE) VALUES('GLI_U001','CKDO','FINANCE_ADMIN','N','A',NOW(),'SYS', NOW(),'SYS','N');
A42: GLI_U001 | B42: GLI | C42: ACC_TYPE_SP | D42: CKDO | E42: SP_OP_ADMIN | F42: N | G42: N | H42: A | I42: =CONCATENATE("INSERT INTO T_CORE_USR_ROLE(UROL_UID, UROL_APPSCODE, UROL_ROLEID, UROL_ADMIN_OPT, UROL_STATUS, UROL_DT_CREATE, UROL_UID_CREATE, UROL_DT_LUPD, UROL_UID_LUPD, UROL_TEMP_ROLE) VALUES('",A42,"','",D42,"','",E42,"','",F42,"','",H42,"',NOW(),'SYS', NOW(),'SYS','",G42,"');") -> INSERT INTO T_CORE_USR_ROLE(UROL_UID, UROL_APPSCODE, UROL_ROLEID, UROL_ADMIN_OPT, UROL_STATUS, UROL_DT_CREATE, UROL_UID_CREATE, UROL_DT_LUPD, UROL_UID_LUPD, UROL_TEMP_ROLE) VALUES('GLI_U001','CKDO','SP_OP_ADMIN','N','A',NOW(),'SYS', NOW(),'SYS','N');
A43: GLI_L1 | B43: GLI | C43: ACC_TYPE_SP | D43: CKDO | E43: SP_L1 | F43: N | G43: N | H43: A | I43: =CONCATENATE("INSERT INTO T_CORE_USR_ROLE(UROL_UID, UROL_APPSCODE, UROL_ROLEID, UROL_ADMIN_OPT, UROL_STATUS, UROL_DT_CREATE, UROL_UID_CREATE, UROL_DT_LUPD, UROL_UID_LUPD, UROL_TEMP_ROLE) VALUES('",A43,"','",D43,"','",E43,"','",F43,"','",H43,"',NOW(),'SYS', NOW(),'SYS','",G43,"');") -> INSERT INTO T_CORE_USR_ROLE(UROL_UID, UROL_APPSCODE, UROL_ROLEID, UROL_ADMIN_OPT, UROL_STATUS, UROL_DT_CREATE, UROL_UID_CREATE, UROL_DT_LUPD, UROL_UID_LUPD, UROL_TEMP_ROLE) VALUES('GLI_L1','CKDO','SP_L1','N','A',NOW(),'SYS', NOW(),'SYS','N');
A44: GLI_U001 | B44: GLI | C44: ACC_TYPE_SP | D44: CKDO | E44: SP_L1 | F44: N | G44: N | H44: A | I44: =CONCATENATE("INSERT INTO T_CORE_USR_ROLE(UROL_UID, UROL_APPSCODE, UROL_ROLEID, UROL_ADMIN_OPT, UROL_STATUS, UROL_DT_CREATE, UROL_UID_CREATE, UROL_DT_LUPD, UROL_UID_LUPD, UROL_TEMP_ROLE) VALUES('",A44,"','",D44,"','",E44,"','",F44,"','",H44,"',NOW(),'SYS', NOW(),'SYS','",G44,"');") -> INSERT INTO T_CORE_USR_ROLE(UROL_UID, UROL_APPSCODE, UROL_ROLEID, UROL_ADMIN_OPT, UROL_STATUS, UROL_DT_CREATE, UROL_UID_CREATE, UROL_DT_LUPD, UROL_UID_LUPD, UROL_TEMP_ROLE) VALUES('GLI_U001','CKDO','SP_L1','N','A',NOW(),'SYS', NOW(),'SYS','N');

Sheet CK Master Tables
A1: CREDIT UPDATE STATE
A2: ID | B2: NAME | C2: DESC | D2: DESC OTH | E2: STATUS | F2: SQL
A3: NEW | B3: NEW | C3: NEW | D3: NEW | E3: A | F3: =CONCATENATE(G3,H3) -> INSERT INTO `T_CK_MST_CREDIT_UPDATE_STATE` (`ST_ID`,`ST_NAME`,`ST_DESC`,`ST_DESC_OTH`,`ST_STATUS`,`ST_DT_CREATE`,`ST_UID_CREATE`,`ST_DT_LUPD`,`ST_UID_LUPD`) VALUES('NEW','NEW','NEW','NEW','A',NOW(),'SYS',NOW(),'SYS'); | G3: =CONCATENATE("INSERT INTO `T_CK_MST_CREDIT_UPDATE_STATE` (`ST_ID`,`ST_NAME`,`ST_DESC`,`ST_DESC_OTH`,`ST_STATUS`,`ST_DT_CREATE`,`ST_UID_CREATE`,`ST_DT_LUPD`,`ST_UID_LUPD`) ") -> INSERT INTO `T_CK_MST_CREDIT_UPDATE_STATE` (`ST_ID`,`ST_NAME`,`ST_DESC`,`ST_DESC_OTH`,`ST_STATUS`,`ST_DT_CREATE`,`ST_UID_CREATE`,`ST_DT_LUPD`,`ST_UID_LUPD`) | H3: =CONCATENATE(" VALUES('",A3,"','",B3,"','",C3,"','",D3,"','",E3,"',NOW(),'SYS',NOW(),'SYS');") -> VALUES('NEW','NEW','NEW','NEW','A',NOW(),'SYS',NOW(),'SYS');
A4: SUB | B4: SUBMITTED | C4: SUBMITTED | D4: SUBMITTED | E4: A | F4: =CONCATENATE(G4,H4) -> INSERT INTO `T_CK_MST_CREDIT_UPDATE_STATE` (`ST_ID`,`ST_NAME`,`ST_DESC`,`ST_DESC_OTH`,`ST_STATUS`,`ST_DT_CREATE`,`ST_UID_CREATE`,`ST_DT_LUPD`,`ST_UID_LUPD`) VALUES('SUB','SUBMITTED','SUBMITTED','SUBMITTED','A',NOW(),'SYS',NOW(),'SYS'); | G4: =CONCATENATE("INSERT INTO `T_CK_MST_CREDIT_UPDATE_STATE` (`ST_ID`,`ST_NAME`,`ST_DESC`,`ST_DESC_OTH`,`ST_STATUS`,`ST_DT_CREATE`,`ST_UID_CREATE`,`ST_DT_LUPD`,`ST_UID_LUPD`) ") -> INSERT INTO `T_CK_MST_CREDIT_UPDATE_STATE` (`ST_ID`,`ST_NAME`,`ST_DESC`,`ST_DESC_OTH`,`ST_STATUS`,`ST_DT_CREATE`,`ST_UID_CREATE`,`ST_DT_LUPD`,`ST_UID_LUPD`) | H4: =CONCATENATE(" VALUES('",A4,"','",B4,"','",C4,"','",D4,"','",E4,"',NOW(),'SYS',NOW(),'SYS');") -> VALUES('SUB','SUBMITTED','SUBMITTED','SUBMITTED','A',NOW(),'SYS',NOW(),'SYS');
A5: DEL | B5: DELETED | C5: DELETED | D5: DELETED | E5: A | F5: =CONCATENATE(G5,H5) -> INSERT INTO `T_CK_MST_CREDIT_UPDATE_STATE` (`ST_ID`,`ST_NAME`,`ST_DESC`,`ST_DESC_OTH`,`ST_STATUS`,`ST_DT_CREATE`,`ST_UID_CREATE`,`ST_DT_LUPD`,`ST_UID_LUPD`) VALUES('DEL','DELETED','DELETED','DELETED','A',NOW(),'SYS',NOW(),'SYS'); | G5: =CONCATENATE("INSERT INTO `T_CK_MST_CREDIT_UPDATE_STATE` (`ST_ID`,`ST_NAME`,`ST_DESC`,`ST_DESC_OTH`,`ST_STATUS`,`ST_DT_CREATE`,`ST_UID_CREATE`,`ST_DT_LUPD`,`ST_UID_LUPD`) ") -> INSERT INTO `T_CK_MST_CREDIT_UPDATE_STATE` (`ST_ID`,`ST_NAME`,`ST_DESC`,`ST_DESC_OTH`,`ST_STATUS`,`ST_DT_CREATE`,`ST_UID_CREATE`,`ST_DT_LUPD`,`ST_UID_LUPD`) | H5: =CONCATENATE(" VALUES('",A5,"','",B5,"','",C5,"','",D5,"','",E5,"',NOW(),'SYS',NOW(),'SYS');") -> VALUES('DEL','DELETED','DELETED','DELETED','A',NOW(),'SYS',NOW(),'SYS');
A6: APP | B6: APPROVED | C6: APPROVED | D6: APPROVED | E6: A | F6: =CONCATENATE(G6,H6) -> INSERT INTO `T_CK_MST_CREDIT_UPDATE_STATE` (`ST_ID`,`ST_NAME`,`ST_DESC`,`ST_DESC_OTH`,`ST_STATUS`,`ST_DT_CREATE`,`ST_UID_CREATE`,`ST_DT_LUPD`,`ST_UID_LUPD`) VALUES('APP','APPROVED','APPROVED','APPROVED','A',NOW(),'SYS',NOW(),'SYS'); | G6: =CONCATENATE("INSERT INTO `T_CK_MST_CREDIT_UPDATE_STATE` (`ST_ID`,`ST_NAME`,`ST_DESC`,`ST_DESC_OTH`,`ST_STATUS`,`ST_DT_CREATE`,`ST_UID_CREATE`,`ST_DT_LUPD`,`ST_UID_LUPD`) ") -> INSERT INTO `T_CK_MST_CREDIT_UPDATE_STATE` (`ST_ID`,`ST_NAME`,`ST_DESC`,`ST_DESC_OTH`,`ST_STATUS`,`ST_DT_CREATE`,`ST_UID_CREATE`,`ST_DT_LUPD`,`ST_UID_LUPD`) | H6: =CONCATENATE(" VALUES('",A6,"','",B6,"','",C6,"','",D6,"','",E6,"',NOW(),'SYS',NOW(),'SYS');") -> VALUES('APP','APPROVED','APPROVED','APPROVED','A',NOW(),'SYS',NOW(),'SYS');
A7: REJ | B7: REJECTED | C7: REJECTED | D7: REJECTED | E7: A | F7: =CONCATENATE(G7,H7) -> INSERT INTO `T_CK_MST_CREDIT_UPDATE_STATE` (`ST_ID`,`ST_NAME`,`ST_DESC`,`ST_DESC_OTH`,`ST_STATUS`,`ST_DT_CREATE`,`ST_UID_CREATE`,`ST_DT_LUPD`,`ST_UID_LUPD`) VALUES('REJ','REJECTED','REJECTED','REJECTED','A',NOW(),'SYS',NOW(),'SYS'); | G7: =CONCATENATE("INSERT INTO `T_CK_MST_CREDIT_UPDATE_STATE` (`ST_ID`,`ST_NAME`,`ST_DESC`,`ST_DESC_OTH`,`ST_STATUS`,`ST_DT_CREATE`,`ST_UID_CREATE`,`ST_DT_LUPD`,`ST_UID_LUPD`) ") -> INSERT INTO `T_CK_MST_CREDIT_UPDATE_STATE` (`ST_ID`,`ST_NAME`,`ST_DESC`,`ST_DESC_OTH`,`ST_STATUS`,`ST_DT_CREATE`,`ST_UID_CREATE`,`ST_DT_LUPD`,`ST_UID_LUPD`) | H7: =CONCATENATE(" VALUES('",A7,"','",B7,"','",C7,"','",D7,"','",E7,"',NOW(),'SYS',NOW(),'SYS');") -> VALUES('REJ','REJECTED','REJECTED','REJECTED','A',NOW(),'SYS',NOW(),'SYS');

Sheet Menu_EX_CK2
A1: MENU_ID | B1: MENU_APPS_CODE | C1: REMARKS | D1: MENU_GROUP_LABEL | E1: MENU_GROUP_LABEL_OTH | F1: MENU_NAME | G1: MENU_NAME_OTH | H1: MENU_SEQ | I1: MENU_PATH | J1: MENU_ICON | K1: MENU_PARENT | L1: MENU_STATUS | M1: SQL
A2: CK_MH_080000 | B2: CK | D2: Help | E2: Help | F2: Help | G2: Help | H2: 80000 | I2: /help | J2: help | K2: NULL | L2: A | M2: =CONCATENATE("INSERT INTO T_CORE_MENU_EX (MENU_ID, MENU_APPS_CODE, MENU_GROUP_LABEL, MENU_GROUP_LABEL_OTH, MENU_NAME, MENU_NAME_OTH, MENU_SEQ, MENU_PATH, MENU_ICON, MENU_PARENT, MENU_STATUS, MENU_DT_CREATE, MENU_UID_CREATE, MENU_DT_LUPD, MENU_UID_LUPD) ") -> INSERT INTO T_CORE_MENU_EX (MENU_ID, MENU_APPS_CODE, MENU_GROUP_LABEL, MENU_GROUP_LABEL_OTH, MENU_NAME, MENU_NAME_OTH, MENU_SEQ, MENU_PATH, MENU_ICON, MENU_PARENT, MENU_STATUS, MENU_DT_CREATE, MENU_UID_CREATE, MENU_DT_LUPD, MENU_UID_LUPD) | N2: =CONCATENATE(" VALUES('",A2,"','",B2,"','",D2,"','",E2,"','",F2,"','",G2,"',",IF(H2="NULL","NULL",CONCATENATE("'",H2,"'")),",",IF(I2="NULL","NULL",CONCATENATE("'",I2,"'")),",",IF(J2="NULL","NULL",CONCATENATE("'",J2,"'")),",",IF(K2="NULL","NULL",CONCATENATE("'",K2,"'")),",'A',NOW(),'SYS',NOW(),'SYS');") -> VALUES('CK_MH_080000','CK','Help','Help','Help','Help','80000','/help','help',NULL,'A',NOW(),'SYS',NOW(),'SYS'); | O2: =CONCATENATE(M2,N2) -> INSERT INTO T_CORE_MENU_EX (MENU_ID, MENU_APPS_CODE, MENU_GROUP_LABEL, MENU_GROUP_LABEL_OTH, MENU_NAME, MENU_NAME_OTH, MENU_SEQ, MENU_PATH, MENU_ICON, MENU_PARENT, MENU_STATUS, MENU_DT_CREATE, MENU_UID_CREATE, MENU_DT_LUPD, MENU_UID_LUPD) VALUES('CK_MH_080000','CK','Help','Help','Help','Help','80000','/help','help',NULL,'A',NOW(),'SYS',NOW(),'SYS');
A3: CKT_MS_010000 | B3: CKT | D3: Services | E3: Services | F3: Services | G3: Services | H3: 10000 | I3: / | J3: grid_view | K3: NULL | L3: A | M3: =CONCATENATE("INSERT INTO T_CORE_MENU_EX (MENU_ID, MENU_APPS_CODE, MENU_GROUP_LABEL, MENU_GROUP_LABEL_OTH, MENU_NAME, MENU_NAME_OTH, MENU_SEQ, MENU_PATH, MENU_ICON, MENU_PARENT, MENU_STATUS, MENU_DT_CREATE, MENU_UID_CREATE, MENU_DT_LUPD, MENU_UID_LUPD) ") -> INSERT INTO T_CORE_MENU_EX (MENU_ID, MENU_APPS_CODE, MENU_GROUP_LABEL, MENU_GROUP_LABEL_OTH, MENU_NAME, MENU_NAME_OTH, MENU_SEQ, MENU_PATH, MENU_ICON, MENU_PARENT, MENU_STATUS, MENU_DT_CREATE, MENU_UID_CREATE, MENU_DT_LUPD, MENU_UID_LUPD) | N3: =CONCATENATE(" VALUES('",A3,"','",B3,"','",D3,"','",E3,"','",F3,"','",G3,"',",IF(H3="NULL","NULL",CONCATENATE("'",H3,"'")),",",IF(I3="NULL","NULL",CONCATENATE("'",I3,"'")),",",IF(J3="NULL","NULL",CONCATENATE("'",J3,"'")),",",IF(K3="NULL","NULL",CONCATENATE("'",K3,"'")),",'A',NOW(),'SYS',NOW(),'SYS');") -> VALUES('CKT_MS_010000','CKT','Services','Services','Services','Services','10000','/','grid_view',NULL,'A',NOW(),'SYS',NOW(),'SYS'); | O3: =CONCATENATE(M3,N3) -> INSERT INTO T_CORE_MENU_EX (MENU_ID, MENU_APPS_CODE, MENU_GROUP_LABEL, MENU_GROUP_LABEL_OTH, MENU_NAME, MENU_NAME_OTH, MENU_SEQ, MENU_PATH, MENU_ICON, MENU_PARENT, MENU_STATUS, MENU_DT_CREATE, MENU_UID_CREATE, MENU_DT_LUPD, MENU_UID_LUPD) VALUES('CKT_MS_010000','CKT','Services','Services','Services','Services','10000','/','grid_view',NULL,'A',NOW(),'SYS',NOW(),'SYS');
A4: CKT_MA_030000 | B4: CKT | D4: Administrations | E4: Administrations | F4: Administrations | G4: Administrations | H4: 30000 | I4: NULL | J4: admin_panel_settings | K4: NULL | L4: A | M4: =CONCATENATE("INSERT INTO T_CORE_MENU_EX (MENU_ID, MENU_APPS_CODE, MENU_GROUP_LABEL, MENU_GROUP_LABEL_OTH, MENU_NAME, MENU_NAME_OTH, MENU_SEQ, MENU_PATH, MENU_ICON, MENU_PARENT, MENU_STATUS, MENU_DT_CREATE, MENU_UID_CREATE, MENU_DT_LUPD, MENU_UID_LUPD) ") -> INSERT INTO T_CORE_MENU_EX (MENU_ID, MENU_APPS_CODE, MENU_GROUP_LABEL, MENU_GROUP_LABEL_OTH, MENU_NAME, MENU_NAME_OTH, MENU_SEQ, MENU_PATH, MENU_ICON, MENU_PARENT, MENU_STATUS, MENU_DT_CREATE, MENU_UID_CREATE, MENU_DT_LUPD, MENU_UID_LUPD) | N4: =CONCATENATE(" VALUES('",A4,"','",B4,"','",D4,"','",E4,"','",F4,"','",G4,"',",IF(H4="NULL","NULL",CONCATENATE("'",H4,"'")),",",IF(I4="NULL","NULL",CONCATENATE("'",I4,"'")),",",IF(J4="NULL","NULL",CONCATENATE("'",J4,"'")),",",IF(K4="NULL","NULL",CONCATENATE("'",K4,"'")),",'A',NOW(),'SYS',NOW(),'SYS');") -> VALUES('CKT_MA_030000','CKT','Administrations','Administrations','Administrations','Administrations','30000',NULL,'admin_panel_settings',NULL,'A',NOW(),'SYS',NOW(),'SYS'); | O4: =CONCATENATE(M4,N4) -> INSERT INTO T_CORE_MENU_EX (MENU_ID, MENU_APPS_CODE, MENU_GROUP_LABEL, MENU_GROUP_LABEL_OTH, MENU_NAME, MENU_NAME_OTH, MENU_SEQ, MENU_PATH, MENU_ICON, MENU_PARENT, MENU_STATUS, MENU_DT_CREATE, MENU_UID_CREATE, MENU_DT_LUPD, MENU_UID_LUPD) VALUES('CKT_MA_030000','CKT','Administrations','Administrations','Administrations','Administrations','30000',NULL,'admin_panel_settings',NULL,'A',NOW(),'SYS',NOW(),'SYS');
A5: CKT_MA_030100 | B5: CKT | F5: Manage Trucks | G5: Manage Trucks | H5: 30100 | I5: /administrations/truck-management/list | J5: NULL | K5: CKT_MA_030000 | L5: A | M5: =CONCATENATE("INSERT INTO T_CORE_MENU_EX (MENU_ID, MENU_APPS_CODE, MENU_GROUP_LABEL, MENU_GROUP_LABEL_OTH, MENU_NAME, MENU_NAME_OTH, MENU_SEQ, MENU_PATH, MENU_ICON, MENU_PARENT, MENU_STATUS, MENU_DT_CREATE, MENU_UID_CREATE, MENU_DT_LUPD, MENU_UID_LUPD) ") -> INSERT INTO T_CORE_MENU_EX (MENU_ID, MENU_APPS_CODE, MENU_GROUP_LABEL, MENU_GROUP_LABEL_OTH, MENU_NAME, MENU_NAME_OTH, MENU_SEQ, MENU_PATH, MENU_ICON, MENU_PARENT, MENU_STATUS, MENU_DT_CREATE, MENU_UID_CREATE, MENU_DT_LUPD, MENU_UID_LUPD) | N5: =CONCATENATE(" VALUES('",A5,"','",B5,"','",D5,"','",E5,"','",F5,"','",G5,"',",IF(H5="NULL","NULL",CONCATENATE("'",H5,"'")),",",IF(I5="NULL","NULL",CONCATENATE("'",I5,"'")),",",IF(J5="NULL","NULL",CONCATENATE("'",J5,"'")),",",IF(K5="NULL","NULL",CONCATENATE("'",K5,"'")),",'A',NOW(),'SYS',NOW(),'SYS');") -> VALUES('CKT_MA_030100','CKT','','','Manage Trucks','Manage Trucks','30100','/administrations/truck-management/list',NULL,'CKT_MA_030000','A',NOW(),'SYS',NOW(),'SYS'); | O5: =CONCATENATE(M5,N5) -> INSERT INTO T_CORE_MENU_EX (MENU_ID, MENU_APPS_CODE, MENU_GROUP_LABEL, MENU_GROUP_LABEL_OTH, MENU_NAME, MENU_NAME_OTH, MENU_SEQ, MENU_PATH, MENU_ICON, MENU_PARENT, MENU_STATUS, MENU_DT_CREATE, MENU_UID_CREATE, MENU_DT_LUPD, MENU_UID_LUPD) VALUES('CKT_MA_030100','CKT','','','Manage Trucks','Manage Trucks','30100','/administrations/truck-management/list',NULL,'CKT_MA_030000','A',NOW(),'SYS',NOW(),'SYS');
A6: CKT_MA_030200 | B6: CKT | F6: Manage Drivers | G6: Manage Drivers | H6: 30200 | I6: /administrations/driver-management/list | J6: NULL | K6: CKT_MA_030000 | L6: A | M6: =CONCATENATE("INSERT INTO T_CORE_MENU_EX (MENU_ID, MENU_APPS_CODE, MENU_GROUP_LABEL, MENU_GROUP_LABEL_OTH, MENU_NAME, MENU_NAME_OTH, MENU_SEQ, MENU_PATH, MENU_ICON, MENU_PARENT, MENU_STATUS, MENU_DT_CREATE, MENU_UID_CREATE, MENU_DT_LUPD, MENU_UID_LUPD) ") -> INSERT INTO T_CORE_MENU_EX (MENU_ID, MENU_APPS_CODE, MENU_GROUP_LABEL, MENU_GROUP_LABEL_OTH, MENU_NAME, MENU_NAME_OTH, MENU_SEQ, MENU_PATH, MENU_ICON, MENU_PARENT, MENU_STATUS, MENU_DT_CREATE, MENU_UID_CREATE, MENU_DT_LUPD, MENU_UID_LUPD) | N6: =CONCATENATE(" VALUES('",A6,"','",B6,"','",D6,"','",E6,"','",F6,"','",G6,"',",IF(H6="NULL","NULL",CONCATENATE("'",H6,"'")),",",IF(I6="NULL","NULL",CONCATENATE("'",I6,"'")),",",IF(J6="NULL","NULL",CONCATENATE("'",J6,"'")),",",IF(K6="NULL","NULL",CONCATENATE("'",K6,"'")),",'A',NOW(),'SYS',NOW(),'SYS');") -> VALUES('CKT_MA_030200','CKT','','','Manage Drivers','Manage Drivers','30200','/administrations/driver-management/list',NULL,'CKT_MA_030000','A',NOW(),'SYS',NOW(),'SYS'); | O6: =CONCATENATE(M6,N6) -> INSERT INTO T_CORE_MENU_EX (MENU_ID, MENU_APPS_CODE, MENU_GROUP_LABEL, MENU_GROUP_LABEL_OTH, MENU_NAME, MENU_NAME_OTH, MENU_SEQ, MENU_PATH, MENU_ICON, MENU_PARENT, MENU_STATUS, MENU_DT_CREATE, MENU_UID_CREATE, MENU_DT_LUPD, MENU_UID_LUPD) VALUES('CKT_MA_030200','CKT','','','Manage Drivers','Manage Drivers','30200','/administrations/driver-management/list',NULL,'CKT_MA_030000','A',NOW(),'SYS',NOW(),'SYS');
A7: CKT_MA_030300 | B7: CKT | F7: Manage Locations | G7: Manage Locations | H7: 30300 | I7: /administrations/location-management/list | J7: NULL | K7: CKT_MA_030000 | L7: A | M7: =CONCATENATE("INSERT INTO T_CORE_MENU_EX (MENU_ID, MENU_APPS_CODE, MENU_GROUP_LABEL, MENU_GROUP_LABEL_OTH, MENU_NAME, MENU_NAME_OTH, MENU_SEQ, MENU_PATH, MENU_ICON, MENU_PARENT, MENU_STATUS, MENU_DT_CREATE, MENU_UID_CREATE, MENU_DT_LUPD, MENU_UID_LUPD) ") -> INSERT INTO T_CORE_MENU_EX (MENU_ID, MENU_APPS_CODE, MENU_GROUP_LABEL, MENU_GROUP_LABEL_OTH, MENU_NAME, MENU_NAME_OTH, MENU_SEQ, MENU_PATH, MENU_ICON, MENU_PARENT, MENU_STATUS, MENU_DT_CREATE, MENU_UID_CREATE, MENU_DT_LUPD, MENU_UID_LUPD) | N7: =CONCATENATE(" VALUES('",A7,"','",B7,"','",D7,"','",E7,"','",F7,"','",G7,"',",IF(H7="NULL","NULL",CONCATENATE("'",H7,"'")),",",IF(I7="NULL","NULL",CONCATENATE("'",I7,"'")),",",IF(J7="NULL","NULL",CONCATENATE("'",J7,"'")),",",IF(K7="NULL","NULL",CONCATENATE("'",K7,"'")),",'A',NOW(),'SYS',NOW(),'SYS');") -> VALUES('CKT_MA_030300','CKT','','','Manage Locations','Manage Locations','30300','/administrations/location-management/list',NULL,'CKT_MA_030000','A',NOW(),'SYS',NOW(),'SYS'); | O7: =CONCATENATE(M7,N7) -> INSERT INTO T_CORE_MENU_EX (MENU_ID, MENU_APPS_CODE, MENU_GROUP_LABEL, MENU_GROUP_LABEL_OTH, MENU_NAME, MENU_NAME_OTH, MENU_SEQ, MENU_PATH, MENU_ICON, MENU_PARENT, MENU_STATUS, MENU_DT_CREATE, MENU_UID_CREATE, MENU_DT_LUPD, MENU_UID_LUPD) VALUES('CKT_MA_030300','CKT','','','Manage Locations','Manage Locations','30300','/administrations/location-management/list',NULL,'CKT_MA_030000','A',NOW(),'SYS',NOW(),'SYS');
A8: CKT_MA_030400 | B8: CKT | F8: Manage Rentals | G8: Manage Rentals | H8: 30400 | I8: /administrations/rental-management/list | J8: NULL | K8: CKT_MA_030000 | L8: A | M8: =CONCATENATE("INSERT INTO T_CORE_MENU_EX (MENU_ID, MENU_APPS_CODE, MENU_GROUP_LABEL, MENU_GROUP_LABEL_OTH, MENU_NAME, MENU_NAME_OTH, MENU_SEQ, MENU_PATH, MENU_ICON, MENU_PARENT, MENU_STATUS, MENU_DT_CREATE, MENU_UID_CREATE, MENU_DT_LUPD, MENU_UID_LUPD) ") -> INSERT INTO T_CORE_MENU_EX (MENU_ID, MENU_APPS_CODE, MENU_GROUP_LABEL, MENU_GROUP_LABEL_OTH, MENU_NAME, MENU_NAME_OTH, MENU_SEQ, MENU_PATH, MENU_ICON, MENU_PARENT, MENU_STATUS, MENU_DT_CREATE, MENU_UID_CREATE, MENU_DT_LUPD, MENU_UID_LUPD) | N8: =CONCATENATE(" VALUES('",A8,"','",B8,"','",D8,"','",E8,"','",F8,"','",G8,"',",IF(H8="NULL","NULL",CONCATENATE("'",H8,"'")),",",IF(I8="NULL","NULL",CONCATENATE("'",I8,"'")),",",IF(J8="NULL","NULL",CONCATENATE("'",J8,"'")),",",IF(K8="NULL","NULL",CONCATENATE("'",K8,"'")),",'A',NOW(),'SYS',NOW(),'SYS');") -> VALUES('CKT_MA_030400','CKT','','','Manage Rentals','Manage Rentals','30400','/administrations/rental-management/list',NULL,'CKT_MA_030000','A',NOW(),'SYS',NOW(),'SYS'); | O8: =CONCATENATE(M8,N8) -> INSERT INTO T_CORE_MENU_EX (MENU_ID, MENU_APPS_CODE, MENU_GROUP_LABEL, MENU_GROUP_LABEL_OTH, MENU_NAME, MENU_NAME_OTH, MENU_SEQ, MENU_PATH, MENU_ICON, MENU_PARENT, MENU_STATUS, MENU_DT_CREATE, MENU_UID_CREATE, MENU_DT_LUPD, MENU_UID_LUPD) VALUES('CKT_MA_030400','CKT','','','Manage Rentals','Manage Rentals','30400','/administrations/rental-management/list',NULL,'CKT_MA_030000','A',NOW(),'SYS',NOW(),'SYS');
A9: CKT_MA_030500 | B9: CKT | F9: Manage Rate Table | G9: Manage Rate Table | H9: 30500 | I9: /administrations/rateTable-management/list | J9: NULL | K9: CKT_MA_030000 | L9: A | M9: =CONCATENATE("INSERT INTO T_CORE_MENU_EX (MENU_ID, MENU_APPS_CODE, MENU_GROUP_LABEL, MENU_GROUP_LABEL_OTH, MENU_NAME, MENU_NAME_OTH, MENU_SEQ, MENU_PATH, MENU_ICON, MENU_PARENT, MENU_STATUS, MENU_DT_CREATE, MENU_UID_CREATE, MENU_DT_LUPD, MENU_UID_LUPD) ") -> INSERT INTO T_CORE_MENU_EX (MENU_ID, MENU_APPS_CODE, MENU_GROUP_LABEL, MENU_GROUP_LABEL_OTH, MENU_NAME, MENU_NAME_OTH, MENU_SEQ, MENU_PATH, MENU_ICON, MENU_PARENT, MENU_STATUS, MENU_DT_CREATE, MENU_UID_CREATE, MENU_DT_LUPD, MENU_UID_LUPD) | N9: =CONCATENATE(" VALUES('",A9,"','",B9,"','",D9,"','",E9,"','",F9,"','",G9,"',",IF(H9="NULL","NULL",CONCATENATE("'",H9,"'")),",",IF(I9="NULL","NULL",CONCATENATE("'",I9,"'")),",",IF(J9="NULL","NULL",CONCATENATE("'",J9,"'")),",",IF(K9="NULL","NULL",CONCATENATE("'",K9,"'")),",'A',NOW(),'SYS',NOW(),'SYS');") -> VALUES('CKT_MA_030500','CKT','','','Manage Rate Table','Manage Rate Table','30500','/administrations/rateTable-management/list',NULL,'CKT_MA_030000','A',NOW(),'SYS',NOW(),'SYS'); | O9: =CONCATENATE(M9,N9) -> INSERT INTO T_CORE_MENU_EX (MENU_ID, MENU_APPS_CODE, MENU_GROUP_LABEL, MENU_GROUP_LABEL_OTH, MENU_NAME, MENU_NAME_OTH, MENU_SEQ, MENU_PATH, MENU_ICON, MENU_PARENT, MENU_STATUS, MENU_DT_CREATE, MENU_UID_CREATE, MENU_DT_LUPD, MENU_UID_LUPD) VALUES('CKT_MA_030500','CKT','','','Manage Rate Table','Manage Rate Table','30500','/administrations/rateTable-management/list',NULL,'CKT_MA_030000','A',NOW(),'SYS',NOW(),'SYS');
A10: CKT_MA_030600 | B10: CKT | F10: Live Monitoring | G10: Live Monitoring | H10: 30600 | I10: /administrations/live-monitoring | J10: NULL | K10: CKT_MA_030000 | L10: A | M10: =CONCATENATE("INSERT INTO T_CORE_MENU_EX (MENU_ID, MENU_APPS_CODE, MENU_GROUP_LABEL, MENU_GROUP_LABEL_OTH, MENU_NAME, MENU_NAME_OTH, MENU_SEQ, MENU_PATH, MENU_ICON, MENU_PARENT, MENU_STATUS, MENU_DT_CREATE, MENU_UID_CREATE, MENU_DT_LUPD, MENU_UID_LUPD) ") -> INSERT INTO T_CORE_MENU_EX (MENU_ID, MENU_APPS_CODE, MENU_GROUP_LABEL, MENU_GROUP_LABEL_OTH, MENU_NAME, MENU_NAME_OTH, MENU_SEQ, MENU_PATH, MENU_ICON, MENU_PARENT, MENU_STATUS, MENU_DT_CREATE, MENU_UID_CREATE, MENU_DT_LUPD, MENU_UID_LUPD) | N10: =CONCATENATE(" VALUES('",A10,"','",B10,"','",D10,"','",E10,"','",F10,"','",G10,"',",IF(H10="NULL","NULL",CONCATENATE("'",H10,"'")),",",IF(I10="NULL","NULL",CONCATENATE("'",I10,"'")),",",IF(J10="NULL","NULL",CONCATENATE("'",J10,"'")),",",IF(K10="NULL","NULL",CONCATENATE("'",K10,"'")),",'A',NOW(),'SYS',NOW(),'SYS');") -> VALUES('CKT_MA_030600','CKT','','','Live Monitoring','Live Monitoring','30600','/administrations/live-monitoring',NULL,'CKT_MA_030000','A',NOW(),'SYS',NOW(),'SYS'); | O10: =CONCATENATE(M10,N10) -> INSERT INTO T_CORE_MENU_EX (MENU_ID, MENU_APPS_CODE, MENU_GROUP_LABEL, MENU_GROUP_LABEL_OTH, MENU_NAME, MENU_NAME_OTH, MENU_SEQ, MENU_PATH, MENU_ICON, MENU_PARENT, MENU_STATUS, MENU_DT_CREATE, MENU_UID_CREATE, MENU_DT_LUPD, MENU_UID_LUPD) VALUES('CKT_MA_030600','CKT','','','Live Monitoring','Live Monitoring','30600','/administrations/live-monitoring',NULL,'CKT_MA_030000','A',NOW(),'SYS',NOW(),'SYS');
A11: CKT_MA_030700 | B11: CKT | F11: Historical Monitoring | G11: Historical Monitoring | H11: 30700 | I11: /administrations/historical-monitoring | J11: NULL | K11: CKT_MA_030000 | L11: A | M11: =CONCATENATE("INSERT INTO T_CORE_MENU_EX (MENU_ID, MENU_APPS_CODE, MENU_GROUP_LABEL, MENU_GROUP_LABEL_OTH, MENU_NAME, MENU_NAME_OTH, MENU_SEQ, MENU_PATH, MENU_ICON, MENU_PARENT, MENU_STATUS, MENU_DT_CREATE, MENU_UID_CREATE, MENU_DT_LUPD, MENU_UID_LUPD) ") -> INSERT INTO T_CORE_MENU_EX (MENU_ID, MENU_APPS_CODE, MENU_GROUP_LABEL, MENU_GROUP_LABEL_OTH, MENU_NAME, MENU_NAME_OTH, MENU_SEQ, MENU_PATH, MENU_ICON, MENU_PARENT, MENU_STATUS, MENU_DT_CREATE, MENU_UID_CREATE, MENU_DT_LUPD, MENU_UID_LUPD) | N11: =CONCATENATE(" VALUES('",A11,"','",B11,"','",D11,"','",E11,"','",F11,"','",G11,"',",IF(H11="NULL","NULL",CONCATENATE("'",H11,"'")),",",IF(I11="NULL","NULL",CONCATENATE("'",I11,"'")),",",IF(J11="NULL","NULL",CONCATENATE("'",J11,"'")),",",IF(K11="NULL","NULL",CONCATENATE("'",K11,"'")),",'A',NOW(),'SYS',NOW(),'SYS');") -> VALUES('CKT_MA_030700','CKT','','','Historical Monitoring','Historical Monitoring','30700','/administrations/historical-monitoring',NULL,'CKT_MA_030000','A',NOW(),'SYS',NOW(),'SYS'); | O11: =CONCATENATE(M11,N11) -> INSERT INTO T_CORE_MENU_EX (MENU_ID, MENU_APPS_CODE, MENU_GROUP_LABEL, MENU_GROUP_LABEL_OTH, MENU_NAME, MENU_NAME_OTH, MENU_SEQ, MENU_PATH, MENU_ICON, MENU_PARENT, MENU_STATUS, MENU_DT_CREATE, MENU_UID_CREATE, MENU_DT_LUPD, MENU_UID_LUPD) VALUES('CKT_MA_030700','CKT','','','Historical Monitoring','Historical Monitoring','30700','/administrations/historical-monitoring',NULL,'CKT_MA_030000','A',NOW(),'SYS',NOW(),'SYS');
A12: CKT_MA_030800 | B12: CKT | F12: Truck Performance | G12: Truck Performance | H12: 30800 | I12: /administrations/trackTrackEnterExit/list | J12: NULL | K12: CKT_MA_030000 | L12: A | M12: =CONCATENATE("INSERT INTO T_CORE_MENU_EX (MENU_ID, MENU_APPS_CODE, MENU_GROUP_LABEL, MENU_GROUP_LABEL_OTH, MENU_NAME, MENU_NAME_OTH, MENU_SEQ, MENU_PATH, MENU_ICON, MENU_PARENT, MENU_STATUS, MENU_DT_CREATE, MENU_UID_CREATE, MENU_DT_LUPD, MENU_UID_LUPD) ") -> INSERT INTO T_CORE_MENU_EX (MENU_ID, MENU_APPS_CODE, MENU_GROUP_LABEL, MENU_GROUP_LABEL_OTH, MENU_NAME, MENU_NAME_OTH, MENU_SEQ, MENU_PATH, MENU_ICON, MENU_PARENT, MENU_STATUS, MENU_DT_CREATE, MENU_UID_CREATE, MENU_DT_LUPD, MENU_UID_LUPD) | N12: =CONCATENATE(" VALUES('",A12,"','",B12,"','",D12,"','",E12,"','",F12,"','",G12,"',",IF(H12="NULL","NULL",CONCATENATE("'",H12,"'")),",",IF(I12="NULL","NULL",CONCATENATE("'",I12,"'")),",",IF(J12="NULL","NULL",CONCATENATE("'",J12,"'")),",",IF(K12="NULL","NULL",CONCATENATE("'",K12,"'")),",'A',NOW(),'SYS',NOW(),'SYS');") -> VALUES('CKT_MA_030800','CKT','','','Truck Performance','Truck Performance','30800','/administrations/trackTrackEnterExit/list',NULL,'CKT_MA_030000','A',NOW(),'SYS',NOW(),'SYS'); | O12: =CONCATENATE(M12,N12) -> INSERT INTO T_CORE_MENU_EX (MENU_ID, MENU_APPS_CODE, MENU_GROUP_LABEL, MENU_GROUP_LABEL_OTH, MENU_NAME, MENU_NAME_OTH, MENU_SEQ, MENU_PATH, MENU_ICON, MENU_PARENT, MENU_STATUS, MENU_DT_CREATE, MENU_UID_CREATE, MENU_DT_LUPD, MENU_UID_LUPD) VALUES('CKT_MA_030800','CKT','','','Truck Performance','Truck Performance','30800','/administrations/trackTrackEnterExit/list',NULL,'CKT_MA_030000','A',NOW(),'SYS',NOW(),'SYS');
A13: CKT_MA_030900 | B13: CKT | F13: Manage Chassis | G13: Manage Chassis | H13: 30900 | I13: /administrations/chassis-management/list | J13: NULL | K13: CKT_MA_030000 | L13: A | M13: =CONCATENATE("INSERT INTO T_CORE_MENU_EX (MENU_ID, MENU_APPS_CODE, MENU_GROUP_LABEL, MENU_GROUP_LABEL_OTH, MENU_NAME, MENU_NAME_OTH, MENU_SEQ, MENU_PATH, MENU_ICON, MENU_PARENT, MENU_STATUS, MENU_DT_CREATE, MENU_UID_CREATE, MENU_DT_LUPD, MENU_UID_LUPD) ") -> INSERT INTO T_CORE_MENU_EX (MENU_ID, MENU_APPS_CODE, MENU_GROUP_LABEL, MENU_GROUP_LABEL_OTH, MENU_NAME, MENU_NAME_OTH, MENU_SEQ, MENU_PATH, MENU_ICON, MENU_PARENT, MENU_STATUS, MENU_DT_CREATE, MENU_UID_CREATE, MENU_DT_LUPD, MENU_UID_LUPD) | N13: =CONCATENATE(" VALUES('",A13,"','",B13,"','",D13,"','",E13,"','",F13,"','",G13,"',",IF(H13="NULL","NULL",CONCATENATE("'",H13,"'")),",",IF(I13="NULL","NULL",CONCATENATE("'",I13,"'")),",",IF(J13="NULL","NULL",CONCATENATE("'",J13,"'")),",",IF(K13="NULL","NULL",CONCATENATE("'",K13,"'")),",'A',NOW(),'SYS',NOW(),'SYS');") -> VALUES('CKT_MA_030900','CKT','','','Manage Chassis','Manage Chassis','30900','/administrations/chassis-management/list',NULL,'CKT_MA_030000','A',NOW(),'SYS',NOW(),'SYS'); | O13: =CONCATENATE(M13,N13) -> INSERT INTO T_CORE_MENU_EX (MENU_ID, MENU_APPS_CODE, MENU_GROUP_LABEL, MENU_GROUP_LABEL_OTH, MENU_NAME, MENU_NAME_OTH, MENU_SEQ, MENU_PATH, MENU_ICON, MENU_PARENT, MENU_STATUS, MENU_DT_CREATE, MENU_UID_CREATE, MENU_DT_LUPD, MENU_UID_LUPD) VALUES('CKT_MA_030900','CKT','','','Manage Chassis','Manage Chassis','30900','/administrations/chassis-management/list',NULL,'CKT_MA_030000','A',NOW(),'SYS',NOW(),'SYS');
A14: CKT_AA_050000 | B14: CKT | D14: Account Administration | E14: Account Administration | F14: Account Administration | G14: Account Administration | H14: 50000 | I14: NULL | J14: manage_accounts | K14: NULL | L14: A | M14: =CONCATENATE("INSERT INTO T_CORE_MENU_EX (MENU_ID, MENU_APPS_CODE, MENU_GROUP_LABEL, MENU_GROUP_LABEL_OTH, MENU_NAME, MENU_NAME_OTH, MENU_SEQ, MENU_PATH, MENU_ICON, MENU_PARENT, MENU_STATUS, MENU_DT_CREATE, MENU_UID_CREATE, MENU_DT_LUPD, MENU_UID_LUPD) ") -> INSERT INTO T_CORE_MENU_EX (MENU_ID, MENU_APPS_CODE, MENU_GROUP_LABEL, MENU_GROUP_LABEL_OTH, MENU_NAME, MENU_NAME_OTH, MENU_SEQ, MENU_PATH, MENU_ICON, MENU_PARENT, MENU_STATUS, MENU_DT_CREATE, MENU_UID_CREATE, MENU_DT_LUPD, MENU_UID_LUPD) | N14: =CONCATENATE(" VALUES('",A14,"','",B14,"','",D14,"','",E14,"','",F14,"','",G14,"',",IF(H14="NULL","NULL",CONCATENATE("'",H14,"'")),",",IF(I14="NULL","NULL",CONCATENATE("'",I14,"'")),",",IF(J14="NULL","NULL",CONCATENATE("'",J14,"'")),",",IF(K14="NULL","NULL",CONCATENATE("'",K14,"'")),",'A',NOW(),'SYS',NOW(),'SYS');") -> VALUES('CKT_AA_050000','CKT','Account Administration','Account Administration','Account Administration','Account Administration','50000',NULL,'manage_accounts',NULL,'A',NOW(),'SYS',NOW(),'SYS'); | O14: =CONCATENATE(M14,N14) -> INSERT INTO T_CORE_MENU_EX (MENU_ID, MENU_APPS_CODE, MENU_GROUP_LABEL, MENU_GROUP_LABEL_OTH, MENU_NAME, MENU_NAME_OTH, MENU_SEQ, MENU_PATH, MENU_ICON, MENU_PARENT, MENU_STATUS, MENU_DT_CREATE, MENU_UID_CREATE, MENU_DT_LUPD, MENU_UID_LUPD) VALUES('CKT_AA_050000','CKT','Account Administration','Account Administration','Account Administration','Account Administration','50000',NULL,'manage_accounts',NULL,'A',NOW(),'SYS',NOW(),'SYS');
A15: CKT_AA_050100 | B15: CKT | F15: Account Profile | G15: Account Profile | H15: 50100 | I15: /account/profile | J15: NULL | K15: CKT_AA_050000 | L15: A | M15: =CONCATENATE("INSERT INTO T_CORE_MENU_EX (MENU_ID, MENU_APPS_CODE, MENU_GROUP_LABEL, MENU_GROUP_LABEL_OTH, MENU_NAME, MENU_NAME_OTH, MENU_SEQ, MENU_PATH, MENU_ICON, MENU_PARENT, MENU_STATUS, MENU_DT_CREATE, MENU_UID_CREATE, MENU_DT_LUPD, MENU_UID_LUPD) ") -> INSERT INTO T_CORE_MENU_EX (MENU_ID, MENU_APPS_CODE, MENU_GROUP_LABEL, MENU_GROUP_LABEL_OTH, MENU_NAME, MENU_NAME_OTH, MENU_SEQ, MENU_PATH, MENU_ICON, MENU_PARENT, MENU_STATUS, MENU_DT_CREATE, MENU_UID_CREATE, MENU_DT_LUPD, MENU_UID_LUPD) | N15: =CONCATENATE(" VALUES('",A15,"','",B15,"','",D15,"','",E15,"','",F15,"','",G15,"',",IF(H15="NULL","NULL",CONCATENATE("'",H15,"'")),",",IF(I15="NULL","NULL",CONCATENATE("'",I15,"'")),",",IF(J15="NULL","NULL",CONCATENATE("'",J15,"'")),",",IF(K15="NULL","NULL",CONCATENATE("'",K15,"'")),",'A',NOW(),'SYS',NOW(),'SYS');") -> VALUES('CKT_AA_050100','CKT','','','Account Profile','Account Profile','50100','/account/profile',NULL,'CKT_AA_050000','A',NOW(),'SYS',NOW(),'SYS'); | O15: =CONCATENATE(M15,N15) -> INSERT INTO T_CORE_MENU_EX (MENU_ID, MENU_APPS_CODE, MENU_GROUP_LABEL, MENU_GROUP_LABEL_OTH, MENU_NAME, MENU_NAME_OTH, MENU_SEQ, MENU_PATH, MENU_ICON, MENU_PARENT, MENU_STATUS, MENU_DT_CREATE, MENU_UID_CREATE, MENU_DT_LUPD, MENU_UID_LUPD) VALUES('CKT_AA_050100','CKT','','','Account Profile','Account Profile','50100','/account/profile',NULL,'CKT_AA_050000','A',NOW(),'SYS',NOW(),'SYS');
A16: CKT_AA_050200 | B16: CKT | F16: Manage Users | G16: Manage Users | H16: 50200 | I16: /account/users | J16: NULL | K16: CKT_AA_050000 | L16: A | M16: =CONCATENATE("INSERT INTO T_CORE_MENU_EX (MENU_ID, MENU_APPS_CODE, MENU_GROUP_LABEL, MENU_GROUP_LABEL_OTH, MENU_NAME, MENU_NAME_OTH, MENU_SEQ, MENU_PATH, MENU_ICON, MENU_PARENT, MENU_STATUS, MENU_DT_CREATE, MENU_UID_CREATE, MENU_DT_LUPD, MENU_UID_LUPD) ") -> INSERT INTO T_CORE_MENU_EX (MENU_ID, MENU_APPS_CODE, MENU_GROUP_LABEL, MENU_GROUP_LABEL_OTH, MENU_NAME, MENU_NAME_OTH, MENU_SEQ, MENU_PATH, MENU_ICON, MENU_PARENT, MENU_STATUS, MENU_DT_CREATE, MENU_UID_CREATE, MENU_DT_LUPD, MENU_UID_LUPD) | N16: =CONCATENATE(" VALUES('",A16,"','",B16,"','",D16,"','",E16,"','",F16,"','",G16,"',",IF(H16="NULL","NULL",CONCATENATE("'",H16,"'")),",",IF(I16="NULL","NULL",CONCATENATE("'",I16,"'")),",",IF(J16="NULL","NULL",CONCATENATE("'",J16,"'")),",",IF(K16="NULL","NULL",CONCATENATE("'",K16,"'")),",'A',NOW(),'SYS',NOW(),'SYS');") -> VALUES('CKT_AA_050200','CKT','','','Manage Users','Manage Users','50200','/account/users',NULL,'CKT_AA_050000','A',NOW(),'SYS',NOW(),'SYS'); | O16: =CONCATENATE(M16,N16) -> INSERT INTO T_CORE_MENU_EX (MENU_ID, MENU_APPS_CODE, MENU_GROUP_LABEL, MENU_GROUP_LABEL_OTH, MENU_NAME, MENU_NAME_OTH, MENU_SEQ, MENU_PATH, MENU_ICON, MENU_PARENT, MENU_STATUS, MENU_DT_CREATE, MENU_UID_CREATE, MENU_DT_LUPD, MENU_UID_LUPD) VALUES('CKT_AA_050200','CKT','','','Manage Users','Manage Users','50200','/account/users',NULL,'CKT_AA_050000','A',NOW(),'SYS',NOW(),'SYS');
A17: CKT_AA_050300 | B17: CKT | F17: Manage Cargo Owners | G17: Manage Cargo Owners | H17: 50300 | I17: /manageAccountsFfCo/all/list | J17: NULL | K17: CKT_AA_050000 | L17: A | M17: =CONCATENATE("INSERT INTO T_CORE_MENU_EX (MENU_ID, MENU_APPS_CODE, MENU_GROUP_LABEL, MENU_GROUP_LABEL_OTH, MENU_NAME, MENU_NAME_OTH, MENU_SEQ, MENU_PATH, MENU_ICON, MENU_PARENT, MENU_STATUS, MENU_DT_CREATE, MENU_UID_CREATE, MENU_DT_LUPD, MENU_UID_LUPD) ") -> INSERT INTO T_CORE_MENU_EX (MENU_ID, MENU_APPS_CODE, MENU_GROUP_LABEL, MENU_GROUP_LABEL_OTH, MENU_NAME, MENU_NAME_OTH, MENU_SEQ, MENU_PATH, MENU_ICON, MENU_PARENT, MENU_STATUS, MENU_DT_CREATE, MENU_UID_CREATE, MENU_DT_LUPD, MENU_UID_LUPD) | N17: =CONCATENATE(" VALUES('",A17,"','",B17,"','",D17,"','",E17,"','",F17,"','",G17,"',",IF(H17="NULL","NULL", CONCATENATE("'",H17,"'")),",",IF(I17="NULL","NULL", CONCATENATE("'",I17,"'")),",",IF(J17="NULL","NULL", CONCATENATE("'",J17,"'")),",",IF(K17="NULL","NULL", CONCATENATE("'",K17,"'")),",'A',NOW(),'SYS',NOW(),'SYS');") -> VALUES('CKT_AA_050300','CKT','','','Manage Cargo Owners','Manage Cargo Owners','50300','/manageAccountsFfCo/all/list',NULL,'CKT_AA_050000','A',NOW(),'SYS',NOW(),'SYS'); | O17: =CONCATENATE(M17,N17) -> INSERT INTO T_CORE_MENU_EX (MENU_ID, MENU_APPS_CODE, MENU_GROUP_LABEL, MENU_GROUP_LABEL_OTH, MENU_NAME, MENU_NAME_OTH, MENU_SEQ, MENU_PATH, MENU_ICON, MENU_PARENT, MENU_STATUS, MENU_DT_CREATE, MENU_UID_CREATE, MENU_DT_LUPD, MENU_UID_LUPD) VALUES('CKT_AA_050300','CKT','','','Manage Cargo Owners','Manage Cargo Owners','50300','/manageAccountsFfCo/all/list',NULL,'CKT_AA_050000','A',NOW(),'SYS',NOW(),'SYS');
A18: CKT_MH_090000 | B18: CKT | D18: Help | E18: Help | F18: Help | G18: Help | H18: 90000 | I18: /help | J18: help | K18: NULL | L18: A | M18: =CONCATENATE("INSERT INTO T_CORE_MENU_EX (MENU_ID, MENU_APPS_CODE, MENU_GROUP_LABEL, MENU_GROUP_LABEL_OTH, MENU_NAME, MENU_NAME_OTH, MENU_SEQ, MENU_PATH, MENU_ICON, MENU_PARENT, MENU_STATUS, MENU_DT_CREATE, MENU_UID_CREATE, MENU_DT_LUPD, MENU_UID_LUPD) ") -> INSERT INTO T_CORE_MENU_EX (MENU_ID, MENU_APPS_CODE, MENU_GROUP_LABEL, MENU_GROUP_LABEL_OTH, MENU_NAME, MENU_NAME_OTH, MENU_SEQ, MENU_PATH, MENU_ICON, MENU_PARENT, MENU_STATUS, MENU_DT_CREATE, MENU_UID_CREATE, MENU_DT_LUPD, MENU_UID_LUPD) | N18: =CONCATENATE(" VALUES('",A18,"','",B18,"','",D18,"','",E18,"','",F18,"','",G18,"',",IF(H18="NULL","NULL",CONCATENATE("'",H18,"'")),",",IF(I18="NULL","NULL",CONCATENATE("'",I18,"'")),",",IF(J18="NULL","NULL",CONCATENATE("'",J18,"'")),",",IF(K18="NULL","NULL",CONCATENATE("'",K18,"'")),",'A',NOW(),'SYS',NOW(),'SYS');") -> VALUES('CKT_MH_090000','CKT','Help','Help','Help','Help','90000','/help','help',NULL,'A',NOW(),'SYS',NOW(),'SYS'); | O18: =CONCATENATE(M18,N18) -> INSERT INTO T_CORE_MENU_EX (MENU_ID, MENU_APPS_CODE, MENU_GROUP_LABEL, MENU_GROUP_LABEL_OTH, MENU_NAME, MENU_NAME_OTH, MENU_SEQ, MENU_PATH, MENU_ICON, MENU_PARENT, MENU_STATUS, MENU_DT_CREATE, MENU_UID_CREATE, MENU_DT_LUPD, MENU_UID_LUPD) VALUES('CKT_MH_090000','CKT','Help','Help','Help','Help','90000','/help','help',NULL,'A',NOW(),'SYS',NOW(),'SYS');
A19: CKT_FA_060000 | B19: CKT | C19: SP Finance Admin | D19: Finance Administration | E19: Finance Administration | F19: Finance Administration | G19: Finance Administration | H19: 60000 | I19: NULL | J19: account_balance | K19: NULL | L19: A | M19: =CONCATENATE("INSERT INTO T_CORE_MENU_EX (MENU_ID, MENU_APPS_CODE, MENU_GROUP_LABEL, MENU_GROUP_LABEL_OTH, MENU_NAME, MENU_NAME_OTH, MENU_SEQ, MENU_PATH, MENU_ICON, MENU_PARENT, MENU_STATUS, MENU_DT_CREATE, MENU_UID_CREATE, MENU_DT_LUPD, MENU_UID_LUPD) ") -> INSERT INTO T_CORE_MENU_EX (MENU_ID, MENU_APPS_CODE, MENU_GROUP_LABEL, MENU_GROUP_LABEL_OTH, MENU_NAME, MENU_NAME_OTH, MENU_SEQ, MENU_PATH, MENU_ICON, MENU_PARENT, MENU_STATUS, MENU_DT_CREATE, MENU_UID_CREATE, MENU_DT_LUPD, MENU_UID_LUPD) | N19: =CONCATENATE(" VALUES('",A19,"','",B19,"','",D19,"','",E19,"','",F19,"','",G19,"',",IF(H19="NULL","NULL",CONCATENATE("'",H19,"'")),",",IF(I19="NULL","NULL",CONCATENATE("'",I19,"'")),",",IF(J19="NULL","NULL",CONCATENATE("'",J19,"'")),",",IF(K19="NULL","NULL",CONCATENATE("'",K19,"'")),",'A',NOW(),'SYS',NOW(),'SYS');") -> VALUES('CKT_FA_060000','CKT','Finance Administration','Finance Administration','Finance Administration','Finance Administration','60000',NULL,'account_balance',NULL,'A',NOW(),'SYS',NOW(),'SYS'); | O19: =CONCATENATE(M19,N19) -> INSERT INTO T_CORE_MENU_EX (MENU_ID, MENU_APPS_CODE, MENU_GROUP_LABEL, MENU_GROUP_LABEL_OTH, MENU_NAME, MENU_NAME_OTH, MENU_SEQ, MENU_PATH, MENU_ICON, MENU_PARENT, MENU_STATUS, MENU_DT_CREATE, MENU_UID_CREATE, MENU_DT_LUPD, MENU_UID_LUPD) VALUES('CKT_FA_060000','CKT','Finance Administration','Finance Administration','Finance Administration','Finance Administration','60000',NULL,'account_balance',NULL,'A',NOW(),'SYS',NOW(),'SYS');
A20: CKT_FA_060100 | B20: CKT | F20: Sage Excel Report | G20: Sage Excel Report | H20: 60100 | I20: /manage/sage/excel | J20: NULL | K20: CKT_FA_060000 | L20: A | M20: =CONCATENATE("INSERT INTO T_CORE_MENU_EX (MENU_ID, MENU_APPS_CODE, MENU_GROUP_LABEL, MENU_GROUP_LABEL_OTH, MENU_NAME, MENU_NAME_OTH, MENU_SEQ, MENU_PATH, MENU_ICON, MENU_PARENT, MENU_STATUS, MENU_DT_CREATE, MENU_UID_CREATE, MENU_DT_LUPD, MENU_UID_LUPD) ") -> INSERT INTO T_CORE_MENU_EX (MENU_ID, MENU_APPS_CODE, MENU_GROUP_LABEL, MENU_GROUP_LABEL_OTH, MENU_NAME, MENU_NAME_OTH, MENU_SEQ, MENU_PATH, MENU_ICON, MENU_PARENT, MENU_STATUS, MENU_DT_CREATE, MENU_UID_CREATE, MENU_DT_LUPD, MENU_UID_LUPD) | N20: =CONCATENATE(" VALUES('",A20,"','",B20,"','",D20,"','",E20,"','",F20,"','",G20,"',",IF(H20="NULL","NULL",CONCATENATE("'",H20,"'")),",",IF(I20="NULL","NULL",CONCATENATE("'",I20,"'")),",",IF(J20="NULL","NULL",CONCATENATE("'",J20,"'")),",",IF(K20="NULL","NULL",CONCATENATE("'",K20,"'")),",'A',NOW(),'SYS',NOW(),'SYS');") -> VALUES('CKT_FA_060100','CKT','','','Sage Excel Report','Sage Excel Report','60100','/manage/sage/excel',NULL,'CKT_FA_060000','A',NOW(),'SYS',NOW(),'SYS'); | O20: =CONCATENATE(M20,N20) -> INSERT INTO T_CORE_MENU_EX (MENU_ID, MENU_APPS_CODE, MENU_GROUP_LABEL, MENU_GROUP_LABEL_OTH, MENU_NAME, MENU_NAME_OTH, MENU_SEQ, MENU_PATH, MENU_ICON, MENU_PARENT, MENU_STATUS, MENU_DT_CREATE, MENU_UID_CREATE, MENU_DT_LUPD, MENU_UID_LUPD) VALUES('CKT_FA_060100','CKT','','','Sage Excel Report','Sage Excel Report','60100','/manage/sage/excel',NULL,'CKT_FA_060000','A',NOW(),'SYS',NOW(),'SYS');
A21: CKT_FA_060200 | B21: CKT | F21: Manage Sage Tax No. | G21: Manage Sage Tax No. | H21: 60200 | I21: /manage/sage/tax | J21: NULL | K21: CKT_FA_060000 | L21: A | M21: =CONCATENATE("INSERT INTO T_CORE_MENU_EX (MENU_ID, MENU_APPS_CODE, MENU_GROUP_LABEL, MENU_GROUP_LABEL_OTH, MENU_NAME, MENU_NAME_OTH, MENU_SEQ, MENU_PATH, MENU_ICON, MENU_PARENT, MENU_STATUS, MENU_DT_CREATE, MENU_UID_CREATE, MENU_DT_LUPD, MENU_UID_LUPD) ") -> INSERT INTO T_CORE_MENU_EX (MENU_ID, MENU_APPS_CODE, MENU_GROUP_LABEL, MENU_GROUP_LABEL_OTH, MENU_NAME, MENU_NAME_OTH, MENU_SEQ, MENU_PATH, MENU_ICON, MENU_PARENT, MENU_STATUS, MENU_DT_CREATE, MENU_UID_CREATE, MENU_DT_LUPD, MENU_UID_LUPD) | N21: =CONCATENATE(" VALUES('",A21,"','",B21,"','",D21,"','",E21,"','",F21,"','",G21,"',",IF(H21="NULL","NULL",CONCATENATE("'",H21,"'")),",",IF(I21="NULL","NULL",CONCATENATE("'",I21,"'")),",",IF(J21="NULL","NULL",CONCATENATE("'",J21,"'")),",",IF(K21="NULL","NULL",CONCATENATE("'",K21,"'")),",'A',NOW(),'SYS',NOW(),'SYS');") -> VALUES('CKT_FA_060200','CKT','','','Manage Sage Tax No.','Manage Sage Tax No.','60200','/manage/sage/tax',NULL,'CKT_FA_060000','A',NOW(),'SYS',NOW(),'SYS'); | O21: =CONCATENATE(M21,N21) -> INSERT INTO T_CORE_MENU_EX (MENU_ID, MENU_APPS_CODE, MENU_GROUP_LABEL, MENU_GROUP_LABEL_OTH, MENU_NAME, MENU_NAME_OTH, MENU_SEQ, MENU_PATH, MENU_ICON, MENU_PARENT, MENU_STATUS, MENU_DT_CREATE, MENU_UID_CREATE, MENU_DT_LUPD, MENU_UID_LUPD) VALUES('CKT_FA_060200','CKT','','','Manage Sage Tax No.','Manage Sage Tax No.','60200','/manage/sage/tax',NULL,'CKT_FA_060000','A',NOW(),'SYS',NOW(),'SYS');
A22: CKT_FN_070000 | B22: CKT | C22: SP Finance | D22: Finance | E22: Finance | F22: Finance | G22: Finance | H22: 70000 | I22: NULL | J22: account_balance | K22: NULL | L22: A | M22: =CONCATENATE("INSERT INTO T_CORE_MENU_EX (MENU_ID, MENU_APPS_CODE, MENU_GROUP_LABEL, MENU_GROUP_LABEL_OTH, MENU_NAME, MENU_NAME_OTH, MENU_SEQ, MENU_PATH, MENU_ICON, MENU_PARENT, MENU_STATUS, MENU_DT_CREATE, MENU_UID_CREATE, MENU_DT_LUPD, MENU_UID_LUPD) ") -> INSERT INTO T_CORE_MENU_EX (MENU_ID, MENU_APPS_CODE, MENU_GROUP_LABEL, MENU_GROUP_LABEL_OTH, MENU_NAME, MENU_NAME_OTH, MENU_SEQ, MENU_PATH, MENU_ICON, MENU_PARENT, MENU_STATUS, MENU_DT_CREATE, MENU_UID_CREATE, MENU_DT_LUPD, MENU_UID_LUPD) | N22: =CONCATENATE(" VALUES('",A22,"','",B22,"','",D22,"','",E22,"','",F22,"','",G22,"',",IF(H22="NULL","NULL",CONCATENATE("'",H22,"'")),",",IF(I22="NULL","NULL",CONCATENATE("'",I22,"'")),",",IF(J22="NULL","NULL",CONCATENATE("'",J22,"'")),",",IF(K22="NULL","NULL",CONCATENATE("'",K22,"'")),",'A',NOW(),'SYS',NOW(),'SYS');") -> VALUES('CKT_FN_070000','CKT','Finance','Finance','Finance','Finance','70000',NULL,'account_balance',NULL,'A',NOW(),'SYS',NOW(),'SYS'); | O22: =CONCATENATE(M22,N22) -> INSERT INTO T_CORE_MENU_EX (MENU_ID, MENU_APPS_CODE, MENU_GROUP_LABEL, MENU_GROUP_LABEL_OTH, MENU_NAME, MENU_NAME_OTH, MENU_SEQ, MENU_PATH, MENU_ICON, MENU_PARENT, MENU_STATUS, MENU_DT_CREATE, MENU_UID_CREATE, MENU_DT_LUPD, MENU_UID_LUPD) VALUES('CKT_FN_070000','CKT','Finance','Finance','Finance','Finance','70000',NULL,'account_balance',NULL,'A',NOW(),'SYS',NOW(),'SYS');
A23: CKT_FN_070100 | B23: CKT | F23: Rate Table Management | G23: Rate Table Management | H23: 70100 | I23: /manage/ratetable | J23: NULL | K23: CKT_FN_070000 | L23: A | M23: =CONCATENATE("INSERT INTO T_CORE_MENU_EX (MENU_ID, MENU_APPS_CODE, MENU_GROUP_LABEL, MENU_GROUP_LABEL_OTH, MENU_NAME, MENU_NAME_OTH, MENU_SEQ, MENU_PATH, MENU_ICON, MENU_PARENT, MENU_STATUS, MENU_DT_CREATE, MENU_UID_CREATE, MENU_DT_LUPD, MENU_UID_LUPD) ") -> INSERT INTO T_CORE_MENU_EX (MENU_ID, MENU_APPS_CODE, MENU_GROUP_LABEL, MENU_GROUP_LABEL_OTH, MENU_NAME, MENU_NAME_OTH, MENU_SEQ, MENU_PATH, MENU_ICON, MENU_PARENT, MENU_STATUS, MENU_DT_CREATE, MENU_UID_CREATE, MENU_DT_LUPD, MENU_UID_LUPD) | N23: =CONCATENATE(" VALUES('",A23,"','",B23,"','",D23,"','",E23,"','",F23,"','",G23,"',",IF(H23="NULL","NULL",CONCATENATE("'",H23,"'")),",",IF(I23="NULL","NULL",CONCATENATE("'",I23,"'")),",",IF(J23="NULL","NULL",CONCATENATE("'",J23,"'")),",",IF(K23="NULL","NULL",CONCATENATE("'",K23,"'")),",'A',NOW(),'SYS',NOW(),'SYS');") -> VALUES('CKT_FN_070100','CKT','','','Rate Table Management','Rate Table Management','70100','/manage/ratetable',NULL,'CKT_FN_070000','A',NOW(),'SYS',NOW(),'SYS'); | O23: =CONCATENATE(M23,N23) -> INSERT INTO T_CORE_MENU_EX (MENU_ID, MENU_APPS_CODE, MENU_GROUP_LABEL, MENU_GROUP_LABEL_OTH, MENU_NAME, MENU_NAME_OTH, MENU_SEQ, MENU_PATH, MENU_ICON, MENU_PARENT, MENU_STATUS, MENU_DT_CREATE, MENU_UID_CREATE, MENU_DT_LUPD, MENU_UID_LUPD) VALUES('CKT_FN_070100','CKT','','','Rate Table Management','Rate Table Management','70100','/manage/ratetable',NULL,'CKT_FN_070000','A',NOW(),'SYS',NOW(),'SYS');
A24: CKT_FN_070200 | B24: CKT | F24: Contract Requests | G24: Contract Requests | H24: 70200 | I24: /opadmin/contractrequest/list | J24: NULL | K24: CKT_FN_070000 | L24: A | M24: =CONCATENATE("INSERT INTO T_CORE_MENU_EX (MENU_ID, MENU_APPS_CODE, MENU_GROUP_LABEL, MENU_GROUP_LABEL_OTH, MENU_NAME, MENU_NAME_OTH, MENU_SEQ, MENU_PATH, MENU_ICON, MENU_PARENT, MENU_STATUS, MENU_DT_CREATE, MENU_UID_CREATE, MENU_DT_LUPD, MENU_UID_LUPD) ") -> INSERT INTO T_CORE_MENU_EX (MENU_ID, MENU_APPS_CODE, MENU_GROUP_LABEL, MENU_GROUP_LABEL_OTH, MENU_NAME, MENU_NAME_OTH, MENU_SEQ, MENU_PATH, MENU_ICON, MENU_PARENT, MENU_STATUS, MENU_DT_CREATE, MENU_UID_CREATE, MENU_DT_LUPD, MENU_UID_LUPD) | N24: =CONCATENATE(" VALUES('",A24,"','",B24,"','",D24,"','",E24,"','",F24,"','",G24,"',",IF(H24="NULL","NULL",CONCATENATE("'",H24,"'")),",",IF(I24="NULL","NULL",CONCATENATE("'",I24,"'")),",",IF(J24="NULL","NULL",CONCATENATE("'",J24,"'")),",",IF(K24="NULL","NULL",CONCATENATE("'",K24,"'")),",'A',NOW(),'SYS',NOW(),'SYS');") -> VALUES('CKT_FN_070200','CKT','','','Contract Requests','Contract Requests','70200','/opadmin/contractrequest/list',NULL,'CKT_FN_070000','A',NOW(),'SYS',NOW(),'SYS'); | O24: =CONCATENATE(M24,N24) -> INSERT INTO T_CORE_MENU_EX (MENU_ID, MENU_APPS_CODE, MENU_GROUP_LABEL, MENU_GROUP_LABEL_OTH, MENU_NAME, MENU_NAME_OTH, MENU_SEQ, MENU_PATH, MENU_ICON, MENU_PARENT, MENU_STATUS, MENU_DT_CREATE, MENU_UID_CREATE, MENU_DT_LUPD, MENU_UID_LUPD) VALUES('CKT_FN_070200','CKT','','','Contract Requests','Contract Requests','70200','/opadmin/contractrequest/list',NULL,'CKT_FN_070000','A',NOW(),'SYS',NOW(),'SYS');
