Workbook

Sheet T_MST_RPT_CAT
A1: CATEGORY ID | B1: ACCN_TYPE | C1: ROLE | D1: APPSCODE | E1: REPORT DESCRIPTION | F1: OTHERS DESCRIPTION | G1: STATUS | H1: SCRIPT
A2: OP_ADMIN | B2: ACC_TYPE_TO | C2: OP_ADMIN | D2: CKT | E2: Operations Report | G2: A | H2: =CONCATENATE("INSERT INTO `T_MST_RPT_CAT` (`RPTC_CAT`,`RPTC_ACCN_TYPE`,`RPTC_ROLE_ID`,`RPTC_APPSID`,`RPTC_DESC`,`RPTC_DESC_OTH`,`RPTC_STATUS`,`RPTC_UID_CREATE`,`RPTC_DT_CREATE`,`RPTC_UID_LUPD`,`RPTC_DT_LUPD`) ") -> INSERT INTO `T_MST_RPT_CAT` (`RPTC_CAT`,`RPTC_ACCN_TYPE`,`RPTC_ROLE_ID`,`RPTC_APPSID`,`RPTC_DESC`,`RPTC_DESC_OTH`,`RPTC_STATUS`,`RPTC_UID_CREATE`,`RPTC_DT_CREATE`,`RPTC_UID_LUPD`,`RPTC_DT_LUPD`) | I2: =CONCATENATE(" VALUES('",A2,"','",B2,"','",C2,"','",D2,"','",E2,"','",F2,"','",G2,"','SYS',NOW(),'SYS',NOW());") -> VALUES('OP_ADMIN','ACC_TYPE_TO','OP_ADMIN','CKT','Operations Report','','A','SYS',NOW(),'SYS',NOW()); | J2: =CONCATENATE(H2, I2) -> INSERT INTO `T_MST_RPT_CAT` (`RPTC_CAT`,`RPTC_ACCN_TYPE`,`RPTC_ROLE_ID`,`RPTC_APPSID`,`RPTC_DESC`,`RPTC_DESC_OTH`,`RPTC_STATUS`,`RPTC_UID_CREATE`,`RPTC_DT_CREATE`,`RPTC_UID_LUPD`,`RPTC_DT_LUPD`) VALUES('OP_ADMIN','ACC_TYPE_TO','OP_ADMIN','CKT','Operations Report','','A','SYS',NOW(),'SYS',NOW());
A3: OP_ADMIN | B3: ACC_TYPE_CO | C3: OP_ADMIN | D3: CKT | E3: Operations Report | G3: A | H3: =CONCATENATE("INSERT INTO `T_MST_RPT_CAT` (`RPTC_CAT`,`RPTC_ACCN_TYPE`,`RPTC_ROLE_ID`,`RPTC_APPSID`,`RPTC_DESC`,`RPTC_DESC_OTH`,`RPTC_STATUS`,`RPTC_UID_CREATE`,`RPTC_DT_CREATE`,`RPTC_UID_LUPD`,`RPTC_DT_LUPD`) ") -> INSERT INTO `T_MST_RPT_CAT` (`RPTC_CAT`,`RPTC_ACCN_TYPE`,`RPTC_ROLE_ID`,`RPTC_APPSID`,`RPTC_DESC`,`RPTC_DESC_OTH`,`RPTC_STATUS`,`RPTC_UID_CREATE`,`RPTC_DT_CREATE`,`RPTC_UID_LUPD`,`RPTC_DT_LUPD`) | I3: =CONCATENATE(" VALUES('",A3,"','",B3,"','",C3,"','",D3,"','",E3,"','",F3,"','",G3,"','SYS',NOW(),'SYS',NOW());") -> VALUES('OP_ADMIN','ACC_TYPE_CO','OP_ADMIN','CKT','Operations Report','','A','SYS',NOW(),'SYS',NOW()); | J3: =CONCATENATE(H3, I3) -> INSERT INTO `T_MST_RPT_CAT` (`RPTC_CAT`,`RPTC_ACCN_TYPE`,`RPTC_ROLE_ID`,`RPTC_APPSID`,`RPTC_DESC`,`RPTC_DESC_OTH`,`RPTC_STATUS`,`RPTC_UID_CREATE`,`RPTC_DT_CREATE`,`RPTC_UID_LUPD`,`RPTC_DT_LUPD`) VALUES('OP_ADMIN','ACC_TYPE_CO','OP_ADMIN','CKT','Operations Report','','A','SYS',NOW(),'SYS',NOW());

Sheet T_CORE_RPT
A1: REPORT ID | B1: ACCOUNT TYPE | C1: APPSCODE | D1: REPORT CATEOGRY | E1: ROLE | F1: Name | G1: TITLE | H1: LANDSCAPE | I1: SHOW | J1: JSPR | K1: BORDER
A2: RPT_ALL_JOBS_TO | B2: ACC_TYPE_TO | C2: CKT | D2: OP_ADMIN | E2: OP_ADMIN | F2: All Jobs | G2: All Jobs | H2: Y | I2: Y | J2: N | K2: N | L2: =CONCATENATE("INSERT INTO `T_CORE_RPT`(`RPT_RPTID`,`RPT_ACCN_TYPE`,`RPT_APPSID`,`RPT_CAT`,`RPT_ROLE_ID`,`RPT_NAME`,`RPT_TITLE`,`RPT_LANDSCAPE`,`RPT_SHOW`,`RPT_JSPR`,`RPT_BORDER`,`RPT_DT_CRT`,`RPT_UID_CRT`,`RPT_DT_LUPD`,`RPT_UID_LUPD`)") -> INSERT INTO `T_CORE_RPT`(`RPT_RPTID`,`RPT_ACCN_TYPE`,`RPT_APPSID`,`RPT_CAT`,`RPT_ROLE_ID`,`RPT_NAME`,`RPT_TITLE`,`RPT_LANDSCAPE`,`RPT_SHOW`,`RPT_JSPR`,`RPT_BORDER`,`RPT_DT_CRT`,`RPT_UID_CRT`,`RPT_DT_LUPD`,`RPT_UID_LUPD`) | M2: =CONCATENATE(" VALUES('",A2,"','",B2,"','",C2,"','",D2,"','",E2,"','",F2,"','",G2,"','",H2,"','",I2,"','",J2,"','",K2,"',NOW(),'SYS',NOW(), 'SYS');") -> VALUES('RPT_ALL_JOBS_TO','ACC_TYPE_TO','CKT','OP_ADMIN','OP_ADMIN','All Jobs','All Jobs','Y','Y','N','N',NOW(),'SYS',NOW(), 'SYS'); | N2: =CONCATENATE(L2,M2) -> INSERT INTO `T_CORE_RPT`(`RPT_RPTID`,`RPT_ACCN_TYPE`,`RPT_APPSID`,`RPT_CAT`,`RPT_ROLE_ID`,`RPT_NAME`,`RPT_TITLE`,`RPT_LANDSCAPE`,`RPT_SHOW`,`RPT_JSPR`,`RPT_BORDER`,`RPT_DT_CRT`,`RPT_UID_CRT`,`RPT_DT_LUPD`,`RPT_UID_LUPD`) VALUES('RPT_ALL_JOBS_TO','ACC_TYPE_TO','CKT','OP_ADMIN','OP_ADMIN','All Jobs','All Jobs','Y','Y','N','N',NOW(),'SYS',NOW(), 'SYS');
A3: RPT_ALL_JOBS_CO | B3: ACC_TYPE_CO | C3: CKT | D3: OP_ADMIN | E3: OP_ADMIN | F3: All Jobs | G3: All Jobs | H3: Y | I3: Y | J3: N | K3: N | L3: =CONCATENATE("INSERT INTO `T_CORE_RPT`(`RPT_RPTID`,`RPT_ACCN_TYPE`,`RPT_APPSID`,`RPT_CAT`,`RPT_ROLE_ID`,`RPT_NAME`,`RPT_TITLE`,`RPT_LANDSCAPE`,`RPT_SHOW`,`RPT_JSPR`,`RPT_BORDER`,`RPT_DT_CRT`,`RPT_UID_CRT`,`RPT_DT_LUPD`,`RPT_UID_LUPD`)") -> INSERT INTO `T_CORE_RPT`(`RPT_RPTID`,`RPT_ACCN_TYPE`,`RPT_APPSID`,`RPT_CAT`,`RPT_ROLE_ID`,`RPT_NAME`,`RPT_TITLE`,`RPT_LANDSCAPE`,`RPT_SHOW`,`RPT_JSPR`,`RPT_BORDER`,`RPT_DT_CRT`,`RPT_UID_CRT`,`RPT_DT_LUPD`,`RPT_UID_LUPD`) | M3: =CONCATENATE(" VALUES('",A3,"','",B3,"','",C3,"','",D3,"','",E3,"','",F3,"','",G3,"','",H3,"','",I3,"','",J3,"','",K3,"',NOW(),'SYS',NOW(), 'SYS');") -> VALUES('RPT_ALL_JOBS_CO','ACC_TYPE_CO','CKT','OP_ADMIN','OP_ADMIN','All Jobs','All Jobs','Y','Y','N','N',NOW(),'SYS',NOW(), 'SYS'); | N3: =CONCATENATE(L3,M3) -> INSERT INTO `T_CORE_RPT`(`RPT_RPTID`,`RPT_ACCN_TYPE`,`RPT_APPSID`,`RPT_CAT`,`RPT_ROLE_ID`,`RPT_NAME`,`RPT_TITLE`,`RPT_LANDSCAPE`,`RPT_SHOW`,`RPT_JSPR`,`RPT_BORDER`,`RPT_DT_CRT`,`RPT_UID_CRT`,`RPT_DT_LUPD`,`RPT_UID_LUPD`) VALUES('RPT_ALL_JOBS_CO','ACC_TYPE_CO','CKT','OP_ADMIN','OP_ADMIN','All Jobs','All Jobs','Y','Y','N','N',NOW(),'SYS',NOW(), 'SYS');
A4: RPT_JOBS_DISCREPANCY_TO | B4: ACC_TYPE_TO | C4: CKT | D4: OP_ADMIN | E4: OP_ADMIN | F4: Jobs with Discripancies/Deviations | G4: Jobs with Discripancies/Deviations | H4: Y | I4: Y | J4: N | K4: N | L4: =CONCATENATE("INSERT INTO `T_CORE_RPT`(`RPT_RPTID`,`RPT_ACCN_TYPE`,`RPT_APPSID`,`RPT_CAT`,`RPT_ROLE_ID`,`RPT_NAME`,`RPT_TITLE`,`RPT_LANDSCAPE`,`RPT_SHOW`,`RPT_JSPR`,`RPT_BORDER`,`RPT_DT_CRT`,`RPT_UID_CRT`,`RPT_DT_LUPD`,`RPT_UID_LUPD`)") -> INSERT INTO `T_CORE_RPT`(`RPT_RPTID`,`RPT_ACCN_TYPE`,`RPT_APPSID`,`RPT_CAT`,`RPT_ROLE_ID`,`RPT_NAME`,`RPT_TITLE`,`RPT_LANDSCAPE`,`RPT_SHOW`,`RPT_JSPR`,`RPT_BORDER`,`RPT_DT_CRT`,`RPT_UID_CRT`,`RPT_DT_LUPD`,`RPT_UID_LUPD`) | M4: =CONCATENATE(" VALUES('",A4,"','",B4,"','",C4,"','",D4,"','",E4,"','",F4,"','",G4,"','",H4,"','",I4,"','",J4,"','",K4,"',NOW(),'SYS',NOW(), 'SYS');") -> VALUES('RPT_JOBS_DISCREPANCY_TO','ACC_TYPE_TO','CKT','OP_ADMIN','OP_ADMIN','Jobs with Discripancies/Deviations','Jobs with Discripancies/Deviations','Y','Y','N','N',NOW(),'SYS',NOW(), 'SYS'); | N4: =CONCATENATE(L4,M4) -> INSERT INTO `T_CORE_RPT`(`RPT_RPTID`,`RPT_ACCN_TYPE`,`RPT_APPSID`,`RPT_CAT`,`RPT_ROLE_ID`,`RPT_NAME`,`RPT_TITLE`,`RPT_LANDSCAPE`,`RPT_SHOW`,`RPT_JSPR`,`RPT_BORDER`,`RPT_DT_CRT`,`RPT_UID_CRT`,`RPT_DT_LUPD`,`RPT_UID_LUPD`) VALUES('RPT_JOBS_DISCREPANCY_TO','ACC_TYPE_TO','CKT','OP_ADMIN','OP_ADMIN','Jobs with Discripancies/Deviations','Jobs with Discripancies/Deviations','Y','Y','N','N',NOW(),'SYS',NOW(), 'SYS');
A5: RPT_JOBS_DISCREPANCY_CO | B5: ACC_TYPE_CO | C5: CKT | D5: OP_ADMIN | E5: OP_ADMIN | F5: Jobs with Discripancies/Deviations | G5: Jobs with Discripancies/Deviations | H5: Y | I5: Y | J5: N | K5: N | L5: =CONCATENATE("INSERT INTO `T_CORE_RPT`(`RPT_RPTID`,`RPT_ACCN_TYPE`,`RPT_APPSID`,`RPT_CAT`,`RPT_ROLE_ID`,`RPT_NAME`,`RPT_TITLE`,`RPT_LANDSCAPE`,`RPT_SHOW`,`RPT_JSPR`,`RPT_BORDER`,`RPT_DT_CRT`,`RPT_UID_CRT`,`RPT_DT_LUPD`,`RPT_UID_LUPD`)") -> INSERT INTO `T_CORE_RPT`(`RPT_RPTID`,`RPT_ACCN_TYPE`,`RPT_APPSID`,`RPT_CAT`,`RPT_ROLE_ID`,`RPT_NAME`,`RPT_TITLE`,`RPT_LANDSCAPE`,`RPT_SHOW`,`RPT_JSPR`,`RPT_BORDER`,`RPT_DT_CRT`,`RPT_UID_CRT`,`RPT_DT_LUPD`,`RPT_UID_LUPD`) | M5: =CONCATENATE(" VALUES('",A5,"','",B5,"','",C5,"','",D5,"','",E5,"','",F5,"','",G5,"','",H5,"','",I5,"','",J5,"','",K5,"',NOW(),'SYS',NOW(), 'SYS');") -> VALUES('RPT_JOBS_DISCREPANCY_CO','ACC_TYPE_CO','CKT','OP_ADMIN','OP_ADMIN','Jobs with Discripancies/Deviations','Jobs with Discripancies/Deviations','Y','Y','N','N',NOW(),'SYS',NOW(), 'SYS'); | N5: =CONCATENATE(L5,M5) -> INSERT INTO `T_CORE_RPT`(`RPT_RPTID`,`RPT_ACCN_TYPE`,`RPT_APPSID`,`RPT_CAT`,`RPT_ROLE_ID`,`RPT_NAME`,`RPT_TITLE`,`RPT_LANDSCAPE`,`RPT_SHOW`,`RPT_JSPR`,`RPT_BORDER`,`RPT_DT_CRT`,`RPT_UID_CRT`,`RPT_DT_LUPD`,`RPT_UID_LUPD`) VALUES('RPT_JOBS_DISCREPANCY_CO','ACC_TYPE_CO','CKT','OP_ADMIN','OP_ADMIN','Jobs with Discripancies/Deviations','Jobs with Discripancies/Deviations','Y','Y','N','N',NOW(),'SYS',NOW(), 'SYS');

Sheet T_CORE_RPT_ACL
A1: REPORT ID | B1: ACCN TYPE | C1: ROLE | D1: APPSCODE | E1: ACCNID
A2: RPT_ALL_JOBS_TO | B2: ACC_TYPE_TO | C2: OP_ADMIN | D2: CKT | E2: BERAM | F2: =CONCATENATE("INSERT INTO `T_CORE_RPT_ACL`(`RPTA_RPTID`,`RPTA_ACCN_TYPE`,`RPTA_ROLEID`,`RPTA_APPSID`,`RPTA_ACCNID`) VALUES('",A2,"','",B2,"','",C2,"','",D2,"','",E2,"');") -> INSERT INTO `T_CORE_RPT_ACL`(`RPTA_RPTID`,`RPTA_ACCN_TYPE`,`RPTA_ROLEID`,`RPTA_APPSID`,`RPTA_ACCNID`) VALUES('RPT_ALL_JOBS_TO','ACC_TYPE_TO','OP_ADMIN','CKT','BERAM');
A3: RPT_ALL_JOBS_CO | B3: ACC_TYPE_CO | C3: OP_ADMIN | D3: CKT | E3: ALKNAR | F3: =CONCATENATE("INSERT INTO `T_CORE_RPT_ACL`(`RPTA_RPTID`,`RPTA_ACCN_TYPE`,`RPTA_ROLEID`,`RPTA_APPSID`,`RPTA_ACCNID`) VALUES('",A3,"','",B3,"','",C3,"','",D3,"','",E3,"');") -> INSERT INTO `T_CORE_RPT_ACL`(`RPTA_RPTID`,`RPTA_ACCN_TYPE`,`RPTA_ROLEID`,`RPTA_APPSID`,`RPTA_ACCNID`) VALUES('RPT_ALL_JOBS_CO','ACC_TYPE_CO','OP_ADMIN','CKT','ALKNAR');
A4: RPT_JOBS_DISCREPANCY_TO | B4: ACC_TYPE_TO | C4: OP_ADMIN | D4: CKT | E4: FEDEX | F4: =CONCATENATE("INSERT INTO `T_CORE_RPT_ACL`(`RPTA_RPTID`,`RPTA_ACCN_TYPE`,`RPTA_ROLEID`,`RPTA_APPSID`,`RPTA_ACCNID`) VALUES('",A4,"','",B4,"','",C4,"','",D4,"','",E4,"');") -> INSERT INTO `T_CORE_RPT_ACL`(`RPTA_RPTID`,`RPTA_ACCN_TYPE`,`RPTA_ROLEID`,`RPTA_APPSID`,`RPTA_ACCNID`) VALUES('RPT_JOBS_DISCREPANCY_TO','ACC_TYPE_TO','OP_ADMIN','CKT','FEDEX');
A5: RPT_JOBS_DISCREPANCY_CO | B5: ACC_TYPE_CO | C5: OP_ADMIN | D5: CKT | E5: ALKNAR | F5: =CONCATENATE("INSERT INTO `T_CORE_RPT_ACL`(`RPTA_RPTID`,`RPTA_ACCN_TYPE`,`RPTA_ROLEID`,`RPTA_APPSID`,`RPTA_ACCNID`) VALUES('",A5,"','",B5,"','",C5,"','",D5,"','",E5,"');") -> INSERT INTO `T_CORE_RPT_ACL`(`RPTA_RPTID`,`RPTA_ACCN_TYPE`,`RPTA_ROLEID`,`RPTA_APPSID`,`RPTA_ACCNID`) VALUES('RPT_JOBS_DISCREPANCY_CO','ACC_TYPE_CO','OP_ADMIN','CKT','ALKNAR');

Sheet T_CORE_RPT_FILTER
A1: REPORT ID | B1: ACCN TYPE | C1: INDEX | D1: FILTER NAME | E1: FILTER TYPE | F1: CAPTION LABEL | G1: BASIC ROW | H1: LIST BOX TBL | I1: LISTBOX OPTION ID | J1: LISTBOX NAME OPTION | K1: SHOW | L1: DEFVALUE | M1: IFNULLVAL | N1: MANDATORY
A2: RPT_ALL_JOBS_TO | B2: ACC_TYPE_TO | C2: 0 | D2: JOB_STATE | E2: L | F2: Job State | G2: 1 | H2: LIST | I2: ALL,SUB,CAN,DLV,ACP,ONGOING | J2: ALL,SUBMITTED,CANCELLED,DELIVERED,ACCEPTED,ONGOING | K2: Y | L2: SUB | M2: SUB | N2: N | O2: =CONCATENATE("INSERT INTO `T_CORE_RPT_FILTER`(`RPTF_ID`,`RPTF_ACCN_TYPE`,`RPTF_IDX`,`RPTF_NAME`,`RPTF_FILTYPE`,`RPTF_CAPTION`,`RPTF_BASIC_ROW`,`RPTF_LISTBOX_TBL`,`RPTF_LISTBOX_IDCOL`,`RPTF_LISTBOX_CAPCOL`,`RPTF_SHOW`,`RPTF_DEFVAL`,`RPTF_IFNULLVAL`,`RPTF_MANDATORY`)") -> INSERT INTO `T_CORE_RPT_FILTER`(`RPTF_ID`,`RPTF_ACCN_TYPE`,`RPTF_IDX`,`RPTF_NAME`,`RPTF_FILTYPE`,`RPTF_CAPTION`,`RPTF_BASIC_ROW`,`RPTF_LISTBOX_TBL`,`RPTF_LISTBOX_IDCOL`,`RPTF_LISTBOX_CAPCOL`,`RPTF_SHOW`,`RPTF_DEFVAL`,`RPTF_IFNULLVAL`,`RPTF_MANDATORY`) | P2: =CONCATENATE(" VALUES('",A2,"','",B2,"','",C2,"','",D2,"','",E2,"','",F2,"','",G2,"',",IF(H2="NULL","NULL",CONCATENATE("'",H2,"'")),",",IF(I2="NULL","NULL",CONCATENATE("'",I2,"'")),",",IF(J2="NULL","NULL",CONCATENATE("'",J2,"'")),",'",K2,"',",IF(L2="NULL","NULL",CONCATENATE("'",L2,"'")),",",IF(M2="NULL","NULL",CONCATENATE("'",M2,"'")),",'",N2,"');") -> VALUES('RPT_ALL_JOBS_TO','ACC_TYPE_TO','0','JOB_STATE','L','Job State','1','LIST','ALL,SUB,CAN,DLV,ACP,ONGOING','ALL,SUBMITTED,CANCELLED,DELIVERED,ACCEPTED,ONGOING','Y','SUB','SUB','N'); | R2: =CONCATENATE(O2,P2) -> INSERT INTO `T_CORE_RPT_FILTER`(`RPTF_ID`,`RPTF_ACCN_TYPE`,`RPTF_IDX`,`RPTF_NAME`,`RPTF_FILTYPE`,`RPTF_CAPTION`,`RPTF_BASIC_ROW`,`RPTF_LISTBOX_TBL`,`RPTF_LISTBOX_IDCOL`,`RPTF_LISTBOX_CAPCOL`,`RPTF_SHOW`,`RPTF_DEFVAL`,`RPTF_IFNULLVAL`,`RPTF_MANDATORY`) VALUES('RPT_ALL_JOBS_TO','ACC_TYPE_TO','0','JOB_STATE','L','Job State','1','LIST','ALL,SUB,CAN,DLV,ACP,ONGOING','ALL,SUBMITTED,CANCELLED,DELIVERED,ACCEPTED,ONGOING','Y','SUB','SUB','N');
A3: RPT_ALL_JOBS_TO | B3: ACC_TYPE_TO | C3: 1 | D3: JOB_PROCESS_VIA | E3: L | F3: Process Via | G3: 2 | H3: LIST | I3: ALL,MOBILE,WEB | J3: ALL,MOBILE,WEB | K3: Y | L3: NULL | M3: NULL | N3: N | O3: =CONCATENATE("INSERT INTO `T_CORE_RPT_FILTER`(`RPTF_ID`,`RPTF_ACCN_TYPE`,`RPTF_IDX`,`RPTF_NAME`,`RPTF_FILTYPE`,`RPTF_CAPTION`,`RPTF_BASIC_ROW`,`RPTF_LISTBOX_TBL`,`RPTF_LISTBOX_IDCOL`,`RPTF_LISTBOX_CAPCOL`,`RPTF_SHOW`,`RPTF_DEFVAL`,`RPTF_IFNULLVAL`,`RPTF_MANDATORY`)") -> INSERT INTO `T_CORE_RPT_FILTER`(`RPTF_ID`,`RPTF_ACCN_TYPE`,`RPTF_IDX`,`RPTF_NAME`,`RPTF_FILTYPE`,`RPTF_CAPTION`,`RPTF_BASIC_ROW`,`RPTF_LISTBOX_TBL`,`RPTF_LISTBOX_IDCOL`,`RPTF_LISTBOX_CAPCOL`,`RPTF_SHOW`,`RPTF_DEFVAL`,`RPTF_IFNULLVAL`,`RPTF_MANDATORY`) | P3: =CONCATENATE(" VALUES('",A3,"','",B3,"','",C3,"','",D3,"','",E3,"','",F3,"','",G3,"',",IF(H3="NULL","NULL",CONCATENATE("'",H3,"'")),",",IF(I3="NULL","NULL",CONCATENATE("'",I3,"'")),",",IF(J3="NULL","NULL",CONCATENATE("'",J3,"'")),",'",K3,"',",IF(L3="NULL","NULL",CONCATENATE("'",L3,"'")),",",IF(M3="NULL","NULL",CONCATENATE("'",M3,"'")),",'",N3,"');") -> VALUES('RPT_ALL_JOBS_TO','ACC_TYPE_TO','1','JOB_PROCESS_VIA','L','Process Via','2','LIST','ALL,MOBILE,WEB','ALL,MOBILE,WEB','Y',NULL,NULL,'N'); | R3: =CONCATENATE(O3,P3) -> INSERT INTO `T_CORE_RPT_FILTER`(`RPTF_ID`,`RPTF_ACCN_TYPE`,`RPTF_IDX`,`RPTF_NAME`,`RPTF_FILTYPE`,`RPTF_CAPTION`,`RPTF_BASIC_ROW`,`RPTF_LISTBOX_TBL`,`RPTF_LISTBOX_IDCOL`,`RPTF_LISTBOX_CAPCOL`,`RPTF_SHOW`,`RPTF_DEFVAL`,`RPTF_IFNULLVAL`,`RPTF_MANDATORY`) VALUES('RPT_ALL_JOBS_TO','ACC_TYPE_TO','1','JOB_PROCESS_VIA','L','Process Via','2','LIST','ALL,MOBILE,WEB','ALL,MOBILE,WEB','Y',NULL,NULL,'N');
A4: RPT_ALL_JOBS_TO | B4: ACC_TYPE_TO | C4: 2 | D4: RCD_DT_CANCEL | E4: R | F4: Date Cancelled | G4: 3 | H4: NULL | I4: NULL | J4: NULL | K4: Y | L4: NULL | M4: NULL | N4: N | O4: =CONCATENATE("INSERT INTO `T_CORE_RPT_FILTER`(`RPTF_ID`,`RPTF_ACCN_TYPE`,`RPTF_IDX`,`RPTF_NAME`,`RPTF_FILTYPE`,`RPTF_CAPTION`,`RPTF_BASIC_ROW`,`RPTF_LISTBOX_TBL`,`RPTF_LISTBOX_IDCOL`,`RPTF_LISTBOX_CAPCOL`,`RPTF_SHOW`,`RPTF_DEFVAL`,`RPTF_IFNULLVAL`,`RPTF_MANDATORY`)") -> INSERT INTO `T_CORE_RPT_FILTER`(`RPTF_ID`,`RPTF_ACCN_TYPE`,`RPTF_IDX`,`RPTF_NAME`,`RPTF_FILTYPE`,`RPTF_CAPTION`,`RPTF_BASIC_ROW`,`RPTF_LISTBOX_TBL`,`RPTF_LISTBOX_IDCOL`,`RPTF_LISTBOX_CAPCOL`,`RPTF_SHOW`,`RPTF_DEFVAL`,`RPTF_IFNULLVAL`,`RPTF_MANDATORY`) | P4: =CONCATENATE(" VALUES('",A4,"','",B4,"','",C4,"','",D4,"','",E4,"','",F4,"','",G4,"',",IF(H4="NULL","NULL",CONCATENATE("'",H4,"'")),",",IF(I4="NULL","NULL",CONCATENATE("'",I4,"'")),",",IF(J4="NULL","NULL",CONCATENATE("'",J4,"'")),",'",K4,"',",IF(L4="NULL","NULL",CONCATENATE("'",L4,"'")),",",IF(M4="NULL","NULL",CONCATENATE("'",M4,"'")),",'",N4,"');") -> VALUES('RPT_ALL_JOBS_TO','ACC_TYPE_TO','2','RCD_DT_CANCEL','R','Date Cancelled','3',NULL,NULL,NULL,'Y',NULL,NULL,'N'); | R4: =CONCATENATE(O4,P4) -> INSERT INTO `T_CORE_RPT_FILTER`(`RPTF_ID`,`RPTF_ACCN_TYPE`,`RPTF_IDX`,`RPTF_NAME`,`RPTF_FILTYPE`,`RPTF_CAPTION`,`RPTF_BASIC_ROW`,`RPTF_LISTBOX_TBL`,`RPTF_LISTBOX_IDCOL`,`RPTF_LISTBOX_CAPCOL`,`RPTF_SHOW`,`RPTF_DEFVAL`,`RPTF_IFNULLVAL`,`RPTF_MANDATORY`) VALUES('RPT_ALL_JOBS_TO','ACC_TYPE_TO','2','RCD_DT_CANCEL','R','Date Cancelled','3',NULL,NULL,NULL,'Y',NULL,NULL,'N');
A5: RPT_ALL_JOBS_TO | B5: ACC_TYPE_TO | C5: 3 | D5: RCD_DT_COMPLETE | E5: R | F5: Date Completed | G5: 4 | H5: NULL | I5: NULL | J5: NULL | K5: Y | L5: NULL | M5: NULL | N5: N | O5: =CONCATENATE("INSERT INTO `T_CORE_RPT_FILTER`(`RPTF_ID`,`RPTF_ACCN_TYPE`,`RPTF_IDX`,`RPTF_NAME`,`RPTF_FILTYPE`,`RPTF_CAPTION`,`RPTF_BASIC_ROW`,`RPTF_LISTBOX_TBL`,`RPTF_LISTBOX_IDCOL`,`RPTF_LISTBOX_CAPCOL`,`RPTF_SHOW`,`RPTF_DEFVAL`,`RPTF_IFNULLVAL`,`RPTF_MANDATORY`)") -> INSERT INTO `T_CORE_RPT_FILTER`(`RPTF_ID`,`RPTF_ACCN_TYPE`,`RPTF_IDX`,`RPTF_NAME`,`RPTF_FILTYPE`,`RPTF_CAPTION`,`RPTF_BASIC_ROW`,`RPTF_LISTBOX_TBL`,`RPTF_LISTBOX_IDCOL`,`RPTF_LISTBOX_CAPCOL`,`RPTF_SHOW`,`RPTF_DEFVAL`,`RPTF_IFNULLVAL`,`RPTF_MANDATORY`) | P5: =CONCATENATE(" VALUES('",A5,"','",B5,"','",C5,"','",D5,"','",E5,"','",F5,"','",G5,"',",IF(H5="NULL","NULL",CONCATENATE("'",H5,"'")),",",IF(I5="NULL","NULL",CONCATENATE("'",I5,"'")),",",IF(J5="NULL","NULL",CONCATENATE("'",J5,"'")),",'",K5,"',",IF(L5="NULL","NULL",CONCATENATE("'",L5,"'")),",",IF(M5="NULL","NULL",CONCATENATE("'",M5,"'")),",'",N5,"');") -> VALUES('RPT_ALL_JOBS_TO','ACC_TYPE_TO','3','RCD_DT_COMPLETE','R','Date Completed','4',NULL,NULL,NULL,'Y',NULL,NULL,'N'); | R5: =CONCATENATE(O5,P5) -> INSERT INTO `T_CORE_RPT_FILTER`(`RPTF_ID`,`RPTF_ACCN_TYPE`,`RPTF_IDX`,`RPTF_NAME`,`RPTF_FILTYPE`,`RPTF_CAPTION`,`RPTF_BASIC_ROW`,`RPTF_LISTBOX_TBL`,`RPTF_LISTBOX_IDCOL`,`RPTF_LISTBOX_CAPCOL`,`RPTF_SHOW`,`RPTF_DEFVAL`,`RPTF_IFNULLVAL`,`RPTF_MANDATORY`) VALUES('RPT_ALL_JOBS_TO','ACC_TYPE_TO','3','RCD_DT_COMPLETE','R','Date Completed','4',NULL,NULL,NULL,'Y',NULL,NULL,'N');
A6: RPT_ALL_JOBS_TO | B6: ACC_TYPE_TO | C6: 4 | D6: RCD_DT_ACCEPTED | E6: R | F6: Date Accepted | G6: 5 | H6: NULL | I6: NULL | J6: NULL | K6: Y | N6: N | O6: =CONCATENATE("INSERT INTO `T_CORE_RPT_FILTER`(`RPTF_ID`,`RPTF_ACCN_TYPE`,`RPTF_IDX`,`RPTF_NAME`,`RPTF_FILTYPE`,`RPTF_CAPTION`,`RPTF_BASIC_ROW`,`RPTF_LISTBOX_TBL`,`RPTF_LISTBOX_IDCOL`,`RPTF_LISTBOX_CAPCOL`,`RPTF_SHOW`,`RPTF_DEFVAL`,`RPTF_IFNULLVAL`,`RPTF_MANDATORY`)") -> INSERT INTO `T_CORE_RPT_FILTER`(`RPTF_ID`,`RPTF_ACCN_TYPE`,`RPTF_IDX`,`RPTF_NAME`,`RPTF_FILTYPE`,`RPTF_CAPTION`,`RPTF_BASIC_ROW`,`RPTF_LISTBOX_TBL`,`RPTF_LISTBOX_IDCOL`,`RPTF_LISTBOX_CAPCOL`,`RPTF_SHOW`,`RPTF_DEFVAL`,`RPTF_IFNULLVAL`,`RPTF_MANDATORY`) | P6: =CONCATENATE(" VALUES('",A6,"','",B6,"','",C6,"','",D6,"','",E6,"','",F6,"','",G6,"',",IF(H6="NULL","NULL",CONCATENATE("'",H6,"'")),",",IF(I6="NULL","NULL",CONCATENATE("'",I6,"'")),",",IF(J6="NULL","NULL",CONCATENATE("'",J6,"'")),",'",K6,"',",IF(L6="NULL","NULL",CONCATENATE("'",L6,"'")),",",IF(M6="NULL","NULL",CONCATENATE("'",M6,"'")),",'",N6,"');") -> VALUES('RPT_ALL_JOBS_TO','ACC_TYPE_TO','4','RCD_DT_ACCEPTED','R','Date Accepted','5',NULL,NULL,NULL,'Y','','','N'); | R6: =CONCATENATE(O6,P6) -> INSERT INTO `T_CORE_RPT_FILTER`(`RPTF_ID`,`RPTF_ACCN_TYPE`,`RPTF_IDX`,`RPTF_NAME`,`RPTF_FILTYPE`,`RPTF_CAPTION`,`RPTF_BASIC_ROW`,`RPTF_LISTBOX_TBL`,`RPTF_LISTBOX_IDCOL`,`RPTF_LISTBOX_CAPCOL`,`RPTF_SHOW`,`RPTF_DEFVAL`,`RPTF_IFNULLVAL`,`RPTF_MANDATORY`) VALUES('RPT_ALL_JOBS_TO','ACC_TYPE_TO','4','RCD_DT_ACCEPTED','R','Date Accepted','5',NULL,NULL,NULL,'Y','','','N');
A7: RPT_ALL_JOBS_TO | B7: ACC_TYPE_TO | C7: 5 | D7: RCD_DT_START | E7: R | F7: Date Started | G7: 6 | H7: NULL | I7: NULL | J7: NULL | K7: Y | L7: NULL | M7: NULL | N7: N | O7: =CONCATENATE("INSERT INTO `T_CORE_RPT_FILTER`(`RPTF_ID`,`RPTF_ACCN_TYPE`,`RPTF_IDX`,`RPTF_NAME`,`RPTF_FILTYPE`,`RPTF_CAPTION`,`RPTF_BASIC_ROW`,`RPTF_LISTBOX_TBL`,`RPTF_LISTBOX_IDCOL`,`RPTF_LISTBOX_CAPCOL`,`RPTF_SHOW`,`RPTF_DEFVAL`,`RPTF_IFNULLVAL`,`RPTF_MANDATORY`)") -> INSERT INTO `T_CORE_RPT_FILTER`(`RPTF_ID`,`RPTF_ACCN_TYPE`,`RPTF_IDX`,`RPTF_NAME`,`RPTF_FILTYPE`,`RPTF_CAPTION`,`RPTF_BASIC_ROW`,`RPTF_LISTBOX_TBL`,`RPTF_LISTBOX_IDCOL`,`RPTF_LISTBOX_CAPCOL`,`RPTF_SHOW`,`RPTF_DEFVAL`,`RPTF_IFNULLVAL`,`RPTF_MANDATORY`) | P7: =CONCATENATE(" VALUES('",A7,"','",B7,"','",C7,"','",D7,"','",E7,"','",F7,"','",G7,"',",IF(H7="NULL","NULL",CONCATENATE("'",H7,"'")),",",IF(I7="NULL","NULL",CONCATENATE("'",I7,"'")),",",IF(J7="NULL","NULL",CONCATENATE("'",J7,"'")),",'",K7,"',",IF(L7="NULL","NULL",CONCATENATE("'",L7,"'")),",",IF(M7="NULL","NULL",CONCATENATE("'",M7,"'")),",'",N7,"');") -> VALUES('RPT_ALL_JOBS_TO','ACC_TYPE_TO','5','RCD_DT_START','R','Date Started','6',NULL,NULL,NULL,'Y',NULL,NULL,'N'); | R7: =CONCATENATE(O7,P7) -> INSERT INTO `T_CORE_RPT_FILTER`(`RPTF_ID`,`RPTF_ACCN_TYPE`,`RPTF_IDX`,`RPTF_NAME`,`RPTF_FILTYPE`,`RPTF_CAPTION`,`RPTF_BASIC_ROW`,`RPTF_LISTBOX_TBL`,`RPTF_LISTBOX_IDCOL`,`RPTF_LISTBOX_CAPCOL`,`RPTF_SHOW`,`RPTF_DEFVAL`,`RPTF_IFNULLVAL`,`RPTF_MANDATORY`) VALUES('RPT_ALL_JOBS_TO','ACC_TYPE_TO','5','RCD_DT_START','R','Date Started','6',NULL,NULL,NULL,'Y',NULL,NULL,'N');
O8: =CONCATENATE("INSERT INTO `T_CORE_RPT_FILTER`(`RPTF_ID`,`RPTF_ACCN_TYPE`,`RPTF_IDX`,`RPTF_NAME`,`RPTF_FILTYPE`,`RPTF_CAPTION`,`RPTF_BASIC_ROW`,`RPTF_LISTBOX_TBL`,`RPTF_LISTBOX_IDCOL`,`RPTF_LISTBOX_CAPCOL`,`RPTF_SHOW`,`RPTF_DEFVAL`,`RPTF_IFNULLVAL`,`RPTF_MANDATORY`)") -> INSERT INTO `T_CORE_RPT_FILTER`(`RPTF_ID`,`RPTF_ACCN_TYPE`,`RPTF_IDX`,`RPTF_NAME`,`RPTF_FILTYPE`,`RPTF_CAPTION`,`RPTF_BASIC_ROW`,`RPTF_LISTBOX_TBL`,`RPTF_LISTBOX_IDCOL`,`RPTF_LISTBOX_CAPCOL`,`RPTF_SHOW`,`RPTF_DEFVAL`,`RPTF_IFNULLVAL`,`RPTF_MANDATORY`) | P8: =CONCATENATE(" VALUES('",A8,"','",B8,"','",C8,"','",D8,"','",E8,"','",F8,"','",G8,"',",IF(H8="NULL","NULL",CONCATENATE("'",H8,"'")),",",IF(I8="NULL","NULL",CONCATENATE("'",I8,"'")),",",IF(J8="NULL","NULL",CONCATENATE("'",J8,"'")),",'",K8,"',",IF(L8="NULL","NULL",CONCATENATE("'",L8,"'")),",",IF(M8="NULL","NULL",CONCATENATE("'",M8,"'")),",'",N8,"');") -> VALUES('','','','','','','','','','','','','',''); | R8: =CONCATENATE(O8,P8) -> INSERT INTO `T_CORE_RPT_FILTER`(`RPTF_ID`,`RPTF_ACCN_TYPE`,`RPTF_IDX`,`RPTF_NAME`,`RPTF_FILTYPE`,`RPTF_CAPTION`,`RPTF_BASIC_ROW`,`RPTF_LISTBOX_TBL`,`RPTF_LISTBOX_IDCOL`,`RPTF_LISTBOX_CAPCOL`,`RPTF_SHOW`,`RPTF_DEFVAL`,`RPTF_IFNULLVAL`,`RPTF_MANDATORY`) VALUES('','','','','','','','','','','','','','');
A9: RPT_ALL_JOBS_TO | B9: ACC_TYPE_TO | C9: 6 | D9: RCD_DT_SUBMIT | E9: R | F9: Date Submitted | G9: 7 | H9: NULL | I9: NULL | J9: NULL | K9: Y | L9: NULL | M9: NULL | N9: N | O9: =CONCATENATE("INSERT INTO `T_CORE_RPT_FILTER`(`RPTF_ID`,`RPTF_ACCN_TYPE`,`RPTF_IDX`,`RPTF_NAME`,`RPTF_FILTYPE`,`RPTF_CAPTION`,`RPTF_BASIC_ROW`,`RPTF_LISTBOX_TBL`,`RPTF_LISTBOX_IDCOL`,`RPTF_LISTBOX_CAPCOL`,`RPTF_SHOW`,`RPTF_DEFVAL`,`RPTF_IFNULLVAL`,`RPTF_MANDATORY`)") -> INSERT INTO `T_CORE_RPT_FILTER`(`RPTF_ID`,`RPTF_ACCN_TYPE`,`RPTF_IDX`,`RPTF_NAME`,`RPTF_FILTYPE`,`RPTF_CAPTION`,`RPTF_BASIC_ROW`,`RPTF_LISTBOX_TBL`,`RPTF_LISTBOX_IDCOL`,`RPTF_LISTBOX_CAPCOL`,`RPTF_SHOW`,`RPTF_DEFVAL`,`RPTF_IFNULLVAL`,`RPTF_MANDATORY`) | P9: =CONCATENATE(" VALUES('",A9,"','",B9,"','",C9,"','",D9,"','",E9,"','",F9,"','",G9,"',",IF(H9="NULL","NULL",CONCATENATE("'",H9,"'")),",",IF(I9="NULL","NULL",CONCATENATE("'",I9,"'")),",",IF(J9="NULL","NULL",CONCATENATE("'",J9,"'")),",'",K9,"',",IF(L9="NULL","NULL",CONCATENATE("'",L9,"'")),",",IF(M9="NULL","NULL",CONCATENATE("'",M9,"'")),",'",N9,"');") -> VALUES('RPT_ALL_JOBS_TO','ACC_TYPE_TO','6','RCD_DT_SUBMIT','R','Date Submitted','7',NULL,NULL,NULL,'Y',NULL,NULL,'N'); | R9: =CONCATENATE(O9,P9) -> INSERT INTO `T_CORE_RPT_FILTER`(`RPTF_ID`,`RPTF_ACCN_TYPE`,`RPTF_IDX`,`RPTF_NAME`,`RPTF_FILTYPE`,`RPTF_CAPTION`,`RPTF_BASIC_ROW`,`RPTF_LISTBOX_TBL`,`RPTF_LISTBOX_IDCOL`,`RPTF_LISTBOX_CAPCOL`,`RPTF_SHOW`,`RPTF_DEFVAL`,`RPTF_IFNULLVAL`,`RPTF_MANDATORY`) VALUES('RPT_ALL_JOBS_TO','ACC_TYPE_TO','6','RCD_DT_SUBMIT','R','Date Submitted','7',NULL,NULL,NULL,'Y',NULL,NULL,'N');
A10: RPT_ALL_JOBS_CO | B10: ACC_TYPE_CO | C10: 0 | D10: JOB_STATE | E10: L | F10: Job State | G10: 1 | H10: LIST | I10: ALL,CAN,DLV,ACP,ONGOING | J10: ALL,CANCELLED,DELIVERED,ACCEPTED,ONGOING | K10: Y | L10: NULL | M10: NULL | N10: N | O10: =CONCATENATE("INSERT INTO `T_CORE_RPT_FILTER`(`RPTF_ID`,`RPTF_ACCN_TYPE`,`RPTF_IDX`,`RPTF_NAME`,`RPTF_FILTYPE`,`RPTF_CAPTION`,`RPTF_BASIC_ROW`,`RPTF_LISTBOX_TBL`,`RPTF_LISTBOX_IDCOL`,`RPTF_LISTBOX_CAPCOL`,`RPTF_SHOW`,`RPTF_DEFVAL`,`RPTF_IFNULLVAL`,`RPTF_MANDATORY`)") -> INSERT INTO `T_CORE_RPT_FILTER`(`RPTF_ID`,`RPTF_ACCN_TYPE`,`RPTF_IDX`,`RPTF_NAME`,`RPTF_FILTYPE`,`RPTF_CAPTION`,`RPTF_BASIC_ROW`,`RPTF_LISTBOX_TBL`,`RPTF_LISTBOX_IDCOL`,`RPTF_LISTBOX_CAPCOL`,`RPTF_SHOW`,`RPTF_DEFVAL`,`RPTF_IFNULLVAL`,`RPTF_MANDATORY`) | P10: =CONCATENATE(" VALUES('",A10,"','",B10,"','",C10,"','",D10,"','",E10,"','",F10,"','",G10,"',",IF(H10="NULL","NULL",CONCATENATE("'",H10,"'")),",",IF(I10="NULL","NULL",CONCATENATE("'",I10,"'")),",",IF(J10="NULL","NULL",CONCATENATE("'",J10,"'")),",'",K10,"',",IF(L10="NULL","NULL",CONCATENATE("'",L10,"'")),",",IF(M10="NULL","NULL",CONCATENATE("'",M10,"'")),",'",N10,"');") -> VALUES('RPT_ALL_JOBS_CO','ACC_TYPE_CO','0','JOB_STATE','L','Job State','1','LIST','ALL,CAN,DLV,ACP,ONGOING','ALL,CANCELLED,DELIVERED,ACCEPTED,ONGOING','Y',NULL,NULL,'N'); | R10: =CONCATENATE(O10,P10) -> INSERT INTO `T_CORE_RPT_FILTER`(`RPTF_ID`,`RPTF_ACCN_TYPE`,`RPTF_IDX`,`RPTF_NAME`,`RPTF_FILTYPE`,`RPTF_CAPTION`,`RPTF_BASIC_ROW`,`RPTF_LISTBOX_TBL`,`RPTF_LISTBOX_IDCOL`,`RPTF_LISTBOX_CAPCOL`,`RPTF_SHOW`,`RPTF_DEFVAL`,`RPTF_IFNULLVAL`,`RPTF_MANDATORY`) VALUES('RPT_ALL_JOBS_CO','ACC_TYPE_CO','0','JOB_STATE','L','Job State','1','LIST','ALL,CAN,DLV,ACP,ONGOING','ALL,CANCELLED,DELIVERED,ACCEPTED,ONGOING','Y',NULL,NULL,'N');
A11: RPT_ALL_JOBS_CO | B11: ACC_TYPE_CO | C11: 1 | D11: JOB_PROCESS_VIA | E11: L | F11: Process Via | G11: 2 | H11: LIST | I11: ALL,MOBILE,WEB | J11: ALL,MOBILE,WEB | K11: Y | L11: NULL | M11: NULL | N11: N | O11: =CONCATENATE("INSERT INTO `T_CORE_RPT_FILTER`(`RPTF_ID`,`RPTF_ACCN_TYPE`,`RPTF_IDX`,`RPTF_NAME`,`RPTF_FILTYPE`,`RPTF_CAPTION`,`RPTF_BASIC_ROW`,`RPTF_LISTBOX_TBL`,`RPTF_LISTBOX_IDCOL`,`RPTF_LISTBOX_CAPCOL`,`RPTF_SHOW`,`RPTF_DEFVAL`,`RPTF_IFNULLVAL`,`RPTF_MANDATORY`)") -> INSERT INTO `T_CORE_RPT_FILTER`(`RPTF_ID`,`RPTF_ACCN_TYPE`,`RPTF_IDX`,`RPTF_NAME`,`RPTF_FILTYPE`,`RPTF_CAPTION`,`RPTF_BASIC_ROW`,`RPTF_LISTBOX_TBL`,`RPTF_LISTBOX_IDCOL`,`RPTF_LISTBOX_CAPCOL`,`RPTF_SHOW`,`RPTF_DEFVAL`,`RPTF_IFNULLVAL`,`RPTF_MANDATORY`) | P11: =CONCATENATE(" VALUES('",A11,"','",B11,"','",C11,"','",D11,"','",E11,"','",F11,"','",G11,"',",IF(H11="NULL","NULL",CONCATENATE("'",H11,"'")),",",IF(I11="NULL","NULL",CONCATENATE("'",I11,"'")),",",IF(J11="NULL","NULL",CONCATENATE("'",J11,"'")),",'",K11,"',",IF(L11="NULL","NULL",CONCATENATE("'",L11,"'")),",",IF(M11="NULL","NULL",CONCATENATE("'",M11,"'")),",'",N11,"');") -> VALUES('RPT_ALL_JOBS_CO','ACC_TYPE_CO','1','JOB_PROCESS_VIA','L','Process Via','2','LIST','ALL,MOBILE,WEB','ALL,MOBILE,WEB','Y',NULL,NULL,'N'); | R11: =CONCATENATE(O11,P11) -> INSERT INTO `T_CORE_RPT_FILTER`(`RPTF_ID`,`RPTF_ACCN_TYPE`,`RPTF_IDX`,`RPTF_NAME`,`RPTF_FILTYPE`,`RPTF_CAPTION`,`RPTF_BASIC_ROW`,`RPTF_LISTBOX_TBL`,`RPTF_LISTBOX_IDCOL`,`RPTF_LISTBOX_CAPCOL`,`RPTF_SHOW`,`RPTF_DEFVAL`,`RPTF_IFNULLVAL`,`RPTF_MANDATORY`) VALUES('RPT_ALL_JOBS_CO','ACC_TYPE_CO','1','JOB_PROCESS_VIA','L','Process Via','2','LIST','ALL,MOBILE,WEB','ALL,MOBILE,WEB','Y',NULL,NULL,'N');
A12: RPT_ALL_JOBS_CO | B12: ACC_TYPE_CO | C12: 2 | D12: RCD_DT_CANCEL | E12: R | F12: Date Cancelled | G12: 3 | H12: NULL | I12: NULL | J12: NULL | K12: Y | L12: NULL | M12: NULL | N12: N | O12: =CONCATENATE("INSERT INTO `T_CORE_RPT_FILTER`(`RPTF_ID`,`RPTF_ACCN_TYPE`,`RPTF_IDX`,`RPTF_NAME`,`RPTF_FILTYPE`,`RPTF_CAPTION`,`RPTF_BASIC_ROW`,`RPTF_LISTBOX_TBL`,`RPTF_LISTBOX_IDCOL`,`RPTF_LISTBOX_CAPCOL`,`RPTF_SHOW`,`RPTF_DEFVAL`,`RPTF_IFNULLVAL`,`RPTF_MANDATORY`)") -> INSERT INTO `T_CORE_RPT_FILTER`(`RPTF_ID`,`RPTF_ACCN_TYPE`,`RPTF_IDX`,`RPTF_NAME`,`RPTF_FILTYPE`,`RPTF_CAPTION`,`RPTF_BASIC_ROW`,`RPTF_LISTBOX_TBL`,`RPTF_LISTBOX_IDCOL`,`RPTF_LISTBOX_CAPCOL`,`RPTF_SHOW`,`RPTF_DEFVAL`,`RPTF_IFNULLVAL`,`RPTF_MANDATORY`) | P12: =CONCATENATE(" VALUES('",A12,"','",B12,"','",C12,"','",D12,"','",E12,"','",F12,"','",G12,"',",IF(H12="NULL","NULL",CONCATENATE("'",H12,"'")),",",IF(I12="NULL","NULL",CONCATENATE("'",I12,"'")),",",IF(J12="NULL","NULL",CONCATENATE("'",J12,"'")),",'",K12,"',",IF(L12="NULL","NULL",CONCATENATE("'",L12,"'")),",",IF(M12="NULL","NULL",CONCATENATE("'",M12,"'")),",'",N12,"');") -> VALUES('RPT_ALL_JOBS_CO','ACC_TYPE_CO','2','RCD_DT_CANCEL','R','Date Cancelled','3',NULL,NULL,NULL,'Y',NULL,NULL,'N'); | R12: =CONCATENATE(O12,P12) -> INSERT INTO `T_CORE_RPT_FILTER`(`RPTF_ID`,`RPTF_ACCN_TYPE`,`RPTF_IDX`,`RPTF_NAME`,`RPTF_FILTYPE`,`RPTF_CAPTION`,`RPTF_BASIC_ROW`,`RPTF_LISTBOX_TBL`,`RPTF_LISTBOX_IDCOL`,`RPTF_LISTBOX_CAPCOL`,`RPTF_SHOW`,`RPTF_DEFVAL`,`RPTF_IFNULLVAL`,`RPTF_MANDATORY`) VALUES('RPT_ALL_JOBS_CO','ACC_TYPE_CO','2','RCD_DT_CANCEL','R','Date Cancelled','3',NULL,NULL,NULL,'Y',NULL,NULL,'N');
A13: RPT_ALL_JOBS_CO | B13: ACC_TYPE_CO | C13: 3 | D13: RCD_DT_COMPLETE | E13: R | F13: Date Completed | G13: 4 | H13: NULL | I13: NULL | J13: NULL | K13: Y | L13: NULL | M13: NULL | N13: N | O13: =CONCATENATE("INSERT INTO `T_CORE_RPT_FILTER`(`RPTF_ID`,`RPTF_ACCN_TYPE`,`RPTF_IDX`,`RPTF_NAME`,`RPTF_FILTYPE`,`RPTF_CAPTION`,`RPTF_BASIC_ROW`,`RPTF_LISTBOX_TBL`,`RPTF_LISTBOX_IDCOL`,`RPTF_LISTBOX_CAPCOL`,`RPTF_SHOW`,`RPTF_DEFVAL`,`RPTF_IFNULLVAL`,`RPTF_MANDATORY`)") -> INSERT INTO `T_CORE_RPT_FILTER`(`RPTF_ID`,`RPTF_ACCN_TYPE`,`RPTF_IDX`,`RPTF_NAME`,`RPTF_FILTYPE`,`RPTF_CAPTION`,`RPTF_BASIC_ROW`,`RPTF_LISTBOX_TBL`,`RPTF_LISTBOX_IDCOL`,`RPTF_LISTBOX_CAPCOL`,`RPTF_SHOW`,`RPTF_DEFVAL`,`RPTF_IFNULLVAL`,`RPTF_MANDATORY`) | P13: =CONCATENATE(" VALUES('",A13,"','",B13,"','",C13,"','",D13,"','",E13,"','",F13,"','",G13,"',",IF(H13="NULL","NULL",CONCATENATE("'",H13,"'")),",",IF(I13="NULL","NULL",CONCATENATE("'",I13,"'")),",",IF(J13="NULL","NULL",CONCATENATE("'",J13,"'")),",'",K13,"',",IF(L13="NULL","NULL",CONCATENATE("'",L13,"'")),",",IF(M13="NULL","NULL",CONCATENATE("'",M13,"'")),",'",N13,"');") -> VALUES('RPT_ALL_JOBS_CO','ACC_TYPE_CO','3','RCD_DT_COMPLETE','R','Date Completed','4',NULL,NULL,NULL,'Y',NULL,NULL,'N'); | R13: =CONCATENATE(O13,P13) -> INSERT INTO `T_CORE_RPT_FILTER`(`RPTF_ID`,`RPTF_ACCN_TYPE`,`RPTF_IDX`,`RPTF_NAME`,`RPTF_FILTYPE`,`RPTF_CAPTION`,`RPTF_BASIC_ROW`,`RPTF_LISTBOX_TBL`,`RPTF_LISTBOX_IDCOL`,`RPTF_LISTBOX_CAPCOL`,`RPTF_SHOW`,`RPTF_DEFVAL`,`RPTF_IFNULLVAL`,`RPTF_MANDATORY`) VALUES('RPT_ALL_JOBS_CO','ACC_TYPE_CO','3','RCD_DT_COMPLETE','R','Date Completed','4',NULL,NULL,NULL,'Y',NULL,NULL,'N');
A14: RPT_ALL_JOBS_CO | B14: ACC_TYPE_CO | C14: 4 | D14: RCD_DT_ACCEPTED | E14: R | F14: Date Accepted | G14: 5 | H14: NULL | I14: NULL | J14: NULL | K14: Y | L14: NULL | M14: NULL | N14: N | O14: =CONCATENATE("INSERT INTO `T_CORE_RPT_FILTER`(`RPTF_ID`,`RPTF_ACCN_TYPE`,`RPTF_IDX`,`RPTF_NAME`,`RPTF_FILTYPE`,`RPTF_CAPTION`,`RPTF_BASIC_ROW`,`RPTF_LISTBOX_TBL`,`RPTF_LISTBOX_IDCOL`,`RPTF_LISTBOX_CAPCOL`,`RPTF_SHOW`,`RPTF_DEFVAL`,`RPTF_IFNULLVAL`,`RPTF_MANDATORY`)") -> INSERT INTO `T_CORE_RPT_FILTER`(`RPTF_ID`,`RPTF_ACCN_TYPE`,`RPTF_IDX`,`RPTF_NAME`,`RPTF_FILTYPE`,`RPTF_CAPTION`,`RPTF_BASIC_ROW`,`RPTF_LISTBOX_TBL`,`RPTF_LISTBOX_IDCOL`,`RPTF_LISTBOX_CAPCOL`,`RPTF_SHOW`,`RPTF_DEFVAL`,`RPTF_IFNULLVAL`,`RPTF_MANDATORY`) | P14: =CONCATENATE(" VALUES('",A14,"','",B14,"','",C14,"','",D14,"','",E14,"','",F14,"','",G14,"',",IF(H14="NULL","NULL",CONCATENATE("'",H14,"'")),",",IF(I14="NULL","NULL",CONCATENATE("'",I14,"'")),",",IF(J14="NULL","NULL",CONCATENATE("'",J14,"'")),",'",K14,"',",IF(L14="NULL","NULL",CONCATENATE("'",L14,"'")),",",IF(M14="NULL","NULL",CONCATENATE("'",M14,"'")),",'",N14,"');") -> VALUES('RPT_ALL_JOBS_CO','ACC_TYPE_CO','4','RCD_DT_ACCEPTED','R','Date Accepted','5',NULL,NULL,NULL,'Y',NULL,NULL,'N'); | R14: =CONCATENATE(O14,P14) -> INSERT INTO `T_CORE_RPT_FILTER`(`RPTF_ID`,`RPTF_ACCN_TYPE`,`RPTF_IDX`,`RPTF_NAME`,`RPTF_FILTYPE`,`RPTF_CAPTION`,`RPTF_BASIC_ROW`,`RPTF_LISTBOX_TBL`,`RPTF_LISTBOX_IDCOL`,`RPTF_LISTBOX_CAPCOL`,`RPTF_SHOW`,`RPTF_DEFVAL`,`RPTF_IFNULLVAL`,`RPTF_MANDATORY`) VALUES('RPT_ALL_JOBS_CO','ACC_TYPE_CO','4','RCD_DT_ACCEPTED','R','Date Accepted','5',NULL,NULL,NULL,'Y',NULL,NULL,'N');
A15: RPT_ALL_JOBS_CO | B15: ACC_TYPE_CO | C15: 5 | D15: RCD_DT_START | E15: R | F15: Date Started | G15: 6 | H15: NULL | I15: NULL | J15: NULL | K15: Y | L15: NULL | M15: NULL | N15: N | O15: =CONCATENATE("INSERT INTO `T_CORE_RPT_FILTER`(`RPTF_ID`,`RPTF_ACCN_TYPE`,`RPTF_IDX`,`RPTF_NAME`,`RPTF_FILTYPE`,`RPTF_CAPTION`,`RPTF_BASIC_ROW`,`RPTF_LISTBOX_TBL`,`RPTF_LISTBOX_IDCOL`,`RPTF_LISTBOX_CAPCOL`,`RPTF_SHOW`,`RPTF_DEFVAL`,`RPTF_IFNULLVAL`,`RPTF_MANDATORY`)") -> INSERT INTO `T_CORE_RPT_FILTER`(`RPTF_ID`,`RPTF_ACCN_TYPE`,`RPTF_IDX`,`RPTF_NAME`,`RPTF_FILTYPE`,`RPTF_CAPTION`,`RPTF_BASIC_ROW`,`RPTF_LISTBOX_TBL`,`RPTF_LISTBOX_IDCOL`,`RPTF_LISTBOX_CAPCOL`,`RPTF_SHOW`,`RPTF_DEFVAL`,`RPTF_IFNULLVAL`,`RPTF_MANDATORY`) | P15: =CONCATENATE(" VALUES('",A15,"','",B15,"','",C15,"','",D15,"','",E15,"','",F15,"','",G15,"',",IF(H15="NULL","NULL",CONCATENATE("'",H15,"'")),",",IF(I15="NULL","NULL",CONCATENATE("'",I15,"'")),",",IF(J15="NULL","NULL",CONCATENATE("'",J15,"'")),",'",K15,"',",IF(L15="NULL","NULL",CONCATENATE("'",L15,"'")),",",IF(M15="NULL","NULL",CONCATENATE("'",M15,"'")),",'",N15,"');") -> VALUES('RPT_ALL_JOBS_CO','ACC_TYPE_CO','5','RCD_DT_START','R','Date Started','6',NULL,NULL,NULL,'Y',NULL,NULL,'N'); | R15: =CONCATENATE(O15,P15) -> INSERT INTO `T_CORE_RPT_FILTER`(`RPTF_ID`,`RPTF_ACCN_TYPE`,`RPTF_IDX`,`RPTF_NAME`,`RPTF_FILTYPE`,`RPTF_CAPTION`,`RPTF_BASIC_ROW`,`RPTF_LISTBOX_TBL`,`RPTF_LISTBOX_IDCOL`,`RPTF_LISTBOX_CAPCOL`,`RPTF_SHOW`,`RPTF_DEFVAL`,`RPTF_IFNULLVAL`,`RPTF_MANDATORY`) VALUES('RPT_ALL_JOBS_CO','ACC_TYPE_CO','5','RCD_DT_START','R','Date Started','6',NULL,NULL,NULL,'Y',NULL,NULL,'N');
A16: RPT_ALL_JOBS_CO | L16: NULL | M16: NULL | O16: =CONCATENATE("INSERT INTO `T_CORE_RPT_FILTER`(`RPTF_ID`,`RPTF_ACCN_TYPE`,`RPTF_IDX`,`RPTF_NAME`,`RPTF_FILTYPE`,`RPTF_CAPTION`,`RPTF_BASIC_ROW`,`RPTF_LISTBOX_TBL`,`RPTF_LISTBOX_IDCOL`,`RPTF_LISTBOX_CAPCOL`,`RPTF_SHOW`,`RPTF_DEFVAL`,`RPTF_IFNULLVAL`,`RPTF_MANDATORY`)") -> INSERT INTO `T_CORE_RPT_FILTER`(`RPTF_ID`,`RPTF_ACCN_TYPE`,`RPTF_IDX`,`RPTF_NAME`,`RPTF_FILTYPE`,`RPTF_CAPTION`,`RPTF_BASIC_ROW`,`RPTF_LISTBOX_TBL`,`RPTF_LISTBOX_IDCOL`,`RPTF_LISTBOX_CAPCOL`,`RPTF_SHOW`,`RPTF_DEFVAL`,`RPTF_IFNULLVAL`,`RPTF_MANDATORY`) | P16: =CONCATENATE(" VALUES('",A16,"','",B16,"','",C16,"','",D16,"','",E16,"','",F16,"','",G16,"',",IF(H16="NULL","NULL",CONCATENATE("'",H16,"'")),",",IF(I16="NULL","NULL",CONCATENATE("'",I16,"'")),",",IF(J16="NULL","NULL",CONCATENATE("'",J16,"'")),",'",K16,"',",IF(L16="NULL","NULL",CONCATENATE("'",L16,"'")),",",IF(M16="NULL","NULL",CONCATENATE("'",M16,"'")),",'",N16,"');") -> VALUES('RPT_ALL_JOBS_CO','','','','','','','','','','',NULL,NULL,''); | R16: =CONCATENATE(O16,P16) -> INSERT INTO `T_CORE_RPT_FILTER`(`RPTF_ID`,`RPTF_ACCN_TYPE`,`RPTF_IDX`,`RPTF_NAME`,`RPTF_FILTYPE`,`RPTF_CAPTION`,`RPTF_BASIC_ROW`,`RPTF_LISTBOX_TBL`,`RPTF_LISTBOX_IDCOL`,`RPTF_LISTBOX_CAPCOL`,`RPTF_SHOW`,`RPTF_DEFVAL`,`RPTF_IFNULLVAL`,`RPTF_MANDATORY`) VALUES('RPT_ALL_JOBS_CO','','','','','','','','','','',NULL,NULL,'');
A17: RPT_ALL_JOBS_CO | B17: ACC_TYPE_CO | C17: 6 | D17: RCD_DT_SUBMIT | E17: R | F17: Date Submitted | G17: 7 | H17: NULL | I17: NULL | J17: NULL | K17: Y | L17: NULL | M17: NULL | N17: N | O17: =CONCATENATE("INSERT INTO `T_CORE_RPT_FILTER`(`RPTF_ID`,`RPTF_ACCN_TYPE`,`RPTF_IDX`,`RPTF_NAME`,`RPTF_FILTYPE`,`RPTF_CAPTION`,`RPTF_BASIC_ROW`,`RPTF_LISTBOX_TBL`,`RPTF_LISTBOX_IDCOL`,`RPTF_LISTBOX_CAPCOL`,`RPTF_SHOW`,`RPTF_DEFVAL`,`RPTF_IFNULLVAL`,`RPTF_MANDATORY`)") -> INSERT INTO `T_CORE_RPT_FILTER`(`RPTF_ID`,`RPTF_ACCN_TYPE`,`RPTF_IDX`,`RPTF_NAME`,`RPTF_FILTYPE`,`RPTF_CAPTION`,`RPTF_BASIC_ROW`,`RPTF_LISTBOX_TBL`,`RPTF_LISTBOX_IDCOL`,`RPTF_LISTBOX_CAPCOL`,`RPTF_SHOW`,`RPTF_DEFVAL`,`RPTF_IFNULLVAL`,`RPTF_MANDATORY`) | P17: =CONCATENATE(" VALUES('",A17,"','",B17,"','",C17,"','",D17,"','",E17,"','",F17,"','",G17,"',",IF(H17="NULL","NULL",CONCATENATE("'",H17,"'")),",",IF(I17="NULL","NULL",CONCATENATE("'",I17,"'")),",",IF(J17="NULL","NULL",CONCATENATE("'",J17,"'")),",'",K17,"',",IF(L17="NULL","NULL",CONCATENATE("'",L17,"'")),",",IF(M17="NULL","NULL",CONCATENATE("'",M17,"'")),",'",N17,"');") -> VALUES('RPT_ALL_JOBS_CO','ACC_TYPE_CO','6','RCD_DT_SUBMIT','R','Date Submitted','7',NULL,NULL,NULL,'Y',NULL,NULL,'N'); | R17: =CONCATENATE(O17,P17) -> INSERT INTO `T_CORE_RPT_FILTER`(`RPTF_ID`,`RPTF_ACCN_TYPE`,`RPTF_IDX`,`RPTF_NAME`,`RPTF_FILTYPE`,`RPTF_CAPTION`,`RPTF_BASIC_ROW`,`RPTF_LISTBOX_TBL`,`RPTF_LISTBOX_IDCOL`,`RPTF_LISTBOX_CAPCOL`,`RPTF_SHOW`,`RPTF_DEFVAL`,`RPTF_IFNULLVAL`,`RPTF_MANDATORY`) VALUES('RPT_ALL_JOBS_CO','ACC_TYPE_CO','6','RCD_DT_SUBMIT','R','Date Submitted','7',NULL,NULL,NULL,'Y',NULL,NULL,'N');
A18: RPT_JOBS_DISCREPANCY_TO | B18: ACC_TYPE_TO | C18: 0 | D18: RCD_DT_COMPLETE | E18: R | F18: Date Completed | G18: 1 | H18: NULL | I18: NULL | J18: NULL | K18: Y | L18: NULL | M18: NULL | N18: N | O18: =CONCATENATE("INSERT INTO `T_CORE_RPT_FILTER`(`RPTF_ID`,`RPTF_ACCN_TYPE`,`RPTF_IDX`,`RPTF_NAME`,`RPTF_FILTYPE`,`RPTF_CAPTION`,`RPTF_BASIC_ROW`,`RPTF_LISTBOX_TBL`,`RPTF_LISTBOX_IDCOL`,`RPTF_LISTBOX_CAPCOL`,`RPTF_SHOW`,`RPTF_DEFVAL`,`RPTF_IFNULLVAL`,`RPTF_MANDATORY`)") -> INSERT INTO `T_CORE_RPT_FILTER`(`RPTF_ID`,`RPTF_ACCN_TYPE`,`RPTF_IDX`,`RPTF_NAME`,`RPTF_FILTYPE`,`RPTF_CAPTION`,`RPTF_BASIC_ROW`,`RPTF_LISTBOX_TBL`,`RPTF_LISTBOX_IDCOL`,`RPTF_LISTBOX_CAPCOL`,`RPTF_SHOW`,`RPTF_DEFVAL`,`RPTF_IFNULLVAL`,`RPTF_MANDATORY`) | P18: =CONCATENATE(" VALUES('",A18,"','",B18,"','",C18,"','",D18,"','",E18,"','",F18,"','",G18,"',",IF(H18="NULL","NULL",CONCATENATE("'",H18,"'")),",",IF(I18="NULL","NULL",CONCATENATE("'",I18,"'")),",",IF(J18="NULL","NULL",CONCATENATE("'",J18,"'")),",'",K18,"',",IF(L18="NULL","NULL",CONCATENATE("'",L18,"'")),",",IF(M18="NULL","NULL",CONCATENATE("'",M18,"'")),",'",N18,"');") -> VALUES('RPT_JOBS_DISCREPANCY_TO','ACC_TYPE_TO','0','RCD_DT_COMPLETE','R','Date Completed','1',NULL,NULL,NULL,'Y',NULL,NULL,'N'); | R18: =CONCATENATE(O18,P18) -> INSERT INTO `T_CORE_RPT_FILTER`(`RPTF_ID`,`RPTF_ACCN_TYPE`,`RPTF_IDX`,`RPTF_NAME`,`RPTF_FILTYPE`,`RPTF_CAPTION`,`RPTF_BASIC_ROW`,`RPTF_LISTBOX_TBL`,`RPTF_LISTBOX_IDCOL`,`RPTF_LISTBOX_CAPCOL`,`RPTF_SHOW`,`RPTF_DEFVAL`,`RPTF_IFNULLVAL`,`RPTF_MANDATORY`) VALUES('RPT_JOBS_DISCREPANCY_TO','ACC_TYPE_TO','0','RCD_DT_COMPLETE','R','Date Completed','1',NULL,NULL,NULL,'Y',NULL,NULL,'N');
A19: RPT_JOBS_DISCREPANCY_TO | B19: ACC_TYPE_TO | C19: 1 | D19: IS_DEVIATED | E19: L | F19: Is Deviated | G19: 2 | H19: LIST | I19: Y,N | J19: YES,NO | K19: Y | L19: Y | M19: Y | N19: N | O19: =CONCATENATE("INSERT INTO `T_CORE_RPT_FILTER`(`RPTF_ID`,`RPTF_ACCN_TYPE`,`RPTF_IDX`,`RPTF_NAME`,`RPTF_FILTYPE`,`RPTF_CAPTION`,`RPTF_BASIC_ROW`,`RPTF_LISTBOX_TBL`,`RPTF_LISTBOX_IDCOL`,`RPTF_LISTBOX_CAPCOL`,`RPTF_SHOW`,`RPTF_DEFVAL`,`RPTF_IFNULLVAL`,`RPTF_MANDATORY`)") -> INSERT INTO `T_CORE_RPT_FILTER`(`RPTF_ID`,`RPTF_ACCN_TYPE`,`RPTF_IDX`,`RPTF_NAME`,`RPTF_FILTYPE`,`RPTF_CAPTION`,`RPTF_BASIC_ROW`,`RPTF_LISTBOX_TBL`,`RPTF_LISTBOX_IDCOL`,`RPTF_LISTBOX_CAPCOL`,`RPTF_SHOW`,`RPTF_DEFVAL`,`RPTF_IFNULLVAL`,`RPTF_MANDATORY`) | P19: =CONCATENATE(" VALUES('",A19,"','",B19,"','",C19,"','",D19,"','",E19,"','",F19,"','",G19,"',",IF(H19="NULL","NULL",CONCATENATE("'",H19,"'")),",",IF(I19="NULL","NULL",CONCATENATE("'",I19,"'")),",",IF(J19="NULL","NULL",CONCATENATE("'",J19,"'")),",'",K19,"',",IF(L19="NULL","NULL",CONCATENATE("'",L19,"'")),",",IF(M19="NULL","NULL",CONCATENATE("'",M19,"'")),",'",N19,"');") -> VALUES('RPT_JOBS_DISCREPANCY_TO','ACC_TYPE_TO','1','IS_DEVIATED','L','Is Deviated','2','LIST','Y,N','YES,NO','Y','Y','Y','N'); | R19: =CONCATENATE(O19,P19) -> INSERT INTO `T_CORE_RPT_FILTER`(`RPTF_ID`,`RPTF_ACCN_TYPE`,`RPTF_IDX`,`RPTF_NAME`,`RPTF_FILTYPE`,`RPTF_CAPTION`,`RPTF_BASIC_ROW`,`RPTF_LISTBOX_TBL`,`RPTF_LISTBOX_IDCOL`,`RPTF_LISTBOX_CAPCOL`,`RPTF_SHOW`,`RPTF_DEFVAL`,`RPTF_IFNULLVAL`,`RPTF_MANDATORY`) VALUES('RPT_JOBS_DISCREPANCY_TO','ACC_TYPE_TO','1','IS_DEVIATED','L','Is Deviated','2','LIST','Y,N','YES,NO','Y','Y','Y','N');
A20: RPT_JOBS_DISCREPANCY_TO | B20: ACC_TYPE_TO | C20: 2 | D20: HAS_DISCREPANCY | E20: L | F20: Has Discrepancy | G20: 3 | H20: LIST | I20: Y,N | J20: YES,NO | K20: Y | L20: Y | M20: Y | N20: N | O20: =CONCATENATE("INSERT INTO `T_CORE_RPT_FILTER`(`RPTF_ID`,`RPTF_ACCN_TYPE`,`RPTF_IDX`,`RPTF_NAME`,`RPTF_FILTYPE`,`RPTF_CAPTION`,`RPTF_BASIC_ROW`,`RPTF_LISTBOX_TBL`,`RPTF_LISTBOX_IDCOL`,`RPTF_LISTBOX_CAPCOL`,`RPTF_SHOW`,`RPTF_DEFVAL`,`RPTF_IFNULLVAL`,`RPTF_MANDATORY`)") -> INSERT INTO `T_CORE_RPT_FILTER`(`RPTF_ID`,`RPTF_ACCN_TYPE`,`RPTF_IDX`,`RPTF_NAME`,`RPTF_FILTYPE`,`RPTF_CAPTION`,`RPTF_BASIC_ROW`,`RPTF_LISTBOX_TBL`,`RPTF_LISTBOX_IDCOL`,`RPTF_LISTBOX_CAPCOL`,`RPTF_SHOW`,`RPTF_DEFVAL`,`RPTF_IFNULLVAL`,`RPTF_MANDATORY`) | P20: =CONCATENATE(" VALUES('",A20,"','",B20,"','",C20,"','",D20,"','",E20,"','",F20,"','",G20,"',",IF(H20="NULL","NULL",CONCATENATE("'",H20,"'")),",",IF(I20="NULL","NULL",CONCATENATE("'",I20,"'")),",",IF(J20="NULL","NULL",CONCATENATE("'",J20,"'")),",'",K20,"',",IF(L20="NULL","NULL",CONCATENATE("'",L20,"'")),",",IF(M20="NULL","NULL",CONCATENATE("'",M20,"'")),",'",N20,"');") -> VALUES('RPT_JOBS_DISCREPANCY_TO','ACC_TYPE_TO','2','HAS_DISCREPANCY','L','Has Discrepancy','3','LIST','Y,N','YES,NO','Y','Y','Y','N'); | R20: =CONCATENATE(O20,P20) -> INSERT INTO `T_CORE_RPT_FILTER`(`RPTF_ID`,`RPTF_ACCN_TYPE`,`RPTF_IDX`,`RPTF_NAME`,`RPTF_FILTYPE`,`RPTF_CAPTION`,`RPTF_BASIC_ROW`,`RPTF_LISTBOX_TBL`,`RPTF_LISTBOX_IDCOL`,`RPTF_LISTBOX_CAPCOL`,`RPTF_SHOW`,`RPTF_DEFVAL`,`RPTF_IFNULLVAL`,`RPTF_MANDATORY`) VALUES('RPT_JOBS_DISCREPANCY_TO','ACC_TYPE_TO','2','HAS_DISCREPANCY','L','Has Discrepancy','3','LIST','Y,N','YES,NO','Y','Y','Y','N');
A21: RPT_JOBS_DISCREPANCY_CO | B21: ACC_TYPE_CO | C21: 0 | D21: RCD_DT_COMPLETE | E21: R | F21: Date Completed | G21: 1 | H21: NULL | I21: NULL | J21: NULL | K21: Y | L21: NULL | M21: NULL | N21: N | O21: =CONCATENATE("INSERT INTO `T_CORE_RPT_FILTER`(`RPTF_ID`,`RPTF_ACCN_TYPE`,`RPTF_IDX`,`RPTF_NAME`,`RPTF_FILTYPE`,`RPTF_CAPTION`,`RPTF_BASIC_ROW`,`RPTF_LISTBOX_TBL`,`RPTF_LISTBOX_IDCOL`,`RPTF_LISTBOX_CAPCOL`,`RPTF_SHOW`,`RPTF_DEFVAL`,`RPTF_IFNULLVAL`,`RPTF_MANDATORY`)") -> INSERT INTO `T_CORE_RPT_FILTER`(`RPTF_ID`,`RPTF_ACCN_TYPE`,`RPTF_IDX`,`RPTF_NAME`,`RPTF_FILTYPE`,`RPTF_CAPTION`,`RPTF_BASIC_ROW`,`RPTF_LISTBOX_TBL`,`RPTF_LISTBOX_IDCOL`,`RPTF_LISTBOX_CAPCOL`,`RPTF_SHOW`,`RPTF_DEFVAL`,`RPTF_IFNULLVAL`,`RPTF_MANDATORY`) | P21: =CONCATENATE(" VALUES('",A21,"','",B21,"','",C21,"','",D21,"','",E21,"','",F21,"','",G21,"',",IF(H21="NULL","NULL",CONCATENATE("'",H21,"'")),",",IF(I21="NULL","NULL",CONCATENATE("'",I21,"'")),",",IF(J21="NULL","NULL",CONCATENATE("'",J21,"'")),",'",K21,"',",IF(L21="NULL","NULL",CONCATENATE("'",L21,"'")),",",IF(M21="NULL","NULL",CONCATENATE("'",M21,"'")),",'",N21,"');") -> VALUES('RPT_JOBS_DISCREPANCY_CO','ACC_TYPE_CO','0','RCD_DT_COMPLETE','R','Date Completed','1',NULL,NULL,NULL,'Y',NULL,NULL,'N'); | R21: =CONCATENATE(O21,P21) -> INSERT INTO `T_CORE_RPT_FILTER`(`RPTF_ID`,`RPTF_ACCN_TYPE`,`RPTF_IDX`,`RPTF_NAME`,`RPTF_FILTYPE`,`RPTF_CAPTION`,`RPTF_BASIC_ROW`,`RPTF_LISTBOX_TBL`,`RPTF_LISTBOX_IDCOL`,`RPTF_LISTBOX_CAPCOL`,`RPTF_SHOW`,`RPTF_DEFVAL`,`RPTF_IFNULLVAL`,`RPTF_MANDATORY`) VALUES('RPT_JOBS_DISCREPANCY_CO','ACC_TYPE_CO','0','RCD_DT_COMPLETE','R','Date Completed','1',NULL,NULL,NULL,'Y',NULL,NULL,'N');
A22: RPT_JOBS_DISCREPANCY_CO | B22: ACC_TYPE_CO | C22: 1 | D22: IS_DEVIATED | E22: L | F22: Is Deviated | G22: 2 | H22: LIST | I22: Y,N | J22: YES,NO | K22: Y | L22: Y | M22: Y | N22: N | O22: =CONCATENATE("INSERT INTO `T_CORE_RPT_FILTER`(`RPTF_ID`,`RPTF_ACCN_TYPE`,`RPTF_IDX`,`RPTF_NAME`,`RPTF_FILTYPE`,`RPTF_CAPTION`,`RPTF_BASIC_ROW`,`RPTF_LISTBOX_TBL`,`RPTF_LISTBOX_IDCOL`,`RPTF_LISTBOX_CAPCOL`,`RPTF_SHOW`,`RPTF_DEFVAL`,`RPTF_IFNULLVAL`,`RPTF_MANDATORY`)") -> INSERT INTO `T_CORE_RPT_FILTER`(`RPTF_ID`,`RPTF_ACCN_TYPE`,`RPTF_IDX`,`RPTF_NAME`,`RPTF_FILTYPE`,`RPTF_CAPTION`,`RPTF_BASIC_ROW`,`RPTF_LISTBOX_TBL`,`RPTF_LISTBOX_IDCOL`,`RPTF_LISTBOX_CAPCOL`,`RPTF_SHOW`,`RPTF_DEFVAL`,`RPTF_IFNULLVAL`,`RPTF_MANDATORY`) | P22: =CONCATENATE(" VALUES('",A22,"','",B22,"','",C22,"','",D22,"','",E22,"','",F22,"','",G22,"',",IF(H22="NULL","NULL",CONCATENATE("'",H22,"'")),",",IF(I22="NULL","NULL",CONCATENATE("'",I22,"'")),",",IF(J22="NULL","NULL",CONCATENATE("'",J22,"'")),",'",K22,"',",IF(L22="NULL","NULL",CONCATENATE("'",L22,"'")),",",IF(M22="NULL","NULL",CONCATENATE("'",M22,"'")),",'",N22,"');") -> VALUES('RPT_JOBS_DISCREPANCY_CO','ACC_TYPE_CO','1','IS_DEVIATED','L','Is Deviated','2','LIST','Y,N','YES,NO','Y','Y','Y','N'); | R22: =CONCATENATE(O22,P22) -> INSERT INTO `T_CORE_RPT_FILTER`(`RPTF_ID`,`RPTF_ACCN_TYPE`,`RPTF_IDX`,`RPTF_NAME`,`RPTF_FILTYPE`,`RPTF_CAPTION`,`RPTF_BASIC_ROW`,`RPTF_LISTBOX_TBL`,`RPTF_LISTBOX_IDCOL`,`RPTF_LISTBOX_CAPCOL`,`RPTF_SHOW`,`RPTF_DEFVAL`,`RPTF_IFNULLVAL`,`RPTF_MANDATORY`) VALUES('RPT_JOBS_DISCREPANCY_CO','ACC_TYPE_CO','1','IS_DEVIATED','L','Is Deviated','2','LIST','Y,N','YES,NO','Y','Y','Y','N');
A23: RPT_JOBS_DISCREPANCY_CO | B23: ACC_TYPE_CO | C23: 2 | D23: HAS_DISCREPANCY | E23: L | F23: Has Discrepancy | G23: 3 | H23: LIST | I23: Y,N | J23: YES,NO | K23: Y | L23: Y | M23: Y | N23: N | O23: =CONCATENATE("INSERT INTO `T_CORE_RPT_FILTER`(`RPTF_ID`,`RPTF_ACCN_TYPE`,`RPTF_IDX`,`RPTF_NAME`,`RPTF_FILTYPE`,`RPTF_CAPTION`,`RPTF_BASIC_ROW`,`RPTF_LISTBOX_TBL`,`RPTF_LISTBOX_IDCOL`,`RPTF_LISTBOX_CAPCOL`,`RPTF_SHOW`,`RPTF_DEFVAL`,`RPTF_IFNULLVAL`,`RPTF_MANDATORY`)") -> INSERT INTO `T_CORE_RPT_FILTER`(`RPTF_ID`,`RPTF_ACCN_TYPE`,`RPTF_IDX`,`RPTF_NAME`,`RPTF_FILTYPE`,`RPTF_CAPTION`,`RPTF_BASIC_ROW`,`RPTF_LISTBOX_TBL`,`RPTF_LISTBOX_IDCOL`,`RPTF_LISTBOX_CAPCOL`,`RPTF_SHOW`,`RPTF_DEFVAL`,`RPTF_IFNULLVAL`,`RPTF_MANDATORY`) | P23: =CONCATENATE(" VALUES('",A23,"','",B23,"','",C23,"','",D23,"','",E23,"','",F23,"','",G23,"',",IF(H23="NULL","NULL",CONCATENATE("'",H23,"'")),",",IF(I23="NULL","NULL",CONCATENATE("'",I23,"'")),",",IF(J23="NULL","NULL",CONCATENATE("'",J23,"'")),",'",K23,"',",IF(L23="NULL","NULL",CONCATENATE("'",L23,"'")),",",IF(M23="NULL","NULL",CONCATENATE("'",M23,"'")),",'",N23,"');") -> VALUES('RPT_JOBS_DISCREPANCY_CO','ACC_TYPE_CO','2','HAS_DISCREPANCY','L','Has Discrepancy','3','LIST','Y,N','YES,NO','Y','Y','Y','N'); | R23: =CONCATENATE(O23,P23) -> INSERT INTO `T_CORE_RPT_FILTER`(`RPTF_ID`,`RPTF_ACCN_TYPE`,`RPTF_IDX`,`RPTF_NAME`,`RPTF_FILTYPE`,`RPTF_CAPTION`,`RPTF_BASIC_ROW`,`RPTF_LISTBOX_TBL`,`RPTF_LISTBOX_IDCOL`,`RPTF_LISTBOX_CAPCOL`,`RPTF_SHOW`,`RPTF_DEFVAL`,`RPTF_IFNULLVAL`,`RPTF_MANDATORY`) VALUES('RPT_JOBS_DISCREPANCY_CO','ACC_TYPE_CO','2','HAS_DISCREPANCY','L','Has Discrepancy','3','LIST','Y,N','YES,NO','Y','Y','Y','N');

Sheet Menu_EX
A1: MENU_ID | B1: MENU_APPS_CODE | C1: MENU_GROUP_LABEL | D1: MENU_GROUP_LABEL_OTH | E1: MENU_NAME | F1: MENU_NAME_OTH | G1: MENU_SEQ | H1: MENU_PATH | I1: MENU_ICON | J1: MENU_PARENT | K1: MENU_STATUS | L1: SQL
A2: CK_MS_010000 | B2: CK | C2: Services | D2: Services | E2: Services | F2: Services | G2: 10000 | H2: / | I2: NULL | J2: NULL | K2: A | L2: =CONCATENATE("INSERT INTO T_CORE_MENU_EX (MENU_ID, MENU_APPS_CODE, MENU_GROUP_LABEL, MENU_GROUP_LABEL_OTH, MENU_NAME, MENU_NAME_OTH, MENU_SEQ, MENU_PATH, MENU_ICON, MENU_PARENT, MENU_STATUS, MENU_DT_CREATE, MENU_UID_CREATE, MENU_DT_LUPD, MENU_UID_LUPD) ") -> INSERT INTO T_CORE_MENU_EX (MENU_ID, MENU_APPS_CODE, MENU_GROUP_LABEL, MENU_GROUP_LABEL_OTH, MENU_NAME, MENU_NAME_OTH, MENU_SEQ, MENU_PATH, MENU_ICON, MENU_PARENT, MENU_STATUS, MENU_DT_CREATE, MENU_UID_CREATE, MENU_DT_LUPD, MENU_UID_LUPD) | M2: =CONCATENATE(" VALUES('",A2,"','",B2,"','",C2,"','",D2,"','",E2,"','",F2,"',",IF(G2="NULL","NULL",CONCATENATE("'",G2,"'")),",",IF(H2="NULL","NULL",CONCATENATE("'",H2,"'")),",",IF(I2="NULL","NULL",CONCATENATE("'",I2,"'")),",",IF(J2="NULL","NULL",CONCATENATE("'",J2,"'")),",'A',NOW(),'SYS',NOW(),'SYS');") -> VALUES('CK_MS_010000','CK','Services','Services','Services','Services','10000','/',NULL,NULL,'A',NOW(),'SYS',NOW(),'SYS'); | N2: =CONCATENATE(L2,M2) -> INSERT INTO T_CORE_MENU_EX (MENU_ID, MENU_APPS_CODE, MENU_GROUP_LABEL, MENU_GROUP_LABEL_OTH, MENU_NAME, MENU_NAME_OTH, MENU_SEQ, MENU_PATH, MENU_ICON, MENU_PARENT, MENU_STATUS, MENU_DT_CREATE, MENU_UID_CREATE, MENU_DT_LUPD, MENU_UID_LUPD) VALUES('CK_MS_010000','CK','Services','Services','Services','Services','10000','/',NULL,NULL,'A',NOW(),'SYS',NOW(),'SYS');
A3: CK_MP_020000 | B3: CK | C3: Payments | D3: Payments | E3: Payments | F3: Payments | G3: 20000 | H3: /payments | I3: NULL | J3: NULL | K3: A | L3: =CONCATENATE("INSERT INTO T_CORE_MENU_EX (MENU_ID, MENU_APPS_CODE, MENU_GROUP_LABEL, MENU_GROUP_LABEL_OTH, MENU_NAME, MENU_NAME_OTH, MENU_SEQ, MENU_PATH, MENU_ICON, MENU_PARENT, MENU_STATUS, MENU_DT_CREATE, MENU_UID_CREATE, MENU_DT_LUPD, MENU_UID_LUPD) ") -> INSERT INTO T_CORE_MENU_EX (MENU_ID, MENU_APPS_CODE, MENU_GROUP_LABEL, MENU_GROUP_LABEL_OTH, MENU_NAME, MENU_NAME_OTH, MENU_SEQ, MENU_PATH, MENU_ICON, MENU_PARENT, MENU_STATUS, MENU_DT_CREATE, MENU_UID_CREATE, MENU_DT_LUPD, MENU_UID_LUPD) | M3: =CONCATENATE(" VALUES('",A3,"','",B3,"','",C3,"','",D3,"','",E3,"','",F3,"',",IF(G3="NULL","NULL",CONCATENATE("'",G3,"'")),",",IF(H3="NULL","NULL",CONCATENATE("'",H3,"'")),",",IF(I3="NULL","NULL",CONCATENATE("'",I3,"'")),",",IF(J3="NULL","NULL",CONCATENATE("'",J3,"'")),",'A',NOW(),'SYS',NOW(),'SYS');") -> VALUES('CK_MP_020000','CK','Payments','Payments','Payments','Payments','20000','/payments',NULL,NULL,'A',NOW(),'SYS',NOW(),'SYS'); | N3: =CONCATENATE(L3,M3) -> INSERT INTO T_CORE_MENU_EX (MENU_ID, MENU_APPS_CODE, MENU_GROUP_LABEL, MENU_GROUP_LABEL_OTH, MENU_NAME, MENU_NAME_OTH, MENU_SEQ, MENU_PATH, MENU_ICON, MENU_PARENT, MENU_STATUS, MENU_DT_CREATE, MENU_UID_CREATE, MENU_DT_LUPD, MENU_UID_LUPD) VALUES('CK_MP_020000','CK','Payments','Payments','Payments','Payments','20000','/payments',NULL,NULL,'A',NOW(),'SYS',NOW(),'SYS');
A4: CK_MA_030000 | B4: CK | C4: Administrations | D4: Administrations | E4: Administrations | F4: Administrations | G4: 30000 | H4: NULL | I4: group | J4: NULL | K4: A | L4: =CONCATENATE("INSERT INTO T_CORE_MENU_EX (MENU_ID, MENU_APPS_CODE, MENU_GROUP_LABEL, MENU_GROUP_LABEL_OTH, MENU_NAME, MENU_NAME_OTH, MENU_SEQ, MENU_PATH, MENU_ICON, MENU_PARENT, MENU_STATUS, MENU_DT_CREATE, MENU_UID_CREATE, MENU_DT_LUPD, MENU_UID_LUPD) ") -> INSERT INTO T_CORE_MENU_EX (MENU_ID, MENU_APPS_CODE, MENU_GROUP_LABEL, MENU_GROUP_LABEL_OTH, MENU_NAME, MENU_NAME_OTH, MENU_SEQ, MENU_PATH, MENU_ICON, MENU_PARENT, MENU_STATUS, MENU_DT_CREATE, MENU_UID_CREATE, MENU_DT_LUPD, MENU_UID_LUPD) | M4: =CONCATENATE(" VALUES('",A4,"','",B4,"','",C4,"','",D4,"','",E4,"','",F4,"',",IF(G4="NULL","NULL",CONCATENATE("'",G4,"'")),",",IF(H4="NULL","NULL",CONCATENATE("'",H4,"'")),",",IF(I4="NULL","NULL",CONCATENATE("'",I4,"'")),",",IF(J4="NULL","NULL",CONCATENATE("'",J4,"'")),",'A',NOW(),'SYS',NOW(),'SYS');") -> VALUES('CK_MA_030000','CK','Administrations','Administrations','Administrations','Administrations','30000',NULL,'group',NULL,'A',NOW(),'SYS',NOW(),'SYS'); | N4: =CONCATENATE(L4,M4) -> INSERT INTO T_CORE_MENU_EX (MENU_ID, MENU_APPS_CODE, MENU_GROUP_LABEL, MENU_GROUP_LABEL_OTH, MENU_NAME, MENU_NAME_OTH, MENU_SEQ, MENU_PATH, MENU_ICON, MENU_PARENT, MENU_STATUS, MENU_DT_CREATE, MENU_UID_CREATE, MENU_DT_LUPD, MENU_UID_LUPD) VALUES('CK_MA_030000','CK','Administrations','Administrations','Administrations','Administrations','30000',NULL,'group',NULL,'A',NOW(),'SYS',NOW(),'SYS');
A5: CK_MA_030100 | B5: CK | E5: Account Profile | F5: Account Profile | G5: 30100 | H5: /accountProfile | I5: NULL | J5: CK_MA_030000 | K5: A | L5: =CONCATENATE("INSERT INTO T_CORE_MENU_EX (MENU_ID, MENU_APPS_CODE, MENU_GROUP_LABEL, MENU_GROUP_LABEL_OTH, MENU_NAME, MENU_NAME_OTH, MENU_SEQ, MENU_PATH, MENU_ICON, MENU_PARENT, MENU_STATUS, MENU_DT_CREATE, MENU_UID_CREATE, MENU_DT_LUPD, MENU_UID_LUPD) ") -> INSERT INTO T_CORE_MENU_EX (MENU_ID, MENU_APPS_CODE, MENU_GROUP_LABEL, MENU_GROUP_LABEL_OTH, MENU_NAME, MENU_NAME_OTH, MENU_SEQ, MENU_PATH, MENU_ICON, MENU_PARENT, MENU_STATUS, MENU_DT_CREATE, MENU_UID_CREATE, MENU_DT_LUPD, MENU_UID_LUPD) | M5: =CONCATENATE(" VALUES('",A5,"','",B5,"','",C5,"','",D5,"','",E5,"','",F5,"',",IF(G5="NULL","NULL",CONCATENATE("'",G5,"'")),",",IF(H5="NULL","NULL",CONCATENATE("'",H5,"'")),",",IF(I5="NULL","NULL",CONCATENATE("'",I5,"'")),",",IF(J5="NULL","NULL",CONCATENATE("'",J5,"'")),",'A',NOW(),'SYS',NOW(),'SYS');") -> VALUES('CK_MA_030100','CK','','','Account Profile','Account Profile','30100','/accountProfile',NULL,'CK_MA_030000','A',NOW(),'SYS',NOW(),'SYS'); | N5: =CONCATENATE(L5,M5) -> INSERT INTO T_CORE_MENU_EX (MENU_ID, MENU_APPS_CODE, MENU_GROUP_LABEL, MENU_GROUP_LABEL_OTH, MENU_NAME, MENU_NAME_OTH, MENU_SEQ, MENU_PATH, MENU_ICON, MENU_PARENT, MENU_STATUS, MENU_DT_CREATE, MENU_UID_CREATE, MENU_DT_LUPD, MENU_UID_LUPD) VALUES('CK_MA_030100','CK','','','Account Profile','Account Profile','30100','/accountProfile',NULL,'CK_MA_030000','A',NOW(),'SYS',NOW(),'SYS');
A6: CK_MA_030200 | B6: CK | E6: Users | F6: Users | G6: 30200 | H6: /accountUsers | I6: NULL | J6: CK_MA_030000 | K6: A | L6: =CONCATENATE("INSERT INTO T_CORE_MENU_EX (MENU_ID, MENU_APPS_CODE, MENU_GROUP_LABEL, MENU_GROUP_LABEL_OTH, MENU_NAME, MENU_NAME_OTH, MENU_SEQ, MENU_PATH, MENU_ICON, MENU_PARENT, MENU_STATUS, MENU_DT_CREATE, MENU_UID_CREATE, MENU_DT_LUPD, MENU_UID_LUPD) ") -> INSERT INTO T_CORE_MENU_EX (MENU_ID, MENU_APPS_CODE, MENU_GROUP_LABEL, MENU_GROUP_LABEL_OTH, MENU_NAME, MENU_NAME_OTH, MENU_SEQ, MENU_PATH, MENU_ICON, MENU_PARENT, MENU_STATUS, MENU_DT_CREATE, MENU_UID_CREATE, MENU_DT_LUPD, MENU_UID_LUPD) | M6: =CONCATENATE(" VALUES('",A6,"','",B6,"','",C6,"','",D6,"','",E6,"','",F6,"',",IF(G6="NULL","NULL",CONCATENATE("'",G6,"'")),",",IF(H6="NULL","NULL",CONCATENATE("'",H6,"'")),",",IF(I6="NULL","NULL",CONCATENATE("'",I6,"'")),",",IF(J6="NULL","NULL",CONCATENATE("'",J6,"'")),",'A',NOW(),'SYS',NOW(),'SYS');") -> VALUES('CK_MA_030200','CK','','','Users','Users','30200','/accountUsers',NULL,'CK_MA_030000','A',NOW(),'SYS',NOW(),'SYS'); | N6: =CONCATENATE(L6,M6) -> INSERT INTO T_CORE_MENU_EX (MENU_ID, MENU_APPS_CODE, MENU_GROUP_LABEL, MENU_GROUP_LABEL_OTH, MENU_NAME, MENU_NAME_OTH, MENU_SEQ, MENU_PATH, MENU_ICON, MENU_PARENT, MENU_STATUS, MENU_DT_CREATE, MENU_UID_CREATE, MENU_DT_LUPD, MENU_UID_LUPD) VALUES('CK_MA_030200','CK','','','Users','Users','30200','/accountUsers',NULL,'CK_MA_030000','A',NOW(),'SYS',NOW(),'SYS');
A7: CK_MA_030300 | B7: CK | E7: Authorisations | F7: Authorisations | G7: 30400 | H7: /accountAuthorisations | I7: NULL | J7: CK_MA_030000 | K7: A | L7: =CONCATENATE("INSERT INTO T_CORE_MENU_EX (MENU_ID, MENU_APPS_CODE, MENU_GROUP_LABEL, MENU_GROUP_LABEL_OTH, MENU_NAME, MENU_NAME_OTH, MENU_SEQ, MENU_PATH, MENU_ICON, MENU_PARENT, MENU_STATUS, MENU_DT_CREATE, MENU_UID_CREATE, MENU_DT_LUPD, MENU_UID_LUPD) ") -> INSERT INTO T_CORE_MENU_EX (MENU_ID, MENU_APPS_CODE, MENU_GROUP_LABEL, MENU_GROUP_LABEL_OTH, MENU_NAME, MENU_NAME_OTH, MENU_SEQ, MENU_PATH, MENU_ICON, MENU_PARENT, MENU_STATUS, MENU_DT_CREATE, MENU_UID_CREATE, MENU_DT_LUPD, MENU_UID_LUPD) | M7: =CONCATENATE(" VALUES('",A7,"','",B7,"','",C7,"','",D7,"','",E7,"','",F7,"',",IF(G7="NULL","NULL",CONCATENATE("'",G7,"'")),",",IF(H7="NULL","NULL",CONCATENATE("'",H7,"'")),",",IF(I7="NULL","NULL",CONCATENATE("'",I7,"'")),",",IF(J7="NULL","NULL",CONCATENATE("'",J7,"'")),",'A',NOW(),'SYS',NOW(),'SYS');") -> VALUES('CK_MA_030300','CK','','','Authorisations','Authorisations','30400','/accountAuthorisations',NULL,'CK_MA_030000','A',NOW(),'SYS',NOW(),'SYS'); | N7: =CONCATENATE(L7,M7) -> INSERT INTO T_CORE_MENU_EX (MENU_ID, MENU_APPS_CODE, MENU_GROUP_LABEL, MENU_GROUP_LABEL_OTH, MENU_NAME, MENU_NAME_OTH, MENU_SEQ, MENU_PATH, MENU_ICON, MENU_PARENT, MENU_STATUS, MENU_DT_CREATE, MENU_UID_CREATE, MENU_DT_LUPD, MENU_UID_LUPD) VALUES('CK_MA_030300','CK','','','Authorisations','Authorisations','30400','/accountAuthorisations',NULL,'CK_MA_030000','A',NOW(),'SYS',NOW(),'SYS');
A8: CK_MH_040000 | B8: CK | C8: Help | D8: Help | E8: Help | F8: Help | G8: 40000 | H8: /help | I8: NULL | J8: NULL | K8: A | L8: =CONCATENATE("INSERT INTO T_CORE_MENU_EX (MENU_ID, MENU_APPS_CODE, MENU_GROUP_LABEL, MENU_GROUP_LABEL_OTH, MENU_NAME, MENU_NAME_OTH, MENU_SEQ, MENU_PATH, MENU_ICON, MENU_PARENT, MENU_STATUS, MENU_DT_CREATE, MENU_UID_CREATE, MENU_DT_LUPD, MENU_UID_LUPD) ") -> INSERT INTO T_CORE_MENU_EX (MENU_ID, MENU_APPS_CODE, MENU_GROUP_LABEL, MENU_GROUP_LABEL_OTH, MENU_NAME, MENU_NAME_OTH, MENU_SEQ, MENU_PATH, MENU_ICON, MENU_PARENT, MENU_STATUS, MENU_DT_CREATE, MENU_UID_CREATE, MENU_DT_LUPD, MENU_UID_LUPD) | M8: =CONCATENATE(" VALUES('",A8,"','",B8,"','",C8,"','",D8,"','",E8,"','",F8,"',",IF(G8="NULL","NULL",CONCATENATE("'",G8,"'")),",",IF(H8="NULL","NULL",CONCATENATE("'",H8,"'")),",",IF(I8="NULL","NULL",CONCATENATE("'",I8,"'")),",",IF(J8="NULL","NULL",CONCATENATE("'",J8,"'")),",'A',NOW(),'SYS',NOW(),'SYS');") -> VALUES('CK_MH_040000','CK','Help','Help','Help','Help','40000','/help',NULL,NULL,'A',NOW(),'SYS',NOW(),'SYS'); | N8: =CONCATENATE(L8,M8) -> INSERT INTO T_CORE_MENU_EX (MENU_ID, MENU_APPS_CODE, MENU_GROUP_LABEL, MENU_GROUP_LABEL_OTH, MENU_NAME, MENU_NAME_OTH, MENU_SEQ, MENU_PATH, MENU_ICON, MENU_PARENT, MENU_STATUS, MENU_DT_CREATE, MENU_UID_CREATE, MENU_DT_LUPD, MENU_UID_LUPD) VALUES('CK_MH_040000','CK','Help','Help','Help','Help','40000','/help',NULL,NULL,'A',NOW(),'SYS',NOW(),'SYS');
A9: CK_MT_050000 | B9: CK | C9: Master Table | D9: Master Table | E9: Master Table | F9: Master Table | G9: 50000 | H9: NULL | I9: table_view | J9: NULL | K9: A | L9: =CONCATENATE("INSERT INTO T_CORE_MENU_EX (MENU_ID, MENU_APPS_CODE, MENU_GROUP_LABEL, MENU_GROUP_LABEL_OTH, MENU_NAME, MENU_NAME_OTH, MENU_SEQ, MENU_PATH, MENU_ICON, MENU_PARENT, MENU_STATUS, MENU_DT_CREATE, MENU_UID_CREATE, MENU_DT_LUPD, MENU_UID_LUPD) ") -> INSERT INTO T_CORE_MENU_EX (MENU_ID, MENU_APPS_CODE, MENU_GROUP_LABEL, MENU_GROUP_LABEL_OTH, MENU_NAME, MENU_NAME_OTH, MENU_SEQ, MENU_PATH, MENU_ICON, MENU_PARENT, MENU_STATUS, MENU_DT_CREATE, MENU_UID_CREATE, MENU_DT_LUPD, MENU_UID_LUPD) | M9: =CONCATENATE(" VALUES('",A9,"','",B9,"','",C9,"','",D9,"','",E9,"','",F9,"',",IF(G9="NULL","NULL",CONCATENATE("'",G9,"'")),",",IF(H9="NULL","NULL",CONCATENATE("'",H9,"'")),",",IF(I9="NULL","NULL",CONCATENATE("'",I9,"'")),",",IF(J9="NULL","NULL",CONCATENATE("'",J9,"'")),",'A',NOW(),'SYS',NOW(),'SYS');") -> VALUES('CK_MT_050000','CK','Master Table','Master Table','Master Table','Master Table','50000',NULL,'table_view',NULL,'A',NOW(),'SYS',NOW(),'SYS'); | N9: =CONCATENATE(L9,M9) -> INSERT INTO T_CORE_MENU_EX (MENU_ID, MENU_APPS_CODE, MENU_GROUP_LABEL, MENU_GROUP_LABEL_OTH, MENU_NAME, MENU_NAME_OTH, MENU_SEQ, MENU_PATH, MENU_ICON, MENU_PARENT, MENU_STATUS, MENU_DT_CREATE, MENU_UID_CREATE, MENU_DT_LUPD, MENU_UID_LUPD) VALUES('CK_MT_050000','CK','Master Table','Master Table','Master Table','Master Table','50000',NULL,'table_view',NULL,'A',NOW(),'SYS',NOW(),'SYS');
A10: CK_MT_050100 | B10: CK | E10: Announcement Type | F10: Announcement Type | G10: 50100 | H10: /configuration/announcementType/list | I10: NULL | J10: CK_MT_050000 | K10: A | L10: =CONCATENATE("INSERT INTO T_CORE_MENU_EX (MENU_ID, MENU_APPS_CODE, MENU_GROUP_LABEL, MENU_GROUP_LABEL_OTH, MENU_NAME, MENU_NAME_OTH, MENU_SEQ, MENU_PATH, MENU_ICON, MENU_PARENT, MENU_STATUS, MENU_DT_CREATE, MENU_UID_CREATE, MENU_DT_LUPD, MENU_UID_LUPD) ") -> INSERT INTO T_CORE_MENU_EX (MENU_ID, MENU_APPS_CODE, MENU_GROUP_LABEL, MENU_GROUP_LABEL_OTH, MENU_NAME, MENU_NAME_OTH, MENU_SEQ, MENU_PATH, MENU_ICON, MENU_PARENT, MENU_STATUS, MENU_DT_CREATE, MENU_UID_CREATE, MENU_DT_LUPD, MENU_UID_LUPD) | M10: =CONCATENATE(" VALUES('",A10,"','",B10,"','",C10,"','",D10,"','",E10,"','",F10,"',",IF(G10="NULL","NULL",CONCATENATE("'",G10,"'")),",",IF(H10="NULL","NULL",CONCATENATE("'",H10,"'")),",",IF(I10="NULL","NULL",CONCATENATE("'",I10,"'")),",",IF(J10="NULL","NULL",CONCATENATE("'",J10,"'")),",'A',NOW(),'SYS',NOW(),'SYS');") -> VALUES('CK_MT_050100','CK','','','Announcement Type','Announcement Type','50100','/configuration/announcementType/list',NULL,'CK_MT_050000','A',NOW(),'SYS',NOW(),'SYS'); | N10: =CONCATENATE(L10,M10) -> INSERT INTO T_CORE_MENU_EX (MENU_ID, MENU_APPS_CODE, MENU_GROUP_LABEL, MENU_GROUP_LABEL_OTH, MENU_NAME, MENU_NAME_OTH, MENU_SEQ, MENU_PATH, MENU_ICON, MENU_PARENT, MENU_STATUS, MENU_DT_CREATE, MENU_UID_CREATE, MENU_DT_LUPD, MENU_UID_LUPD) VALUES('CK_MT_050100','CK','','','Announcement Type','Announcement Type','50100','/configuration/announcementType/list',NULL,'CK_MT_050000','A',NOW(),'SYS',NOW(),'SYS');
