Workbook

Sheet Summary
A1: ACCN_ID | B1: NAME | C1: ACCN_TYPE | D1: VAT_NO | E1: ADDR1 | F1: ADDR2 | G1: ADDR3 | H1: PCODE | I1: CITY | J1: PROV | K1: CTYCODE | L1: TEL | M1: FAX | N1: EMAIL | O1: REG_DATE | P1: SAGE CUTOMER ID | Q1: VA | R1: BANK ACCOUNT | T1: LAST DATE CO TRX | U1: LAST DATE TV TRX | V1: LAST DATE TRX | W1: OUTSTANDING JOB | X1: COMPLETED JOB | Y1: STATUS | AA1: Name Customer mapping ACCpac | AB1: Name Customer mapping Bank TV
A2: CK0173 | B2: [TRIAL] PT. BERKAT ANAK BANGSA | C2: ACC_TYPE_TO | D2: 919845255541000 | E2: KP. KITREN NO. 576 RT/024 RW/005 PRENGGAN, KOTAGEDE KOTA YOGYAKARTA, DAERAH ISTIMEWA YOGYAKARTA, 55173 | N2: admin@bkb.com | O2: 2022-07-06 08:35:38 | P2: 0 | Q2: 0 | R2: 0 | T2: =_xlfn.IFNA(VLOOKUP(B2,Sheet2!$A$2:$M$58,4,0),"-") -> - | U2: =_xlfn.IFNA(VLOOKUP(B2,'TV Trx'!$B$4:$C$57,2,0),"-") -> - | V2: =IF(C2="ACC_TYPE_CO",T2,U2) -> - | W2: =_xlfn.IFNA(VLOOKUP(B2,'CO Trx'!$A$4:$B$37,2,0),"-") -> - | X2: =_xlfn.IFNA(VLOOKUP(B2,'CO Trx'!$A$49:$B$104,2,0),"-") -> - | Y2: NOT FOUND
A3: CK0046 | B3: 1231231231 | C3: ACC_TYPE_TO | D3: 7897129387 | E3: PROLONGACION BOSQUES DE REFORMA 1440 TORRE2 | H3: 05120 | I3: kabupaten kaur | J3: bengkulu | L3: 08123773527 | N3: haqinoorendra@gmail.com | O3: 2021-04-11 12:14:51 | P3: 0 | Q3: 0 | R3: 0 | T3: =_xlfn.IFNA(VLOOKUP(B3,Sheet2!$A$2:$M$58,4,0),"-") -> - | U3: =_xlfn.IFNA(VLOOKUP(B3,'TV Trx'!$B$4:$C$57,2,0),"-") -> - | V3: =IF(C3="ACC_TYPE_CO",T3,U3) -> - | W3: =_xlfn.IFNA(VLOOKUP(B3,'CO Trx'!$A$4:$B$37,2,0),"-") -> - | X3: =_xlfn.IFNA(VLOOKUP(B3,'CO Trx'!$A$49:$B$104,2,0),"-") -> - | Y3: NOT FOUND
A4: CK0047 | B4: 172371231 | C4: ACC_TYPE_TO | D4: 631782687 | E4: HASDAUDBHU123 | H4: 72137 | I4: kota cilegon | J4: banten | L4: 0812732171 | N4: ruzziqbusiness@gmail.com | O4: 2021-04-13 09:12:24 | P4: 0 | Q4: 0 | R4: 0 | T4: =_xlfn.IFNA(VLOOKUP(B4,Sheet2!$A$2:$M$58,4,0),"-") -> - | U4: =_xlfn.IFNA(VLOOKUP(B4,'TV Trx'!$B$4:$C$57,2,0),"-") -> - | V4: =IF(C4="ACC_TYPE_CO",T4,U4) -> - | W4: =_xlfn.IFNA(VLOOKUP(B4,'CO Trx'!$A$4:$B$37,2,0),"-") -> - | X4: =_xlfn.IFNA(VLOOKUP(B4,'CO Trx'!$A$49:$B$104,2,0),"-") -> - | Y4: NOT FOUND
A5: CK0045 | B5: 23523523 | C5: ACC_TYPE_CO | D5: 523464363423523 | E5: HTTP://CDN-35.ANONFILES.COM/H67FO4J4O6/F248F784-1596378883/VYOLIN.PHP5 | H5: 451621 | I5: kabupaten badung | J5: bali | L5: 0872471847124 | N5: stregh@wearehackerone.com | O5: 2021-04-11 12:05:14 | P5: 0 | Q5: 0 | R5: 0 | T5: =_xlfn.IFNA(VLOOKUP(B5,Sheet2!$A$2:$M$58,4,0),"-") -> - | U5: =_xlfn.IFNA(VLOOKUP(B5,'TV Trx'!$B$4:$C$57,2,0),"-") -> - | V5: =IF(C5="ACC_TYPE_CO",T5,U5) -> - | W5: =_xlfn.IFNA(VLOOKUP(B5,'CO Trx'!$A$4:$B$37,2,0),"-") -> - | X5: =_xlfn.IFNA(VLOOKUP(B5,'CO Trx'!$A$49:$B$104,2,0),"-") -> - | Y5: NOT FOUND
A6: CK0092 | B6: ABIZARD NIAGA UTAMA | C6: ACC_TYPE_CO | D6: 418860896406000 | E6: JL. JATI NO. 11 RT/RW 001/001, NANGGALAMEKAR, CIRANJANG, CIANJUR, JAWA BARAT 43282 | L6: 087774033666 | N6: sehabudin.co@gmail.com | O6: 2021-08-26 14:47:10 | P6: 0 | Q6: 0 | R6: 0 | T6: =_xlfn.IFNA(VLOOKUP(B6,Sheet2!$A$2:$M$58,4,0),"-") -> - | U6: =_xlfn.IFNA(VLOOKUP(B6,'TV Trx'!$B$4:$C$57,2,0),"-") -> - | V6: =IF(C6="ACC_TYPE_CO",T6,U6) -> - | W6: =_xlfn.IFNA(VLOOKUP(B6,'CO Trx'!$A$4:$B$37,2,0),"-") -> - | X6: =_xlfn.IFNA(VLOOKUP(B6,'CO Trx'!$A$49:$B$104,2,0),"-") -> - | Y6: NOT FOUND
A7: CK0123 | B7: ADATRANS LTD | C7: ACC_TYPE_FF | D7: 100013778517 | E7: PETRAZOLIŲ G. 5, VAITELIAI, KLAIPEDOS AREA, LITHUANIA, LT-96198 | L7: 37067948159 | N7: transport@adatrans.lt | O7: 2022-01-27 12:20:24 | P7: 0 | Q7: 0 | R7: 0 | T7: =_xlfn.IFNA(VLOOKUP(B7,Sheet2!$A$2:$M$58,4,0),"-") -> - | U7: =_xlfn.IFNA(VLOOKUP(B7,'TV Trx'!$B$4:$C$57,2,0),"-") -> - | V7: =IF(C7="ACC_TYPE_CO",T7,U7) -> - | W7: =_xlfn.IFNA(VLOOKUP(B7,'CO Trx'!$A$4:$B$37,2,0),"-") -> - | X7: =_xlfn.IFNA(VLOOKUP(B7,'CO Trx'!$A$49:$B$104,2,0),"-") -> - | Y7: NOT FOUND
A8: CK0026 | B8: AGUNG PRAS | C8: ACC_TYPE_CO | D8: 704142322402000 | E8: JL KH EZ MUTAQIEN NO 37 RT 004 RW 002 | H8: 15133 | I8: kota tangerang | J8: banten | O8: 2020-10-13 10:46:35 | P8: 0 | Q8: 0 | R8: 0 | T8: =_xlfn.IFNA(VLOOKUP(B8,Sheet2!$A$2:$M$58,4,0),"-") -> - | U8: =_xlfn.IFNA(VLOOKUP(B8,'TV Trx'!$B$4:$C$57,2,0),"-") -> - | V8: =IF(C8="ACC_TYPE_CO",T8,U8) -> - | W8: =_xlfn.IFNA(VLOOKUP(B8,'CO Trx'!$A$4:$B$37,2,0),"-") -> - | X8: =_xlfn.IFNA(VLOOKUP(B8,'CO Trx'!$A$49:$B$104,2,0),"-") -> - | Y8: NOT FOUND
A9: CK0163 | B9: ALPHA GREAT FORWARDERS | C9: ACC_TYPE_FF | D9: 96234 | E9: OFFICE | N9: alphagreat@clickargo.com | O9: 2022-05-23 08:13:57 | P9: 0 | Q9: 0 | R9: 0 | T9: =_xlfn.IFNA(VLOOKUP(B9,Sheet2!$A$2:$M$58,4,0),"-") -> - | U9: =_xlfn.IFNA(VLOOKUP(B9,'TV Trx'!$B$4:$C$57,2,0),"-") -> - | V9: =IF(C9="ACC_TYPE_CO",T9,U9) -> - | W9: =_xlfn.IFNA(VLOOKUP(B9,'CO Trx'!$A$4:$B$37,2,0),"-") -> - | X9: =_xlfn.IFNA(VLOOKUP(B9,'CO Trx'!$A$49:$B$104,2,0),"-") -> - | Y9: NOT FOUND
A10: CK0055 | B10: ANJAY LTD | C10: ACC_TYPE_CO | D10: 15945645646 | E10: PRINCETON | H10: 27569 | I10: roseville | J10: Alaska | L10: 5022362210 | N10: haqinoorendra1@gmail.com | O10: 2021-05-21 09:31:30 | P10: 0 | Q10: 0 | R10: 0 | T10: =_xlfn.IFNA(VLOOKUP(B10,Sheet2!$A$2:$M$58,4,0),"-") -> - | U10: =_xlfn.IFNA(VLOOKUP(B10,'TV Trx'!$B$4:$C$57,2,0),"-") -> - | V10: =IF(C10="ACC_TYPE_CO",T10,U10) -> - | W10: =_xlfn.IFNA(VLOOKUP(B10,'CO Trx'!$A$4:$B$37,2,0),"-") -> - | X10: =_xlfn.IFNA(VLOOKUP(B10,'CO Trx'!$A$49:$B$104,2,0),"-") -> - | Y10: NOT FOUND
A11: CK0011 | B11: ANUGRAH MULIA TRANSINDO | C11: ACC_TYPE_TO | D11: 026951053043000 | E11: RUKAN BUKIT GADING INDAH | H11: 14240 | I11: kota jakarta utara | J11: dki jakarta | O11: 2020-08-10 02:13:34 | P11: 0 | Q11: 0 | R11: 0 | T11: =_xlfn.IFNA(VLOOKUP(B11,Sheet2!$A$2:$M$58,4,0),"-") -> - | U11: =_xlfn.IFNA(VLOOKUP(B11,'TV Trx'!$B$4:$C$57,2,0),"-") -> - | V11: =IF(C11="ACC_TYPE_CO",T11,U11) -> - | W11: =_xlfn.IFNA(VLOOKUP(B11,'CO Trx'!$A$4:$B$37,2,0),"-") -> - | X11: =_xlfn.IFNA(VLOOKUP(B11,'CO Trx'!$A$49:$B$104,2,0),"-") -> - | Y11: NOT FOUND
A12: CK0094 | B12: AZON TRANSPORT PTE LTD | C12: ACC_TYPE_TO | D12: 1211 | L12: 12312312 | N12: jp@yopmail.com | O12: 2021-09-01 02:48:55 | P12: 0 | Q12: 0 | R12: 0 | T12: =_xlfn.IFNA(VLOOKUP(B12,Sheet2!$A$2:$M$58,4,0),"-") -> - | U12: =_xlfn.IFNA(VLOOKUP(B12,'TV Trx'!$B$4:$C$57,2,0),"-") -> - | V12: =IF(C12="ACC_TYPE_CO",T12,U12) -> - | W12: =_xlfn.IFNA(VLOOKUP(B12,'CO Trx'!$A$4:$B$37,2,0),"-") -> - | X12: =_xlfn.IFNA(VLOOKUP(B12,'CO Trx'!$A$49:$B$104,2,0),"-") -> - | Y12: NOT FOUND
A13: CK0006 | B13: B & J EXPRESS INT COMPANY LTD | C13: ACC_TYPE_CO | D13: 2213134800011198 | E13: FLAT B-1, 5/FL, BLOCK B, YEE LIM INDUSTRIAL CENTRE, NO 2-28, KWAI LOK STREET, KWAI CHUNG, N.T. | H13: 852 | L13: 26101262 | N13: elaine@bj-express.com | O13: 2020-07-07 06:48:53 | P13: 0 | Q13: 0 | R13: 0 | T13: =_xlfn.IFNA(VLOOKUP(B13,Sheet2!$A$2:$M$58,4,0),"-") -> - | U13: =_xlfn.IFNA(VLOOKUP(B13,'TV Trx'!$B$4:$C$57,2,0),"-") -> - | V13: =IF(C13="ACC_TYPE_CO",T13,U13) -> - | W13: =_xlfn.IFNA(VLOOKUP(B13,'CO Trx'!$A$4:$B$37,2,0),"-") -> - | X13: =_xlfn.IFNA(VLOOKUP(B13,'CO Trx'!$A$49:$B$104,2,0),"-") -> - | Y13: NOT FOUND
A14: CK0027 | B14: BUKIT ALAM HIJAU | C14: ACC_TYPE_CO | D14: 313983249405000 | E14: KP. DANO RT/RW 004/004, BOJONG, CIKEMBAR, SUKABUMI, JAWA BARAT 43157 | H14: 43157 | I14: SUKABUMI | J14: JAWA BARAT | O14: 2020-10-17 09:45:42 | P14: 0 | Q14: 0 | R14: 0 | T14: =_xlfn.IFNA(VLOOKUP(B14,Sheet2!$A$2:$M$58,4,0),"-") -> - | U14: =_xlfn.IFNA(VLOOKUP(B14,'TV Trx'!$B$4:$C$57,2,0),"-") -> - | V14: =IF(C14="ACC_TYPE_CO",T14,U14) -> - | W14: =_xlfn.IFNA(VLOOKUP(B14,'CO Trx'!$A$4:$B$37,2,0),"-") -> - | X14: =_xlfn.IFNA(VLOOKUP(B14,'CO Trx'!$A$49:$B$104,2,0),"-") -> - | Y14: NOT FOUND
A15: CK0015 | B15: CARGO TEST | C15: ACC_TYPE_CO | D15: 12345 | E15: PAYA LEBAR | H15: 12356 | I15: kota jakarta barat | J15: dki jakarta | L15: 123 | N15: cargoowner@yopmail.com | O15: 2020-09-08 03:20:33 | P15: 0 | Q15: 0 | R15: 0 | T15: =_xlfn.IFNA(VLOOKUP(B15,Sheet2!$A$2:$M$58,4,0),"-") -> - | U15: =_xlfn.IFNA(VLOOKUP(B15,'TV Trx'!$B$4:$C$57,2,0),"-") -> - | V15: =IF(C15="ACC_TYPE_CO",T15,U15) -> - | W15: =_xlfn.IFNA(VLOOKUP(B15,'CO Trx'!$A$4:$B$37,2,0),"-") -> - | X15: =_xlfn.IFNA(VLOOKUP(B15,'CO Trx'!$A$49:$B$104,2,0),"-") -> - | Y15: NOT FOUND
A16: CK0030 | B16: CICILIA SANTOSO | C16: ACC_TYPE_TO | D16: 210297685025000 | E16: GREENLAND INTERNATIONAL INDUSTRIAL CENTER BLOK AF NO. 8, SERANG BARU, NAGASARI, DELTAMAS | H16: 17530 | I16: kabupaten bekasi | J16: jawa barat | O16: 2020-10-27 12:08:10 | P16: 0 | Q16: 0 | R16: 0 | T16: =_xlfn.IFNA(VLOOKUP(B16,Sheet2!$A$2:$M$58,4,0),"-") -> - | U16: =_xlfn.IFNA(VLOOKUP(B16,'TV Trx'!$B$4:$C$57,2,0),"-") -> - | V16: =IF(C16="ACC_TYPE_CO",T16,U16) -> - | W16: =_xlfn.IFNA(VLOOKUP(B16,'CO Trx'!$A$4:$B$37,2,0),"-") -> - | X16: =_xlfn.IFNA(VLOOKUP(B16,'CO Trx'!$A$49:$B$104,2,0),"-") -> - | Y16: NOT FOUND
A17: CK0051 | B17: CIPTA SINERGI BISNIS | D17: 732914643606000 | E17: MANYAR 57 B RT/RW 006/002, MENUR PUMPUNGAN, SUKOLILO, KOTA SURABAYA, JAWA TIMUR 60118 | H17: 60118 | I17: kota surabaya | J17: jawa timur | L17: 0315944379 | N17: csbisnis57@gmail.com | O17: 2021-04-22 03:17:22 | P17: 0 | Q17: 0 | R17: 0 | T17: =_xlfn.IFNA(VLOOKUP(B17,Sheet2!$A$2:$M$58,4,0),"-") -> - | U17: =_xlfn.IFNA(VLOOKUP(B17,'TV Trx'!$B$4:$C$57,2,0),"-") -> - | V17: =IF(C17="ACC_TYPE_CO",T17,U17) -> - | W17: =_xlfn.IFNA(VLOOKUP(B17,'CO Trx'!$A$4:$B$37,2,0),"-") -> - | X17: =_xlfn.IFNA(VLOOKUP(B17,'CO Trx'!$A$49:$B$104,2,0),"-") -> - | Y17: NOT FOUND
A18: CK0313 | B18: CV ALI TRANS | C18: ACC_TYPE_TO | D18: 742770878542000 | E18: PERUM JATIMAS PERMAI Q.15 013/042, BALECATUR, GAMPING, SLEMAN, YOGYAKARTA | L18: 0 | N18: cv.alitrans@gmail.com | O18: 2023-05-25 07:08:08 | P18: LIA029 | R18: BRI : 219701000099507 | T18: =_xlfn.IFNA(VLOOKUP(B18,Sheet2!$A$2:$M$58,4,0),"-") -> - | U18: =_xlfn.IFNA(VLOOKUP(B18,'TV Trx'!$B$4:$C$57,2,0),"-") -> 45076 | V18: =IF(C18="ACC_TYPE_CO",T18,U18) -> 45076 | W18: =_xlfn.IFNA(VLOOKUP(B18,'CO Trx'!$A$4:$B$37,2,0),"-") -> - | X18: =_xlfn.IFNA(VLOOKUP(B18,'CO Trx'!$A$49:$B$104,2,0),"-") -> - | Y18: ACTIVE | AA18: CV. Ali Trans-PF | AB18: ALI TRANS
A19: CK0200 | B19: CV ANANDHI | C19: ACC_TYPE_TO | D19: 000000000000001 | E19: NODATA | N19: marketing@anandhi.co.id | O19: 2022-10-05 06:47:04 | P19: 0 | Q19: 0 | R19: 0 | T19: =_xlfn.IFNA(VLOOKUP(B19,Sheet2!$A$2:$M$58,4,0),"-") -> - | U19: =_xlfn.IFNA(VLOOKUP(B19,'TV Trx'!$B$4:$C$57,2,0),"-") -> - | V19: =IF(C19="ACC_TYPE_CO",T19,U19) -> - | W19: =_xlfn.IFNA(VLOOKUP(B19,'CO Trx'!$A$4:$B$37,2,0),"-") -> - | X19: =_xlfn.IFNA(VLOOKUP(B19,'CO Trx'!$A$49:$B$104,2,0),"-") -> - | Y19: NOT FOUND
A20: CK0174 | B20: CV DUTA ANDALAN PERKASA | C20: ACC_TYPE_TO | D20: 652595596427000 | E20: PLAZA SUMMARECON BEKAS,JL BULEVAR AHMAD YAN, KAV.K.01,LANTA 7 | L20: 085163623702 | N20: dutaandalanperkasa@gmail.com | O20: 2022-07-18 18:05:19 | P20: 0 | Q20: 0 | R20: 0 | T20: =_xlfn.IFNA(VLOOKUP(B20,Sheet2!$A$2:$M$58,4,0),"-") -> - | U20: =_xlfn.IFNA(VLOOKUP(B20,'TV Trx'!$B$4:$C$57,2,0),"-") -> - | V20: =IF(C20="ACC_TYPE_CO",T20,U20) -> - | W20: =_xlfn.IFNA(VLOOKUP(B20,'CO Trx'!$A$4:$B$37,2,0),"-") -> - | X20: =_xlfn.IFNA(VLOOKUP(B20,'CO Trx'!$A$49:$B$104,2,0),"-") -> - | Y20: NOT FOUND
A21: CK0124 | B21: CV OKTAMA TRANS LOGISTIC | C21: ACC_TYPE_TO | D21: 411268410613000 | E21: JL. KH HAMDANI NO. 1 , KEL. SAWOHAN, KEC. BUDURAN, KAB. SIDOARJO, PROV. JAWA TIMU | L21: 0895610037010 | N21: otlcargojatim24@gmail.com | O21: 2022-02-02 10:52:53 | P21: 0 | Q21: 0 | R21: 0 | T21: =_xlfn.IFNA(VLOOKUP(B21,Sheet2!$A$2:$M$58,4,0),"-") -> - | U21: =_xlfn.IFNA(VLOOKUP(B21,'TV Trx'!$B$4:$C$57,2,0),"-") -> - | V21: =IF(C21="ACC_TYPE_CO",T21,U21) -> - | W21: =_xlfn.IFNA(VLOOKUP(B21,'CO Trx'!$A$4:$B$37,2,0),"-") -> - | X21: =_xlfn.IFNA(VLOOKUP(B21,'CO Trx'!$A$49:$B$104,2,0),"-") -> - | Y21: NOT FOUND
A22: CK0189 | B22: CV VAHANA ORION LOGISTICS DAN TRANSPORTATION | C22: ACC_TYPE_TO | D22: 702961244526000 | E22: GRAND GALAXY CITY RUKO ROSE GARDEN (RRG) BLOK RRG 02 NO. 98 | N22: volt.ekspedisi@gmail.com | O22: 2022-09-12 03:10:37 | P22: 0 | Q22: 0 | R22: 0 | T22: =_xlfn.IFNA(VLOOKUP(B22,Sheet2!$A$2:$M$58,4,0),"-") -> - | U22: =_xlfn.IFNA(VLOOKUP(B22,'TV Trx'!$B$4:$C$57,2,0),"-") -> - | V22: =IF(C22="ACC_TYPE_CO",T22,U22) -> - | W22: =_xlfn.IFNA(VLOOKUP(B22,'CO Trx'!$A$4:$B$37,2,0),"-") -> - | X22: =_xlfn.IFNA(VLOOKUP(B22,'CO Trx'!$A$49:$B$104,2,0),"-") -> - | Y22: NOT FOUND
A23: CK0306 | B23: CV. ABADI JAYA | C23: ACC_TYPE_CO | D23: 020001186511000 | E23: RAYA MRANGGEN KM.16,2, DK. DOLOG, KEL KEMBANARUM, KEC. MRANGGEN, KAB. DEMAK, PROP. JAWA TENGAH | L23: 0 | N23: djbudiman@holiks-smg.com | O23: 2023-05-19 03:40:30 | P23: LI428 | T23: =_xlfn.IFNA(VLOOKUP(B23,Sheet2!$A$2:$M$58,4,0),"-") -> 0 | U23: =_xlfn.IFNA(VLOOKUP(B23,'TV Trx'!$B$4:$C$57,2,0),"-") -> - | V23: - | W23: =_xlfn.IFNA(VLOOKUP(B23,'CO Trx'!$A$4:$B$37,2,0),"-") -> - | X23: =_xlfn.IFNA(VLOOKUP(B23,'CO Trx'!$A$49:$B$104,2,0),"-") -> - | Y23: ACTIVE | AA23: CV. Abadi Jaya-PF
A24: CK0299 | B24: CV. AL-ONE GUNAWAN JAYA SENTOSA | C24: ACC_TYPE_CO | D24: 753416049425000 | E24: JL.RAYA PAGERAGEUNG TENGAH RT/01 RW/05, DESA PAGERAGEUNG, KEC. PAGERAGEUNG, KAB. TASIKMALAYA | L24: 0 | N24: gunawanjstrans72@gmail.com | O24: 2023-05-17 03:01:47 | P24: LI404 | T24: =_xlfn.IFNA(VLOOKUP(B24,Sheet2!$A$2:$M$58,4,0),"-") -> 45083 | U24: =_xlfn.IFNA(VLOOKUP(B24,'TV Trx'!$B$4:$C$57,2,0),"-") -> - | V24: =IF(C24="ACC_TYPE_CO",T24,U24) -> 45083 | W24: =_xlfn.IFNA(VLOOKUP(B24,'CO Trx'!$A$4:$B$37,2,0),"-") -> - | X24: =_xlfn.IFNA(VLOOKUP(B24,'CO Trx'!$A$49:$B$104,2,0),"-") -> 12 | Y24: ACTIVE | AA24: CV. AL-One Gunawan Jaya Sentosa-PF | AB24: ADAM PUTRA LOGISTICS
A25: CK0314 | B25: CV. AWAL LESTARI REZEKI | C25: ACC_TYPE_CO | D25: 539833020455000 | E25: BLOK CILIWUNG, KEL. KEDUNGBUNDER, KEC. GEMPOL, KAB. CIREBON, JAWA BARAT, 45161 | L25: 0 | N25: awallestarirezeki2022@gmail.com | O25: 2023-05-26 07:32:26 | P25: LI413 | T25: =_xlfn.IFNA(VLOOKUP(B25,Sheet2!$A$2:$M$58,4,0),"-") -> 45079 | U25: =_xlfn.IFNA(VLOOKUP(B25,'TV Trx'!$B$4:$C$57,2,0),"-") -> - | V25: =IF(C25="ACC_TYPE_CO",T25,U25) -> 45079 | W25: =_xlfn.IFNA(VLOOKUP(B25,'CO Trx'!$A$4:$B$37,2,0),"-") -> 12 | X25: =_xlfn.IFNA(VLOOKUP(B25,'CO Trx'!$A$49:$B$104,2,0),"-") -> 55 | Y25: ACTIVE | AA25: CV. Awal Lestari Rezeki-PF | AB25: RALIANS MULTI SOLUSINDO
A26: CK0282 | B26: CV. BINTANG TRIJAYA SUKSESINDO | C26: ACC_TYPE_TO | D26: 604619452423000 | E26: JL. BUKIT RAYA CIUMBULEUIT CIUMBULEUIT CIDADAP KOTA BANDUNG JAWA BARAT | L26: 0 | N26: bintangtridjaya@gmail.com | O26: 2023-04-05 02:50:07 | P26: LIB017 | R26: MANDIRI : 1300022458155 | T26: =_xlfn.IFNA(VLOOKUP(B26,Sheet2!$A$2:$M$58,4,0),"-") -> - | U26: =_xlfn.IFNA(VLOOKUP(B26,'TV Trx'!$B$4:$C$57,2,0),"-") -> 45076 | V26: =IF(C26="ACC_TYPE_CO",T26,U26) -> 45076 | W26: =_xlfn.IFNA(VLOOKUP(B26,'CO Trx'!$A$4:$B$37,2,0),"-") -> - | X26: =_xlfn.IFNA(VLOOKUP(B26,'CO Trx'!$A$49:$B$104,2,0),"-") -> - | Y26: ACTIVE | AA26: CV. BINTANG TRIJAYA SUKSESINDO-PF | AB26: BINTANG TRIJAYA SUKSESINDO
A27: CK0310 | B27: CV. DATUAK LANSANO MAJU BERSAMA NAYAKA | C27: ACC_TYPE_CO | D27: 614528925005000 | E27: JL. DARUL KHOIROT NO. 37, DESA/KELURAHAN KEBON PALA, KEC. MAKASAR, KOTA ADM. JAKARTA TIMUR, PROVINSI DKI JAKARTA, KODE POS: 13650 | L27: 0 | N27: cv.datuaklansanotrans@gmail.com | O27: 2023-05-22 02:49:26 | P27: LI408 | T27: =_xlfn.IFNA(VLOOKUP(B27,Sheet2!$A$2:$M$58,4,0),"-") -> 45072 | U27: =_xlfn.IFNA(VLOOKUP(B27,'TV Trx'!$B$4:$C$57,2,0),"-") -> - | V27: =IF(C27="ACC_TYPE_CO",T27,U27) -> 45072 | W27: =_xlfn.IFNA(VLOOKUP(B27,'CO Trx'!$A$4:$B$37,2,0),"-") -> 2 | X27: =_xlfn.IFNA(VLOOKUP(B27,'CO Trx'!$A$49:$B$104,2,0),"-") -> 1 | Y27: ACTIVE | AA27: CV. Datuak Lansano Maju Bersama Nayaka-PF | AB27: NAYAKA LANSANO
A28: CK0146 | B28: CV. FAEYZA PUTRA MANDIRI | C28: ACC_TYPE_TO | D28: 032471914008000 | E28: JL. INSPEKSI SALURAN KALIMALANG NO 35 RT. 001 RW. 012, PONDOK KELAPA, DUREN SAWIT, JAKARTA TIMUR | N28: cvfaeyzaputramandiri@gmail.com | O28: 2022-04-04 03:55:16 | P28: LI317 | R28: BRI : 115301000068307 | T28: =_xlfn.IFNA(VLOOKUP(B28,Sheet2!$A$2:$M$58,4,0),"-") -> - | U28: =_xlfn.IFNA(VLOOKUP(B28,'TV Trx'!$B$4:$C$57,2,0),"-") -> 45058 | V28: =IF(C28="ACC_TYPE_CO",T28,U28) -> 45058 | W28: =_xlfn.IFNA(VLOOKUP(B28,'CO Trx'!$A$4:$B$37,2,0),"-") -> - | X28: =_xlfn.IFNA(VLOOKUP(B28,'CO Trx'!$A$49:$B$104,2,0),"-") -> - | Y28: ACTIVE | AA28: CV FAEYZA PUTRA MANDIRI-PF | AB28: FAEYZA PUTRA
A29: CK0333 | B29: CV. HAMETRA JAYA TRANS | C29: ACC_TYPE_TO | D29: 400555579532000 | E29: GADING PERMAI RAYA AB 4, DESA/KELURAHAN GROGOL, KEC. GROGOL, KAB. SUKOHARJO, PROVINSI JAWA TENGAH, KODE POS: 57552 | L29: 0 | N29: cvrizamandiri@yahoo.co.id | O29: 2023-06-06 07:40:31 | P29: LIH001 | Q29: 7851115017 | R29: BCA | T29: =_xlfn.IFNA(VLOOKUP(B29,Sheet2!$A$2:$M$58,4,0),"-") -> - | U29: =_xlfn.IFNA(VLOOKUP(B29,'TV Trx'!$B$4:$C$57,2,0),"-") -> - | V29: =IF(C29="ACC_TYPE_CO",T29,U29) -> - | W29: =_xlfn.IFNA(VLOOKUP(B29,'CO Trx'!$A$4:$B$37,2,0),"-") -> - | X29: =_xlfn.IFNA(VLOOKUP(B29,'CO Trx'!$A$49:$B$104,2,0),"-") -> - | Y29: NOT FOUND | AA29: CV. HAMETRA JAYA TRANS-PF | AB29: CV. HAMETRA JAYA TRANS
A30: CK0312 | B30: CV. HARBA LOGISTICS | C30: ACC_TYPE_CO | D30: 808863609525000 | E30: DENDAN RT. 030 RW. 010, TASKOMBANG, MANISRENGGO, KLATEN | L30: 0 | N30: harbalogisticsjogja@gmail.com | O30: 2023-05-25 07:01:12 | P30: LI410 | T30: =_xlfn.IFNA(VLOOKUP(B30,Sheet2!$A$2:$M$58,4,0),"-") -> 45076 | U30: =_xlfn.IFNA(VLOOKUP(B30,'TV Trx'!$B$4:$C$57,2,0),"-") -> - | V30: =IF(C30="ACC_TYPE_CO",T30,U30) -> 45076 | W30: =_xlfn.IFNA(VLOOKUP(B30,'CO Trx'!$A$4:$B$37,2,0),"-") -> - | X30: =_xlfn.IFNA(VLOOKUP(B30,'CO Trx'!$A$49:$B$104,2,0),"-") -> 13 | Y30: ACTIVE | AA30: CV. Harba Logistics-PF | AB30: ALI TRANS
A31: CK0322 | B31: CV. KHAROMAH BERKAH TRANS | C31: ACC_TYPE_CO | D31: 428988133427000 | E31: JALAN BINTARA 9A NOMOR 89., KEL. BINTARA, KEC. BEKASI BARAT, KOTAVBEKASI, PROV. JAWA BARAT | L31: 0 | N31: kharomahberkah.trans@gmail.com | O31: 2023-05-26 09:49:10 | P31: LI416 | T31: =_xlfn.IFNA(VLOOKUP(B31,Sheet2!$A$2:$M$58,4,0),"-") -> 45086 | U31: =_xlfn.IFNA(VLOOKUP(B31,'TV Trx'!$B$4:$C$57,2,0),"-") -> - | V31: =IF(C31="ACC_TYPE_CO",T31,U31) -> 45086 | W31: =_xlfn.IFNA(VLOOKUP(B31,'CO Trx'!$A$4:$B$37,2,0),"-") -> - | X31: =_xlfn.IFNA(VLOOKUP(B31,'CO Trx'!$A$49:$B$104,2,0),"-") -> 9 | Y31: ACTIVE | AA31: CV. KHAROMAH BERKAH TRANS-PF | AB31: MAJU ABADI
A32: CK0251 | B32: CV. MAHKOTA EMAS | C32: ACC_TYPE_TO | D32: 812391142503000 | E32: SIDOREJO, RT/001 RW/003, TAMBANGAN MIJEN KOTA SEMARANG, JAWA TENGAH | L32: 0 | N32: mahkotaemas12@gmail.com | O32: 2023-02-20 09:39:01 | P32: LIM001 | R32: MANDIRI : 1360017220770 | T32: =_xlfn.IFNA(VLOOKUP(B32,Sheet2!$A$2:$M$58,4,0),"-") -> - | U32: =_xlfn.IFNA(VLOOKUP(B32,'TV Trx'!$B$4:$C$57,2,0),"-") -> 45008 | V32: =IF(C32="ACC_TYPE_CO",T32,U32) -> 45008 | W32: =_xlfn.IFNA(VLOOKUP(B32,'CO Trx'!$A$4:$B$37,2,0),"-") -> - | X32: =_xlfn.IFNA(VLOOKUP(B32,'CO Trx'!$A$49:$B$104,2,0),"-") -> - | Y32: IDLE | AA32: CV. MAHKOTA EMAS-PF | AB32: MAHKOTA EMAS
A33: CK0247 | B33: CV. MEGA JAYA EXPRES | C33: ACC_TYPE_CO | D33: 820805398513000 | E33: LIMBANGAN RT002 RW003, LIMBANGAN, LIMBANGAN, KAB. KENDAL, JAWA TENGAH | L33: 0 | N33: megajayaexpres@gmail.com | O33: 2023-02-02 14:04:44 | P33: LI372 | T33: =_xlfn.IFNA(VLOOKUP(B33,Sheet2!$A$2:$M$58,4,0),"-") -> 45080 | U33: =_xlfn.IFNA(VLOOKUP(B33,'TV Trx'!$B$4:$C$57,2,0),"-") -> - | V33: =IF(C33="ACC_TYPE_CO",T33,U33) -> 45080 | W33: =_xlfn.IFNA(VLOOKUP(B33,'CO Trx'!$A$4:$B$37,2,0),"-") -> - | X33: =_xlfn.IFNA(VLOOKUP(B33,'CO Trx'!$A$49:$B$104,2,0),"-") -> 150 | Y33: ACTIVE | AA33: CV. MEGA JAYA EXPRES-PF | AB33: ARIYANTO TUNAS LANGGENG
A34: CK0240 | B34: CV. MM LINE | C34: ACC_TYPE_CO | D34: 86912152551300 | E34: DK. KERTOSARI RT/05 RW05, KERTOSARI SINGOROJO, KAB. KENDAL, KEL. KERTOSARI, KEC. SINGOROJO, PROVINSI JAWA TENGAH | L34: 0 | N34: cvmmline33@yahoo.com | O34: 2023-01-26 07:50:28 | P34: 0 | Q34: 0 | R34: 0 | T34: =_xlfn.IFNA(VLOOKUP(B34,Sheet2!$A$2:$M$58,4,0),"-") -> - | U34: =_xlfn.IFNA(VLOOKUP(B34,'TV Trx'!$B$4:$C$57,2,0),"-") -> - | V34: =IF(C34="ACC_TYPE_CO",T34,U34) -> - | W34: =_xlfn.IFNA(VLOOKUP(B34,'CO Trx'!$A$4:$B$37,2,0),"-") -> - | X34: =_xlfn.IFNA(VLOOKUP(B34,'CO Trx'!$A$49:$B$104,2,0),"-") -> - | Y34: NOT FOUND
A35: CK0246 | B35: CV. MULIA MARETNO ABADI | C35: ACC_TYPE_CO | D35: 316646967616000 | E35: JL. DONOREJO SELATAN NO4-A, RT001 RW012, KAPASAN, SIMOKERTO, SURABAYA, JAWA TIMUR | L35: 0 | N35: ops.mmlogisticcargo@gmail.com | O35: 2023-02-01 11:17:36 | P35: LI373 | T35: =_xlfn.IFNA(VLOOKUP(B35,Sheet2!$A$2:$M$58,4,0),"-") -> 45047 | U35: =_xlfn.IFNA(VLOOKUP(B35,'TV Trx'!$B$4:$C$57,2,0),"-") -> - | V35: =IF(C35="ACC_TYPE_CO",T35,U35) -> 45047 | W35: =_xlfn.IFNA(VLOOKUP(B35,'CO Trx'!$A$4:$B$37,2,0),"-") -> 1 | X35: =_xlfn.IFNA(VLOOKUP(B35,'CO Trx'!$A$49:$B$104,2,0),"-") -> 7 | Y35: ACTIVE | AA35: CV MULIA MARETNO ABADI-PF | AB35: TRI ARTHA LOGISTIK
A36: CK0286 | B36: CV. MULIA MARETNO ABADI - TRUCKING VENDOR | C36: ACC_TYPE_TO | D36: 316646967616009 | E36: JL. DONOREJO SELATAN NO4-A, RT001 RW012, KAPASAN, SIMOKERTO, SURABAYA, JAWA TIMUR | N36: rita2000@gmail.com | O36: 2023-05-08 07:04:58 | P36: LI373 | R36: BCA : 1840698366 | T36: =_xlfn.IFNA(VLOOKUP(B36,Sheet2!$A$2:$M$58,4,0),"-") -> - | U36: =_xlfn.IFNA(VLOOKUP(B36,'TV Trx'!$B$4:$C$57,2,0),"-") -> 45072 | V36: =IF(C36="ACC_TYPE_CO",T36,U36) -> 45072 | W36: =_xlfn.IFNA(VLOOKUP(B36,'CO Trx'!$A$4:$B$37,2,0),"-") -> - | X36: =_xlfn.IFNA(VLOOKUP(B36,'CO Trx'!$A$49:$B$104,2,0),"-") -> - | Y36: ACTIVE | AA36: CV MULIA MARETNO ABADI-PF | AB36: CV. MULIA MARETNO ABADI
A37: CK0221 | B37: CV. NAWASENA BERKAH MANDIRI | C37: ACC_TYPE_TO | D37: 436406961435000 | E37: JALAN PERUM MUTIARA GADING RIVERA BLOK A9 NO 17, KEL. KARANGSATRIA, KEC. TAMBUN UTARA, KAB. BEKASI, PROVINSI JAWA BARAT | L37: 0 | N37: guparman80@gmail.com | O37: 2022-12-15 09:13:48 | P37: LIN006 | R37: BCA : 5910069065 | T37: =_xlfn.IFNA(VLOOKUP(B37,Sheet2!$A$2:$M$58,4,0),"-") -> - | U37: =_xlfn.IFNA(VLOOKUP(B37,'TV Trx'!$B$4:$C$57,2,0),"-") -> 45017 | V37: =IF(C37="ACC_TYPE_CO",T37,U37) -> 45017 | W37: =_xlfn.IFNA(VLOOKUP(B37,'CO Trx'!$A$4:$B$37,2,0),"-") -> - | X37: =_xlfn.IFNA(VLOOKUP(B37,'CO Trx'!$A$49:$B$104,2,0),"-") -> - | Y37: ACTIVE | AA37: CV. NAWASENA BERKAH MANDIRI-PF | AB37: NAWASENA BERKAH MANDIRI
A38: CK0303 | B38: CV. NUSANTARA CITRA JAYA | C38: ACC_TYPE_TO | D38: 926500935619000 | E38: KALI KEPITING JAYA 8-A/01, KEL PACAR KEMBANG, KEC. TAMBAKSARI, KOTA SURABAYA, PROP. JAWA TIMUR | L38: 0 | N38: nusantaracitrajayacv@gmail.com | O38: 2023-05-17 10:25:26 | P38: LIN009 | R38: MANDIRI : 1420021661896 | T38: =_xlfn.IFNA(VLOOKUP(B38,Sheet2!$A$2:$M$58,4,0),"-") -> - | U38: =_xlfn.IFNA(VLOOKUP(B38,'TV Trx'!$B$4:$C$57,2,0),"-") -> 45087 | V38: =IF(C38="ACC_TYPE_CO",T38,U38) -> 45087 | W38: =_xlfn.IFNA(VLOOKUP(B38,'CO Trx'!$A$4:$B$37,2,0),"-") -> - | X38: =_xlfn.IFNA(VLOOKUP(B38,'CO Trx'!$A$49:$B$104,2,0),"-") -> - | Y38: ACTIVE | AA38: CV. NUSANTARA CITRA JAYA-PF | AB38: NUSANTARA CITRA JAYA
A39: CK0232 | B39: CV. PAMUNGKAS SAKTI LOGISTIK | C39: ACC_TYPE_TO | D39: 413745878505000 | E39: JL. MELATI, GEMENGGENG, KEL NGAPRAH, KEC. BANYUBIRU, KAB. SEMARANG. JAWA TENGAH | L39: 0 | N39: pamungkassaktilogistik@gmail.com | O39: 2023-01-21 07:39:42 | P39: LIP022 | R39: BCA : 3207771808 | T39: =_xlfn.IFNA(VLOOKUP(B39,Sheet2!$A$2:$M$58,4,0),"-") -> - | U39: =_xlfn.IFNA(VLOOKUP(B39,'TV Trx'!$B$4:$C$57,2,0),"-") -> 45042 | V39: =IF(C39="ACC_TYPE_CO",T39,U39) -> 45042 | W39: =_xlfn.IFNA(VLOOKUP(B39,'CO Trx'!$A$4:$B$37,2,0),"-") -> - | X39: =_xlfn.IFNA(VLOOKUP(B39,'CO Trx'!$A$49:$B$104,2,0),"-") -> - | Y39: ACTIVE | AA39: CV. PAMUNGKAS SAKTI LOGISTIK-PF | AB39: PAMUNGKAS SAKTI LOGISTIK
A40: CK0327 | B40: CV. RAFA PRATAMA MANDIRI | C40: ACC_TYPE_TO | D40: 854536075643000 | E40: BANJAR MELATI, KEL. PABEAN, KEC. SEDATI, KAB. SIDOARJO, PROP. JAWATIMUR | L40: 0 | N40: cvrafapratamasda@gmail.com | O40: 2023-05-31 05:41:24 | P40: LIR007 | R40: BCA : 2711219651 | T40: =_xlfn.IFNA(VLOOKUP(B40,Sheet2!$A$2:$M$58,4,0),"-") -> - | U40: =_xlfn.IFNA(VLOOKUP(B40,'TV Trx'!$B$4:$C$57,2,0),"-") -> 45083 | V40: =IF(C40="ACC_TYPE_CO",T40,U40) -> 45083 | W40: =_xlfn.IFNA(VLOOKUP(B40,'CO Trx'!$A$4:$B$37,2,0),"-") -> - | X40: =_xlfn.IFNA(VLOOKUP(B40,'CO Trx'!$A$49:$B$104,2,0),"-") -> - | Y40: ACTIVE | AA40: CV. RAFA PRATAMA MANDIRI-PF | AB40: RAFA PRATAMA MANDIRI
...

Sheet Sheet2
A1: Customer | B1: AM | C1: Active Date | D1: Latest Booking Date | E1: Remaining Credit | F1: Credit Limit | G1: CL Ratio | H1: CLD Total | I1: CLG Total | J1: CLT Total | K1: Last Job Number | L1: Debit Note | M1: Total PF
A2: PT. Transindo Jayatama Logistik | B2: Ame | C2: 44854 | D2: 45071 | E2: 42811826 | F2: 15000000000 | G2: 0.0028541217 | H2: 0 | I2: 0 | J2: 1826 | K2: CLICTRUCK-048929 | L2: 17792844529 | M2: 476580341
A3: PT. Inesia Food Indonesia | B3: Dyah | C3: 44988 | D3: 45060 | E3: 1191504400 | F3: 4000000000 | G3: 0.2978761 | H3: 0 | I3: 0 | J3: 104 | K3: CLICTRUCK-048426 | L3: 3665305000 | M3: 104021003
A4: PT. Roket Delapan Delapan | B4: Raiyan | C4: 45015 | D4: 45081 | E4: 1500906750 | F4: 3000000000 | G4: 0.50030225 | H4: 0 | I4: 0 | J4: 11 | K4: CLICTRUCK-049189 | L4: 2646282000 | M4: 117800170
A5: PT KINARYA MANDIRI TRANS | B5: Beny | C5: 44642 | D5: 45083 | E5: 179952875 | F5: 1400000000 | G5: 0.12853777 | H5: 0 | I5: 0 | J5: 863 | K5: CLICTRUCK-049273 | L5: 2146359125 | M5: 85842535
A6: PT. ASHAKA JAYA MANDIRI | B6: Ame | C6: 44959 | D6: 45086 | E6: 42076415 | F6: 1000000000 | G6: 0.042076415 | H6: 0 | I6: 0 | J6: 87 | K6: CLICTRUCK-049381 | L6: 1866300000 | M6: 74920005
A7: PT. Ekspedisi Sehati Abadi | B7: Raiyan | C7: 44917 | D7: 45088 | E7: 99373993 | F7: 700000000 | G7: 0.14196285 | H7: 0 | I7: 0 | J7: 1040 | K7: CLICTRUCK-049454 | L7: 1428541147 | M7: 52492746
A8: PT. Lima Sarana Trans | B8: Dyah | C8: 45002 | D8: 45060 | E8: 2439619 | F8: 1000000000 | G8: 0.002439619 | H8: 0 | I8: 0 | J8: 83 | K8: CLICTRUCK-048431 | L8: 983500000 | M8: 62345925
A9: PT. Nadja Trans Logistik [Cargo Owner] | B9: Ame | C9: 45012 | D9: 45025 | E9: 49724290 | F9: 1000000000 | G9: 0.04972429 | H9: 0 | I9: 0 | J9: 87 | K9: CLICTRUCK-047248 | L9: 968088139 | M9: 40024468
A10: PT. Rajawali Persada Logistik | B10: Raiyan | C10: 44911 | D10: 45017 | E10: 415845000 | F10: 600000000 | G10: 0.693075 | H10: 0 | I10: 0 | J10: 71 | K10: CLICTRUCK-046638 | L10: 914300000 | M10: 27342075
A11: PT. Distribusi Solusi Bersama | B11: Raiyan | C11: 44958 | D11: 45066 | E11: 169791500 | F11: 500000000 | G11: 0.339583 | H11: 0 | I11: 0 | J11: 93 | K11: CLICTRUCK-048734 | L11: 784053500 | M11: 37392722
A12: PT. Central Jasa Mitra Bahari | B12: Ame | C12: 44837 | D12: 45077 | E12: 3269250 | F12: 600000000 | G12: 0.00544875 | H12: 0 | I12: 0 | J12: 478 | K12: CLICTRUCK-049036 | L12: 766300000 | M12: 25517790
A13: PT. Lazuardo Vittorio Indonesia | B13: Ame | C13: 45057 | D13: 45084 | E13: 214180250 | F13: 1000000000 | G13: 0.21418025 | H13: 0 | I13: 0 | J13: 102 | K13: CLICTRUCK-049303 | L13: 744500000 | M13: 44150250
... A53: CV. KHAROMAH BERKAH TRANS | B53: Raiyan | C53: 45075 | D53: 45086 | E53: 89060244 | F53: 150000000 | G53: 0.59373496 | H53: 0 | I53: 0 | J53: 9 | K53: CLICTRUCK-049370 | L53: 39434506 | M53: 2876087
A54: PT. Dewata Freight International | D54: 44951
A55: CV. Datuak Lansano Maju Bersama Nayaka | B55: Raiyan | C55: 45068 | D55: 45072 | E55: 119472250 | F55: 150000000 | G55: 0.79648167 | H55: 0 | I55: 0 | J55: 1 | K55: CLICTRUCK-048956 | L55: 30500000 | M55: 1043400
A56: PT. Gemilang Logistik Terminal | B56: Beny | C56: 45057 | D56: 45085 | E56: 90915401 | F56: 150000000 | G56: 0.60610267 | H56: 0 | I56: 0 | J56: 10 | K56: CLICTRUCK-049332 | L56: 12740000 | M56: 222000
A57: PT. Vektruck Trans Digilogistik | B57: Lena | C57: 45022 | D57: 45025 | E57: 150000000 | F57: 150000000 | G57: 1 | H57: 0 | I57: 0 | J57: 1 | K57: CLICTRUCK-047222 | L57: 4400000 | M57: 210900
A58: CV. Abadi Jaya | B58: Raiyan | C58: 45086 | E58: 1500000000 | F58: 1500000000 | G58: 1

Sheet CO Trx
A1: Status 2 | B1: OUTSTANDING
A3: Cargo Owner | B3: Sum of JML
A4: CV. Awal Lestari Rezeki | B4: 12
A5: CV. Datuak Lansano Maju Bersama Nayaka | B5: 2
A6: CV. Mulia Maretno Abadi | B6: 1
A7: PT KINARYA MANDIRI TRANS | B7: 15
A8: PT Raskita Wira Jaya | B8: 1
A9: PT. Alira Jaya Tranportasi | B9: 2
A10: PT. ASHAKA JAYA MANDIRI | B10: 10
A11: PT. Central Jasa Mitra Bahari | B11: 10
A12: PT. Citra Buana Nusantara | B12: 1
A13: PT. Duta Lestari Segara | B13: 47
A14: PT. Ekspedisi Sehati Abadi | B14: 35
A15: PT. ERAJAYA KARUNIA LOGISTIK | B15: 149
... A38: Grand Total | B38: 536
A46: Status 2 | B46: COMPLETED
A48: Row Labels | B48: Sum of JML
A49: CV. AL-One Gunawan Jaya Sentosa | B49: 12
A50: CV. Awal Lestari Rezeki | B50: 55
A51: CV. Datuak Lansano Maju Bersama Nayaka | B51: 1
A52: CV. Harba Logistics | B52: 13
A53: CV. KHAROMAH BERKAH TRANS | B53: 9
A54: CV. Mega Jaya Expres | B54: 150
A55: CV. Mulia Maretno Abadi | B55: 7
A56: PT KINARYA MANDIRI TRANS | B56: 863
A57: PT Raskita Wira Jaya | B57: 23
A58: PT. ALD Logistik Indonesia | B58: 9
A59: PT. Alira Jaya Tranportasi | B59: 43
A60: PT. Andalan Niaga Indonesia Logistic | B60: 9
... A105: Grand Total | B105: 6827

Sheet TV Trx
A3: Status 2 | B3: Trucking Vendor | C3: Max of Booking Date'
A4: COMPLETED | B4: CV Ali Trans | C4: 45076
B5: CV. BINTANG TRIJAYA SUKSESINDO | C5: 45076
B6: CV. Faeyza Putra Mandiri | C6: 45058
B7: CV. Mahkota Emas | C7: 45008
B8: CV. Mulia Maretno Abadi - TRUCKING VENDOR | C8: 45072
B9: CV. Nawasena Berkah Mandiri | C9: 45017
B10: CV. NUSANTARA CITRA JAYA | C10: 45087
B11: CV. Pamungkas Sakti Logistik | C11: 45042
B12: CV. RAFA PRATAMA MANDIRI | C12: 45083
B13: CV. SKY Xpress | C13: 45086
B14: CV. SUMBER SEJAHTERA ABADI | C14: 45078
B15: PT ELEMEN TRANS LOGISTIK | C15: 45071
B16: PT Jaya Pratama Perkasa | C16: 45071
... B57: PT. ZENSHIN Technology International | C57: 45066
A58: OUTSTANDING | B58: CV. BINTANG TRIJAYA SUKSESINDO | C58: 45077
B59: CV. Faeyza Putra Mandiri | C59: 45085
B60: CV. Mahkota Emas | C60: 45008
B61: CV. Mulia Maretno Abadi - TRUCKING VENDOR | C61: 45072
B62: CV. RAFA PRATAMA MANDIRI | C62: 45082
B63: CV. SUMBER SEJAHTERA ABADI | C63: 45085
B64: PT KINARI JAYA TRANS | C64: 45083
B65: PT. ANINDYA JIFA PERDANA (Trucking) | C65: 45085
B66: PT. Awani Sejahtera Anugerah | C66: 45025
B67: PT. Bina Mitra Segara Setia | C67: 45030
B68: PT. Delta Utama Gemilang | C68: 44993
B69: PT. Dian Giri Selaras | C69: 45078
B70: PT. Jena Solusi Transport | C70: 45052
... B94: PT. ZENSHIN Technology International | C94: 45076
A95: Grand Total | C95: 45088

Sheet CLT Data
A1: Order Number | B1: Type | C1: Booking Date' | D1: Cargo Owner | E1: Debit Note | F1: CO Platform Fee | G1: Invoice Date | H1: Status | I1: Trucking Vendor | J1: TV Platform Fee | K1: JML | L1: Country | M1: Contract ID | N1: Status 2
A2: CLICTRUCK-043054 | B2: export | C2: 44928 | D2: PT KINARYA MANDIRI TRANS | E2: 1575000 | F2: 16650 | G2: 44931 | H2: PAID | I2: PT KINARI JAYA TRANS | J2: 52447 | K2: 1 | L2: Indonesia | M2: KMT-KJT | N2: COMPLETED
A3: CLICTRUCK-043068 | B3: export | C3: 44929 | D3: PT KINARYA MANDIRI TRANS | E3: 5225000 | F3: 16650 | G3: 44931 | H3: PAID | I3: PT KINARI JAYA TRANS | J3: 173992 | K3: 1 | L3: Indonesia | M3: KMT-KJT | N3: COMPLETED
A4: CLICTRUCK-043069 | B4: export | C4: 44929 | D4: PT KINARYA MANDIRI TRANS | E4: 2460000 | F4: 16650 | G4: 44931 | H4: PAID | I4: PT KINARI JAYA TRANS | J4: 81918 | K4: 1 | L4: Indonesia | M4: KMT-KJT | N4: COMPLETED
A5: CLICTRUCK-043070 | B5: import | C5: 44929 | D5: PT KINARYA MANDIRI TRANS | E5: 2050000 | F5: 16650 | G5: 44931 | H5: PAID | I5: PT KINARI JAYA TRANS | J5: 68265 | K5: 1 | L5: Indonesia | M5: KMT-KJT | N5: COMPLETED
A6: CLICTRUCK-043071 | B6: import | C6: 44929 | D6: PT KINARYA MANDIRI TRANS | E6: 2050000 | F6: 16650 | G6: 44931 | H6: PAID | I6: PT KINARI JAYA TRANS | J6: 68265 | K6: 1 | L6: Indonesia | M6: KMT-KJT | N6: COMPLETED
A7: CLICTRUCK-043072 | B7: import | C7: 44929 | D7: PT KINARYA MANDIRI TRANS | E7: 2250000 | F7: 16650 | G7: 44937 | H7: PAID | I7: PT KINARI JAYA TRANS | J7: 74925 | K7: 1 | L7: Indonesia | M7: KMT-KJT | N7: COMPLETED
A8: CLICTRUCK-043073 | B8: import | C8: 44929 | D8: PT KINARYA MANDIRI TRANS | E8: 3225000 | F8: 16650 | G8: 44937 | H8: PAID | I8: PT KINARI JAYA TRANS | J8: 107392 | K8: 1 | L8: Indonesia | M8: KMT-KJT | N8: COMPLETED
A9: CLICTRUCK-043075 | B9: import | C9: 44929 | D9: PT. Ekspedisi Sehati Abadi | E9: 18855210 | F9: 179820 | G9: 44932 | H9: PAID | I9: PT. Saudara Sukses Abadi | J9: 418585 | K9: 9 | L9: Indonesia | M9: ESA - SASA | N9: COMPLETED
A10: CLICTRUCK-043078 | B10: import | C10: 44930 | D10: PT. Ekspedisi Sehati Abadi | E10: 12285845 | F10: 139860 | G10: 44932 | H10: PAID | I10: PT. Saudara Sukses Abadi | J10: 272744 | K10: 7 | L10: Indonesia | M10: ESA - SASA | N10: COMPLETED
A11: CLICTRUCK-043079 | B11: export | C11: 44930 | D11: PT KINARYA MANDIRI TRANS | E11: 2625000 | F11: 16650 | G11: 44937 | H11: PAID | I11: PT KINARI JAYA TRANS | J11: 87412 | K11: 1 | L11: Indonesia | M11: KMT-KJT | N11: COMPLETED
A12: CLICTRUCK-043080 | B12: export | C12: 44930 | D12: PT KINARYA MANDIRI TRANS | E12: 2625000 | F12: 16650 | G12: 44937 | H12: PAID | I12: PT KINARI JAYA TRANS | J12: 87412 | K12: 1 | L12: Indonesia | M12: KMT-KJT | N12: COMPLETED
A13: CLICTRUCK-043081 | B13: export | C13: 44930 | D13: PT KINARYA MANDIRI TRANS | E13: 1775000 | F13: 16650 | G13: 44937 | H13: PAID | I13: PT KINARI JAYA TRANS | J13: 59107 | K13: 1 | L13: Indonesia | M13: KMT-KJT | N13: COMPLETED
... A66: CLICTRUCK-043203 | B66: export | C66: 44938 | D66: PT KINARYA MANDIRI TRANS | E66: 2625000 | F66: 16650 | G66: 44944 | H66: PAID | I66: PT KINARI JAYA TRANS | J66: 87412 | K66: 1 | L66: Indonesia | M66: KMT-KJT | N66: COMPLETED
A67: CLICTRUCK-043204 | B67: import | C67: 44938 | D67: PT. Central Jasa Mitra Bahari | E67: 16000000 | F67: 532800 | G67: 44939 | H67: PAID | I67: PT. Bina Mitra Segara Setia | K67: 10 | L67: Indonesia | M67: CJM-BMS | N67: COMPLETED
A68: CLICTRUCK-043205 | B68: export | C68: 44938 | D68: PT KINARYA MANDIRI TRANS | E68: 2625000 | F68: 16650 | G68: 44944 | H68: PAID | I68: PT KINARI JAYA TRANS | J68: 87412 | K68: 1 | L68: Indonesia | M68: KMT-KJT | N68: COMPLETED
A69: CLICTRUCK-043206 | B69: export | C69: 44938 | D69: PT. Duta Lestari Segara | E69: 6000000 | F69: 83250 | G69: 44939 | H69: UNPAID | I69: PT. KARYA ABADI SEJATI | J69: 133200 | K69: 3 | L69: Indonesia | M69: DLS-KAS | N69: COMPLETED
A70: CLICTRUCK-043207 | B70: export | C70: 44938 | D70: PT KINARYA MANDIRI TRANS | E70: 2575000 | F70: 16650 | G70: 44944 | H70: PAID | I70: PT KINARI JAYA TRANS | J70: 85747 | K70: 1 | L70: Indonesia | M70: KMT-KJT | N70: COMPLETED
A71: CLICTRUCK-043208 | B71: import | C71: 44938 | D71: PT. Central Jasa Mitra Bahari | E71: 16000000 | F71: 532800 | G71: 44939 | H71: PAID | I71: PT. Bina Mitra Segara Setia | K71: 10 | L71: Indonesia | M71: CJM-BMS | N71: COMPLETED
A72: CLICTRUCK-043209 | B72: export | C72: 44938 | D72: PT KINARYA MANDIRI TRANS | E72: 2900000 | F72: 16650 | G72: 44944 | H72: PAID | I72: PT KINARI JAYA TRANS | J72: 96570 | K72: 1 | L72: Indonesia | M72: KMT-KJT | N72: COMPLETED
A73: CLICTRUCK-043210 | B73: import | C73: 44938 | D73: PT. Central Jasa Mitra Bahari | E73: 3200000 | F73: 106560 | G73: 44939 | H73: PAID | I73: PT. Bina Mitra Segara Setia | K73: 2 | L73: Indonesia | M73: CJM-BMS | N73: COMPLETED
A74: CLICTRUCK-043211 | B74: export | C74: 44938 | D74: PT KINARYA MANDIRI TRANS | E74: 2900000 | F74: 16650 | G74: 44944 | H74: PAID | I74: PT KINARI JAYA TRANS | J74: 96570 | K74: 1 | L74: Indonesia | M74: KMT-KJT | N74: COMPLETED
A75: CLICTRUCK-043212 | B75: export | C75: 44938 | D75: PT KINARYA MANDIRI TRANS | E75: 2900000 | F75: 16650 | G75: 44944 | H75: PAID | I75: PT KINARI JAYA TRANS | J75: 96570 | K75: 1 | L75: Indonesia | M75: KMT-KJT | N75: COMPLETED
A76: CLICTRUCK-043213 | B76: export | C76: 44938 | D76: PT KINARYA MANDIRI TRANS | E76: 2900000 | F76: 16650 | G76: 44944 | H76: PAID | I76: PT KINARI JAYA TRANS | J76: 96570 | K76: 1 | L76: Indonesia | M76: KMT-KJT | N76: COMPLETED
A77: CLICTRUCK-043214 | B77: import | C77: 44938 | D77: PT. Central Jasa Mitra Bahari | E77: 16000000 | F77: 532800 | G77: 44939 | H77: PAID | I77: PT. Bina Mitra Segara Setia | K77: 10 | L77: Indonesia | M77: CJM-BMS | N77: COMPLETED
A78: CLICTRUCK-043215 | B78: export | C78: 44938 | D78: PT KINARYA MANDIRI TRANS | E78: 2900000 | F78: 16650 | G78: 44944 | H78: PAID | I78: PT KINARI JAYA TRANS | J78: 96570 | K78: 1 | L78: Indonesia | M78: KMT-KJT | N78: COMPLETED
A79: CLICTRUCK-043216 | B79: export | C79: 44938 | D79: PT KINARYA MANDIRI TRANS | E79: 2900000 | F79: 16650 | G79: 44944 | H79: PAID | I79: PT KINARI JAYA TRANS | J79: 96570 | K79: 1 | L79: Indonesia | M79: KMT-KJT | N79: COMPLETED
A80: CLICTRUCK-043217 | B80: export | C80: 44938 | D80: PT KINARYA MANDIRI TRANS | E80: 2900000 | F80: 16650 | G80: 44944 | H80: PAID | I80: PT KINARI JAYA TRANS | J80: 96570 | K80: 1 | L80: Indonesia | M80: KMT-KJT | N80: COMPLETED
A81: CLICTRUCK-043218 | B81: import | C81: 44938 | D81: PT. Central Jasa Mitra Bahari | E81: 16000000 | F81: 532800 | G81: 44939 | H81: PAID | I81: PT. Bina Mitra Segara Setia | K81: 10 | L81: Indonesia | M81: CJM-BMS | N81: COMPLETED
A82: CLICTRUCK-043219 | B82: export | C82: 44938 | D82: PT KINARYA MANDIRI TRANS | E82: 2900000 | F82: 16650 | G82: 44951 | H82: PAID | I82: PT KINARI JAYA TRANS | J82: 96570 | K82: 1 | L82: Indonesia | M82: KMT-KJT | N82: COMPLETED
A83: CLICTRUCK-043220 | B83: export | C83: 44938 | D83: PT KINARYA MANDIRI TRANS | E83: 2900000 | F83: 16650 | G83: 44951 | H83: PAID | I83: PT KINARI JAYA TRANS | J83: 96570 | K83: 1 | L83: Indonesia | M83: KMT-KJT | N83: COMPLETED
A84: CLICTRUCK-043221 | B84: import | C84: 44938 | D84: PT. Central Jasa Mitra Bahari | E84: 8000000 | F84: 266400 | G84: 44939 | H84: PAID | I84: PT. Bina Mitra Segara Setia | K84: 5 | L84: Indonesia | M84: CJM-BMS | N84: COMPLETED
A85: CLICTRUCK-043222 | B85: export | C85: 44938 | D85: PT KINARYA MANDIRI TRANS | E85: 2525000 | F85: 16650 | G85: 44951 | H85: PAID | I85: PT KINARI JAYA TRANS | J85: 84082 | K85: 1 | L85: Indonesia | M85: KMT-KJT | N85: COMPLETED
A86: CLICTRUCK-043223 | B86: export | C86: 44938 | D86: PT KINARYA MANDIRI TRANS | E86: 1950000 | F86: 16650 | G86: 44951 | H86: PAID | I86: PT KINARI JAYA TRANS | J86: 64935 | K86: 1 | L86: Indonesia | M86: KMT-KJT | N86: COMPLETED
A87: CLICTRUCK-043224 | B87: export | C87: 44938 | D87: PT KINARYA MANDIRI TRANS | E87: 3125000 | F87: 16650 | G87: 44951 | H87: PAID | I87: PT KINARI JAYA TRANS | J87: 104062 | K87: 1 | L87: Indonesia | M87: KMT-KJT | N87: COMPLETED
A88: CLICTRUCK-043225 | B88: export | C88: 44938 | D88: PT KINARYA MANDIRI TRANS | E88: 2525000 | F88: 16650 | G88: 44951 | H88: PAID | I88: PT KINARI JAYA TRANS | J88: 84082 | K88: 1 | L88: Indonesia | M88: KMT-KJT | N88: COMPLETED
A89: CLICTRUCK-043226 | B89: export | C89: 44938 | D89: PT KINARYA MANDIRI TRANS | E89: 1000000 | F89: 16650 | G89: 44951 | H89: PAID | I89: PT KINARI JAYA TRANS | J89: 33300 | K89: 1 | L89: Indonesia | M89: KMT-KJT | N89: COMPLETED
A90: CLICTRUCK-043227 | B90: import | C90: 44938 | D90: PT. Ekspedisi Sehati Abadi | E90: 1740500 | F90: 19980 | G90: 44938 | H90: PAID | I90: PT. Saudara Sukses Abadi | J90: 38639 | K90: 1 | L90: Indonesia | M90: ESA - SASA | N90: COMPLETED
A91: CLICTRUCK-043228 | B91: import | C91: 44938 | D91: PT. Ekspedisi Sehati Abadi | E91: 31358019 | F91: 319680 | G91: 44939 | H91: PAID | I91: PT. Saudara Sukses Abadi | J91: 696147 | K91: 16 | L91: Indonesia | M91: ESA - SASA | N91: COMPLETED
A92: CLICTRUCK-043230 | B92: export | C92: 44939 | D92: PT. GOOD LOGISTICS TERMINAL | E92: 1176000 | F92: 22200 | G92: 44940 | H92: PAID | I92: PT ELEMEN TRANS LOGISTIK | K92: 1 | L92: Indonesia | M92: GLT-Elemen | N92: COMPLETED
...
